<robot name="SpiderBody">
  <link name="Body">
    <inertial>
      <origin xyz="0.2412000000000002 1.7296168291426336e-18 0.004854024896265552" rpy="0.0 0.0 0.0" />
      <mass value="2.567558330651746" />
      <inertia ixx="0.01262901309898984" iyy="0.05067644480183947" izz="0.06301756012942178" ixy="1.0711431741583518e-18" iyz="-1.1167056214726778e-19" ixz="2.168404344971009e-18" />
    </inertial>
    <visual name="Body_visual">
      <origin xyz="0.0 0.0 0.0" rpy="0.0 -0.0 0.0" />
      <geometry>
        <mesh filename="meshes/urdf/Body.stl" scale="0.001 0.001 0.001" />
      </geometry>
    </visual>
    <collision name="Body_collision">
      <origin xyz="0.0 0.0 0.0" rpy="0.0 -0.0 0.0" />
      <geometry>
        <mesh filename="meshes/urdf/Body.stl" scale="0.001 0.001 0.001" />
      </geometry>
    </collision>
  </link>
  <link name="Leg1_Femur_actuator_assembly_Motor">
    <inertial>
      <origin xyz="-0.01682914894623567 -0.012200892588600767 -0.03262580227044481" rpy="0.0 -0.0 0.0" />
      <mass value="0.3028214126901055" />
      <inertia ixx="0.00014140196787329473" iyy="0.00023174021267845235" izz="0.00013816777463288856" ixy="1.0642458936766517e-06" iyz="8.75265172622583e-08" ixz="-2.3069540264122196e-07" />
    </inertial>
    <visual name="Leg1_Femur_actuator_assembly_Motor_visual">
      <origin xyz="-0.017016330000000385 -0.026000000000004155 -0.03285490516471654" rpy="1.6580627893946134 -2.0816681711721605e-17 1.5707963267948968" />
      <geometry>
        <mesh filename="meshes/urdf/Leg1_Femur-actuator-assembly_Motor.stl" scale="0.001 0.001 0.001" />
      </geometry>
    </visual>
    <collision name="Leg1_Femur_actuator_assembly_Motor_collision">
      <origin xyz="-0.017016330000000385 -0.026000000000004155 -0.03285490516471654" rpy="1.6580627893946134 -2.0816681711721605e-17 1.5707963267948968" />
      <geometry>
        <mesh filename="meshes/urdf/Leg1_Femur-actuator-assembly_Motor.stl" scale="0.001 0.001 0.001" />
      </geometry>
    </collision>
  </link>
  <link name="Leg1_Femur_actuator_assembly_Femur">
    <inertial>
      <origin xyz="0.03721165136172445 -0.009661077868573224 -0.008367126382514413" rpy="2.0312024752276523e-50 -0.0 0.0" />
      <mass value="0.06743801039317165" />
      <inertia ixx="4.060590749385694e-05" iyy="0.0002477420639114199" izz="0.00021588191609116206" ixy="2.098786538447991e-06" iyz="-4.706153330534149e-07" ixz="3.577320644580821e-05" />
    </inertial>
    <visual name="Leg1_Femur_actuator_assembly_Femur_visual">
      <origin xyz="-4.707345624410664e-16 0.029500000000004214 -4.835283675674873e-09" rpy="-0.785398163397448 2.219933546484061e-17 -1.5707963267948968" />
      <geometry>
        <mesh filename="meshes/urdf/Leg1_Femur-actuator-assembly_Femur.stl" scale="0.001 0.001 0.001" />
      </geometry>
    </visual>
    <collision name="Leg1_Femur_actuator_assembly_Femur_collision">
      <origin xyz="-4.707345624410664e-16 0.029500000000004214 -4.835283675674873e-09" rpy="-0.785398163397448 2.219933546484061e-17 -1.5707963267948968" />
      <geometry>
        <mesh filename="meshes/urdf/Leg1_Femur-actuator-assembly_Femur.stl" scale="0.001 0.001 0.001" />
      </geometry>
    </collision>
  </link>
  <link name="Leg1_Knee_actuator_assembly_Motor">
    <inertial>
      <origin xyz="-7.88154849537337e-05 0.012200892588596988 -0.0002851495130677506" rpy="0.0 -0.0 0.0" />
      <mass value="0.3028214126901055" />
      <inertia ixx="0.0001394653317402239" iyy="0.0002317402126784246" izz="0.00014010441076596665" ixy="-5.435489230130397e-07" iyz="9.191489442530315e-07" ixz="-1.601910218325571e-06" />
    </inertial>
    <visual name="Leg1_Knee_actuator_assembly_Motor_visual">
      <origin xyz="-5.684341886080802e-16 0.026000000000000387 4.835283675674873e-09" rpy="-2.438224965036078 -1.1171619185290586e-15 -1.5707963267948952" />
      <geometry>
        <mesh filename="meshes/urdf/Leg1_Knee-actuator-assembly_Motor.stl" scale="0.001 0.001 0.001" />
      </geometry>
    </visual>
    <collision name="Leg1_Knee_actuator_assembly_Motor_collision">
      <origin xyz="-5.684341886080802e-16 0.026000000000000387 4.835283675674873e-09" rpy="-2.438224965036078 -1.1171619185290586e-15 -1.5707963267948952" />
      <geometry>
        <mesh filename="meshes/urdf/Leg1_Knee-actuator-assembly_Motor.stl" scale="0.001 0.001 0.001" />
      </geometry>
    </collision>
  </link>
  <link name="Leg1_Knee_actuator_assembly_KneeMotorPulley">
    <inertial>
      <origin xyz="9.539036227579345e-15 0.006094295273220354 -4.835335403186036e-09" rpy="0.0 -0.0 0.0" />
      <mass value="0.08135375942547957" />
      <inertia ixx="7.261200035930254e-06" iyy="1.246264830895294e-05" izz="7.261200035337196e-06" ixy="-1.6669608401964453e-18" iyz="5.204719004198158e-18" ixz="-1.6805133673525319e-16" />
    </inertial>
    <visual name="Leg1_Knee_actuator_assembly_KneeMotorPulley_visual">
      <origin xyz="0.01244836289374586 0.011500000000002562 -0.03640689398858477" rpy="0.867428638241182 -9.28429129370447e-16 -1.5707963267948981" />
      <geometry>
        <mesh filename="meshes/urdf/Leg1_Knee-actuator-assembly_KneeMotorPulley.stl" scale="0.001 0.001 0.001" />
      </geometry>
    </visual>
    <collision name="Leg1_Knee_actuator_assembly_KneeMotorPulley_collision">
      <origin xyz="0.01244836289374586 0.011500000000002562 -0.03640689398858477" rpy="0.867428638241182 -9.28429129370447e-16 -1.5707963267948981" />
      <geometry>
        <mesh filename="meshes/urdf/Leg1_Knee-actuator-assembly_KneeMotorPulley.stl" scale="0.001 0.001 0.001" />
      </geometry>
    </collision>
  </link>
  <link name="Leg1_Knee_actuator_assembly_Knee_motor_bearings">
    <inertial>
      <origin xyz="-0.032908403721941246 0.0018568433438257337 0.016912625578978293" rpy="0.0 -0.0 0.0" />
      <mass value="0.009270686219329867" />
      <inertia ixx="6.408471849645575e-06" iyy="1.2750547945198504e-05" izz="6.4084718495944956e-06" ixy="2.1345230270808429e-19" iyz="5.40505805083098e-20" ixz="2.3744027577432547e-17" />
    </inertial>
    <visual name="Leg1_Knee_actuator_assembly_Knee_motor_bearings_visual">
      <origin xyz="-0.04889581968953464 -0.11894493236997299 0.05649553825927939" rpy="-1.5707963267948946 -1.260127719939907 3.1415926535897913" />
      <geometry>
        <mesh filename="meshes/urdf/Leg1_Knee-actuator-assembly_Knee-motor-bearings.stl" scale="0.001 0.001 0.001" />
      </geometry>
    </visual>
    <collision name="Leg1_Knee_actuator_assembly_Knee_motor_bearings_collision">
      <origin xyz="-0.04889581968953464 -0.11894493236997299 0.05649553825927939" rpy="-1.5707963267948946 -1.260127719939907 3.1415926535897913" />
      <geometry>
        <mesh filename="meshes/urdf/Leg1_Knee-actuator-assembly_Knee-motor-bearings.stl" scale="0.001 0.001 0.001" />
      </geometry>
    </collision>
  </link>
  <link name="Leg1_Knee_actuator_assembly_End_Bearing_Holder">
    <inertial>
      <origin xyz="0.03390957918454023 -0.0035952204002470192 0.02477926885429852" rpy="0.0 -0.0 0.0" />
      <mass value="0.057169625310268736" />
      <inertia ixx="5.134763459655606e-05" iyy="0.00010281021554762668" izz="5.1961941766096964e-05" ixy="1.1711751146881643e-08" iyz="1.0829253630547514e-08" ixz="-9.985502905466301e-07" />
    </inertial>
    <visual name="Leg1_Knee_actuator_assembly_End_Bearing_Holder_visual">
      <origin xyz="0.032801111906407394 0.11894493236997368 -0.01631135744832484" rpy="-1.5707963267948963 1.5707963267948966 0" />
      <geometry>
        <mesh filename="meshes/urdf/Leg1_Knee-actuator-assembly_End-Bearing-Holder.stl" scale="0.001 0.001 0.001" />
      </geometry>
    </visual>
    <collision name="Leg1_Knee_actuator_assembly_End_Bearing_Holder_collision">
      <origin xyz="0.032801111906407394 0.11894493236997368 -0.01631135744832484" rpy="-1.5707963267948963 1.5707963267948966 0" />
      <geometry>
        <mesh filename="meshes/urdf/Leg1_Knee-actuator-assembly_End-Bearing-Holder.stl" scale="0.001 0.001 0.001" />
      </geometry>
    </collision>
  </link>
  <link name="Leg1_Hip_actuator_assembly_Motor">
    <inertial>
      <origin xyz="0.014254586305143917 0.01379910741140097 0.03445749499235996" rpy="0.0 -0.0 0.0" />
      <mass value="0.3028214126901055" />
      <inertia ixx="0.0001414174603782967" iyy="0.0002317402126784246" izz="0.00013815228212788605" ixy="1.0525676781229093e-06" iyz="1.7994859376907227e-07" ixz="5.361526010575276e-08" />
    </inertial>
    <visual name="Leg1_Hip_actuator_assembly_Motor_visual">
      <origin xyz="0.014088085164716163 -2.4447111002245947e-15 0.0342129499999999" rpy="1.570796326794897 9.836221983249827e-17 1.5707963267948966" />
      <geometry>
        <mesh filename="meshes/urdf/Leg1_Hip-actuator-assembly_Motor.stl" scale="0.001 0.001 0.001" />
      </geometry>
    </visual>
    <collision name="Leg1_Hip_actuator_assembly_Motor_collision">
      <origin xyz="0.014088085164716163 -2.4447111002245947e-15 0.0342129499999999" rpy="1.570796326794897 9.836221983249827e-17 1.5707963267948966" />
      <geometry>
        <mesh filename="meshes/urdf/Leg1_Hip-actuator-assembly_Motor.stl" scale="0.001 0.001 0.001" />
      </geometry>
    </collision>
  </link>
  <link name="Leg1_Hip_actuator_assembly_Hip_Bracket">
    <inertial>
      <origin xyz="0.007563359926921698 -0.0012437881617800618 0.040945652067033295" rpy="-4.446271175410867e-78 -0.0 0.0" />
      <mass value="0.05792781115933178" />
      <inertia ixx="0.00010067920230328285" iyy="9.858380629719499e-05" izz="5.264746465636716e-05" ixy="-4.054417809776089e-06" iyz="1.4243321119435066e-06" ixz="1.5317549933663646e-05" />
    </inertial>
    <visual name="Leg1_Hip_actuator_assembly_Hip_Bracket_visual">
      <origin xyz="0.017249999999999936 0.04000000000000236 0.09499999516471626" rpy="-1.3234256087112829e-30 8.321547657025816e-18 -1.5707963267948968" />
      <geometry>
        <mesh filename="meshes/urdf/Leg1_Hip-actuator-assembly_Hip-Bracket.stl" scale="0.001 0.001 0.001" />
      </geometry>
    </visual>
    <collision name="Leg1_Hip_actuator_assembly_Hip_Bracket_collision">
      <origin xyz="0.017249999999999936 0.04000000000000236 0.09499999516471626" rpy="-1.3234256087112829e-30 8.321547657025816e-18 -1.5707963267948968" />
      <geometry>
        <mesh filename="meshes/urdf/Leg1_Hip-actuator-assembly_Hip-Bracket.stl" scale="0.001 0.001 0.001" />
      </geometry>
    </collision>
  </link>
  <link name="Leg1_Hip_actuator_assembly_Body_Bracket">
    <inertial>
      <origin xyz="-0.034799977001900045 -0.004424738499856889 -0.02941478586583357" rpy="0.0 -0.0 0.0" />
      <mass value="0.2737560132535958" />
      <inertia ixx="0.00011826659575640212" iyy="0.00030785752435442265" izz="0.00020548953826175775" ixy="-6.214987801744093e-11" iyz="-9.185276276079258e-08" ixz="3.8625346671095073e-10" />
    </inertial>
    <visual name="Leg1_Hip_actuator_assembly_Body_Bracket_visual">
      <origin xyz="0.04767899757722809 0.02862177809359275 0.017366123416015372" rpy="1.7516230804060163e-46 1.5707963267948963 0" />
      <geometry>
        <mesh filename="meshes/urdf/Leg1_Hip-actuator-assembly_Body-Bracket.stl" scale="0.001 0.001 0.001" />
      </geometry>
    </visual>
    <collision name="Leg1_Hip_actuator_assembly_Body_Bracket_collision">
      <origin xyz="0.04767899757722809 0.02862177809359275 0.017366123416015372" rpy="1.7516230804060163e-46 1.5707963267948963 0" />
      <geometry>
        <mesh filename="meshes/urdf/Leg1_Hip-actuator-assembly_Body-Bracket.stl" scale="0.001 0.001 0.001" />
      </geometry>
    </collision>
  </link>
  <link name="Leg1_Tibia_Leg">
    <inertial>
      <origin xyz="-0.10421987493399568 0.007011542435092304 -0.047194445699454524" rpy="0.0 -0.0 0.0" />
      <mass value="0.6725091028785471" />
      <inertia ixx="0.0004886387764187483" iyy="0.004260036865887468" izz="0.0037944404662035008" ixy="-7.025027001315159e-07" iyz="-3.048581377375348e-07" ixz="-0.001132063397169012" />
    </inertial>
    <visual name="Leg1_Tibia_Leg_visual">
      <origin xyz="-0.08507464832369394 -0.0330000000000039 0.09829702159969003" rpy="-2.8797932657906435 8.326672684688648e-17 1.5707963267948968" />
      <geometry>
        <mesh filename="meshes/urdf/Leg1_Tibia_Leg.stl" scale="0.001 0.001 0.001" />
      </geometry>
    </visual>
    <collision name="Leg1_Tibia_Leg_collision">
      <origin xyz="-0.08507464832369394 -0.0330000000000039 0.09829702159969003" rpy="-2.8797932657906435 8.326672684688648e-17 1.5707963267948968" />
      <geometry>
        <mesh filename="meshes/urdf/Leg1_Tibia_Leg.stl" scale="0.001 0.001 0.001" />
      </geometry>
    </collision>
  </link>
  <link name="Leg1_Tibia_Foot">
    <inertial>
      <origin xyz="-0.004715990367889464 0.006000000023911448 -0.0043383135795792786" rpy="0.0 -0.0 0.0" />
      <mass value="0.0012152855294447645" />
      <inertia ixx="2.8376244461212233e-08" iyy="2.5730108277398196e-08" izz="2.652071652314264e-08" ixy="-5.65445314269081e-17" iyz="1.1697863814760792e-16" ixz="1.0792250335506803e-08" />
    </inertial>
    <visual name="Leg1_Tibia_Foot_visual">
      <origin xyz="0.16677737167630646 0.04600000000000413 -0.16476957159969025" rpy="0.2617993877991517 -8.326672684688659e-17 -1.5707963267948968" />
      <geometry>
        <mesh filename="meshes/urdf/Leg1_Tibia_Foot.stl" scale="0.001 0.001 0.001" />
      </geometry>
    </visual>
    <collision name="Leg1_Tibia_Foot_collision">
      <origin xyz="0.16677737167630646 0.04600000000000413 -0.16476957159969025" rpy="0.2617993877991517 -8.326672684688659e-17 -1.5707963267948968" />
      <geometry>
        <mesh filename="meshes/urdf/Leg1_Tibia_Foot.stl" scale="0.001 0.001 0.001" />
      </geometry>
    </collision>
  </link>
  <link name="Leg1_Tibia_BadTouch">
    <inertial>
      <origin xyz="-0.014307431578915732 1.3944401189291967e-15 -0.019468089080775214" rpy="0.0 -0.0 0.0" />
      <mass value="0.0028499001119515355" />
      <inertia ixx="6.698251338865815e-07" iyy="1.4563954103201497e-05" izz="1.3896028902723182e-05" ixy="-1.8634724839594613e-20" iyz="6.8512712119872204e-37" ixz="1.8604646440308683e-06" />
    </inertial>
    <visual name="Leg1_Tibia_BadTouch_visual">
      <origin xyz="-0.0018152277230345272 0.04003406004254164 -0.04030871839830532" rpy="2.40085729075189e-15 7.632783294297933e-17 -1.5707963267948968" />
      <geometry>
        <mesh filename="meshes/urdf/Leg1_Tibia_BadTouch.stl" scale="0.001 0.001 0.001" />
      </geometry>
    </visual>
    <collision name="Leg1_Tibia_BadTouch_collision">
      <origin xyz="-0.0018152277230345272 0.04003406004254164 -0.04030871839830532" rpy="2.40085729075189e-15 7.632783294297933e-17 -1.5707963267948968" />
      <geometry>
        <mesh filename="meshes/urdf/Leg1_Tibia_BadTouch.stl" scale="0.001 0.001 0.001" />
      </geometry>
    </collision>
  </link>
  <link name="Leg2_Femur_actuator_assembly_Motor">
    <inertial>
      <origin xyz="-0.016829148946235713 -0.00030640961230743 -0.03483117087864265" rpy="0.0 6.162975822039156e-33 0.0" />
      <mass value="0.3028214126901055" />
      <inertia ixx="0.00014140196787329468" iyy="0.00022073805579177902" izz="0.00014916993151953267" ixy="1.0789664876653512e-06" iyz="3.014065109408978e-05" ixz="1.4721076557842226e-07" />
    </inertial>
    <visual name="Leg2_Femur_actuator_assembly_Motor_visual">
      <origin xyz="-0.017016330000000437 -0.0131949712155002 -0.0397660298724049" rpy="1.6580627893946134 -0.349065850398866 1.5707963267948968" />
      <geometry>
        <mesh filename="meshes/urdf/Leg2_Femur-actuator-assembly_Motor.stl" scale="0.001 0.001 0.001" />
      </geometry>
    </visual>
    <collision name="Leg2_Femur_actuator_assembly_Motor_collision">
      <origin xyz="-0.017016330000000437 -0.0131949712155002 -0.0397660298724049" rpy="1.6580627893946134 -0.349065850398866 1.5707963267948968" />
      <geometry>
        <mesh filename="meshes/urdf/Leg2_Femur-actuator-assembly_Motor.stl" scale="0.001 0.001 0.001" />
      </geometry>
    </collision>
  </link>
  <link name="Leg2_Femur_actuator_assembly_Femur">
    <inertial>
      <origin xyz="0.03721165136172438 -0.006216720568817049 -0.01116680996814516" rpy="-4.521675065265935e-35 -0.0 0.0" />
      <mass value="0.06743801039317165" />
      <inertia ixx="4.060590749385522e-05" iyy="0.0002443176403036304" izz="0.0002193063396989441" ixy="-1.0262942973029616e-05" iyz="9.879141870087235e-06" ixz="3.433364539166678e-05" />
    </inertial>
    <visual name="Leg2_Femur_actuator_assembly_Femur_visual">
      <origin xyz="-5.417888360170764e-16 0.027720931215500323 0.010089589872404759" rpy="-0.7853981633974481 0.34906585039886606 -1.5707963267948968" />
      <geometry>
        <mesh filename="meshes/urdf/Leg2_Femur-actuator-assembly_Femur.stl" scale="0.001 0.001 0.001" />
      </geometry>
    </visual>
    <collision name="Leg2_Femur_actuator_assembly_Femur_collision">
      <origin xyz="-5.417888360170764e-16 0.027720931215500323 0.010089589872404759" rpy="-0.7853981633974481 0.34906585039886606 -1.5707963267948968" />
      <geometry>
        <mesh filename="meshes/urdf/Leg2_Femur-actuator-assembly_Femur.stl" scale="0.001 0.001 0.001" />
      </geometry>
    </collision>
  </link>
  <link name="Leg2_Knee_actuator_assembly_Motor">
    <inertial>
      <origin xyz="-7.88154849537781e-05 0.011562613397790394 0.003904990960464474" rpy="-7.190453749649842e-67 -0.0 -2.465190328815662e-32" />
      <mass value="0.3028214126901055" />
      <inertia ixx="0.00013946533174021708" iyy="0.00022043004259227766" izz="0.00015141458085212063" ixy="3.7116650475164316e-08" iyz="3.0155287977656084e-05" ixz="-1.6912078918767263e-06" />
    </inertial>
    <visual name="Leg2_Knee_actuator_assembly_Motor_visual">
      <origin xyz="-6.128431095930865e-16 0.02443200427462525 0.008892521092009744" rpy="-2.4382249650360777 0.3490658503988651 -1.5707963267948952" />
      <geometry>
        <mesh filename="meshes/urdf/Leg2_Knee-actuator-assembly_Motor.stl" scale="0.001 0.001 0.001" />
      </geometry>
    </visual>
    <collision name="Leg2_Knee_actuator_assembly_Motor_collision">
      <origin xyz="-6.128431095930865e-16 0.02443200427462525 0.008892521092009744" rpy="-2.4382249650360777 0.3490658503988651 -1.5707963267948952" />
      <geometry>
        <mesh filename="meshes/urdf/Leg2_Knee-actuator-assembly_Motor.stl" scale="0.001 0.001 0.001" />
      </geometry>
    </collision>
  </link>
  <link name="Leg2_Knee_actuator_assembly_KneeMotorPulley">
    <inertial>
      <origin xyz="9.321432514752815e-15 0.005726762335712383 0.0020843748788644946" rpy="-9.100087466937862e-52 -0.0 2.1382117680737565e-50" />
      <mass value="0.08135375942547957" />
      <inertia ixx="7.261200035931987e-06" iyy="1.1854194445231128e-05" izz="7.869653899061826e-06" ixy="5.58364084795217e-17" iyz="1.6717132513572458e-06" ixz="-1.5829350243121267e-16" />
    </inertial>
    <visual name="Leg2_Knee_actuator_assembly_KneeMotorPulley_visual">
      <origin xyz="0.012448362893745653 0.0232583526238532 -0.03027805029878415" rpy="0.8674286382411815 0.34906585039886495 -1.5707963267948981" />
      <geometry>
        <mesh filename="meshes/urdf/Leg2_Knee-actuator-assembly_KneeMotorPulley.stl" scale="0.001 0.001 0.001" />
      </geometry>
    </visual>
    <collision name="Leg2_Knee_actuator_assembly_KneeMotorPulley_collision">
      <origin xyz="0.012448362893745653 0.0232583526238532 -0.03027805029878415" rpy="0.8674286382411815 0.34906585039886495 -1.5707963267948981" />
      <geometry>
        <mesh filename="meshes/urdf/Leg2_Knee-actuator-assembly_KneeMotorPulley.stl" scale="0.001 0.001 0.001" />
      </geometry>
    </collision>
  </link>
  <link name="Leg2_Knee_actuator_assembly_Knee_motor_bearings">
    <inertial>
      <origin xyz="-0.03290840372194134 -0.004039592452170204 0.01652774946677134" rpy="2.170394212777092e-52 -0.0 -2.1382117680737565e-50" />
      <mass value="0.009270686219329867" />
      <inertia ixx="6.40847184964579e-06" iyy="1.2008665972833722e-05" izz="7.1503538219588035e-06" ixy="-7.935000500045531e-18" iyz="2.0383039669718147e-06" ixz="2.237520973250532e-17" />
    </inertial>
    <visual name="Leg2_Knee_actuator_assembly_Knee_motor_bearings_visual">
      <origin xyz="-0.048895819689534735 -0.1310942831364251 0.012406879778034537" rpy="-2.4429967701427775 -1.1077791797796954 -2.3246023184988633" />
      <geometry>
        <mesh filename="meshes/urdf/Leg2_Knee-actuator-assembly_Knee-motor-bearings.stl" scale="0.001 0.001 0.001" />
      </geometry>
    </visual>
    <collision name="Leg2_Knee_actuator_assembly_Knee_motor_bearings_collision">
      <origin xyz="-0.048895819689534735 -0.1310942831364251 0.012406879778034537" rpy="-2.4429967701427775 -1.1077791797796954 -2.3246023184988633" />
      <geometry>
        <mesh filename="meshes/urdf/Leg2_Knee-actuator-assembly_Knee-motor-bearings.stl" scale="0.001 0.001 0.001" />
      </geometry>
    </collision>
  </link>
  <link name="Leg2_Knee_actuator_assembly_End_Bearing_Holder">
    <inertial>
      <origin xyz="0.03390957918454018 -0.011853406889750815 0.022055263547475903" rpy="0.0 -6.162975822039156e-33 0.0" />
      <mass value="0.057169625310268736" />
      <inertia ixx="5.134763459656125e-05" iyy="9.685513653307463e-05" izz="5.79170207806517e-05" ixy="3.525297596199184e-07" iyz="1.6350615869927147e-05" ixz="-9.343246847045391e-07" />
    </inertial>
    <visual name="Leg2_Knee_actuator_assembly_End_Bearing_Holder_visual">
      <origin xyz="0.03280111190640733 0.11735049231576791 0.025353905841049598" rpy="-3.852309078793539e-16 1.221730476396031 1.5707963267948961" />
      <geometry>
        <mesh filename="meshes/urdf/Leg2_Knee-actuator-assembly_End-Bearing-Holder.stl" scale="0.001 0.001 0.001" />
      </geometry>
    </visual>
    <collision name="Leg2_Knee_actuator_assembly_End_Bearing_Holder_collision">
      <origin xyz="0.03280111190640733 0.11735049231576791 0.025353905841049598" rpy="-3.852309078793539e-16 1.221730476396031 1.5707963267948961" />
      <geometry>
        <mesh filename="meshes/urdf/Leg2_Knee-actuator-assembly_End-Bearing-Holder.stl" scale="0.001 0.001 0.001" />
      </geometry>
    </collision>
  </link>
  <link name="Leg2_Hip_actuator_assembly_Motor">
    <inertial>
      <origin xyz="0.014254586305143811 0.01379910741140097 0.03445749499235994" rpy="0.0 -0.0 0.0" />
      <mass value="0.3028214126901055" />
      <inertia ixx="0.00014141746037829583" iyy="0.0002317402126784246" izz="0.0001381522821278791" ixy="1.0525676781242103e-06" iyz="1.7994859376896385e-07" ixz="5.36152601048854e-08" />
    </inertial>
    <visual name="Leg2_Hip_actuator_assembly_Motor_visual">
      <origin xyz="0.014088085164716055 -2.4447111002245947e-15 0.03421294999999988" rpy="1.570796326794897 9.836221983249827e-17 1.5707963267948966" />
      <geometry>
        <mesh filename="meshes/urdf/Leg2_Hip-actuator-assembly_Motor.stl" scale="0.001 0.001 0.001" />
      </geometry>
    </visual>
    <collision name="Leg2_Hip_actuator_assembly_Motor_collision">
      <origin xyz="0.014088085164716055 -2.4447111002245947e-15 0.03421294999999988" rpy="1.570796326794897 9.836221983249827e-17 1.5707963267948966" />
      <geometry>
        <mesh filename="meshes/urdf/Leg2_Hip-actuator-assembly_Motor.stl" scale="0.001 0.001 0.001" />
      </geometry>
    </collision>
  </link>
  <link name="Leg2_Hip_actuator_assembly_Hip_Bracket">
    <inertial>
      <origin xyz="0.007563359926921671 -0.015173017999739642 0.038050926203696385" rpy="-4.446271175410867e-78 -0.0 0.0" />
      <mass value="0.05792781115933178" />
      <inertia ixx="0.00010067920230328112" iyy="9.229473206872826e-05" izz="5.893653888483161e-05" ixy="-9.048817121139252e-06" iyz="1.5854757320035287e-05" ixz="1.3007096080781451e-05" />
    </inertial>
    <visual name="Leg2_Hip_actuator_assembly_Hip_Bracket_visual">
      <origin xyz="0.017249999999999908 0.0050957912155001495 0.10295159987240521" rpy="-1.55100753225207e-30 0.34906585039886595 -1.5707963267948968" />
      <geometry>
        <mesh filename="meshes/urdf/Leg2_Hip-actuator-assembly_Hip-Bracket.stl" scale="0.001 0.001 0.001" />
      </geometry>
    </visual>
    <collision name="Leg2_Hip_actuator_assembly_Hip_Bracket_collision">
      <origin xyz="0.017249999999999908 0.0050957912155001495 0.10295159987240521" rpy="-1.55100753225207e-30 0.34906585039886595 -1.5707963267948968" />
      <geometry>
        <mesh filename="meshes/urdf/Leg2_Hip-actuator-assembly_Hip-Bracket.stl" scale="0.001 0.001 0.001" />
      </geometry>
    </collision>
  </link>
  <link name="Leg2_Hip_actuator_assembly_Body_Bracket">
    <inertial>
      <origin xyz="-0.034799977001900045 -0.004424738499856889 -0.029414785865833598" rpy="0.0 -0.0 0.0" />
      <mass value="0.2737560132535958" />
      <inertia ixx="0.00011826659575640136" iyy="0.0003078575243544157" izz="0.00020548953826175775" ixy="-6.214987796323082e-11" iyz="-9.185276276079258e-08" ixz="3.862534684456742e-10" />
    </inertial>
    <visual name="Leg2_Hip_actuator_assembly_Body_Bracket_visual">
      <origin xyz="0.04767899757722809 0.02862177809359275 0.017366123416015355" rpy="1.7516230804060163e-46 1.5707963267948963 0" />
      <geometry>
        <mesh filename="meshes/urdf/Leg2_Hip-actuator-assembly_Body-Bracket.stl" scale="0.001 0.001 0.001" />
      </geometry>
    </visual>
    <collision name="Leg2_Hip_actuator_assembly_Body_Bracket_collision">
      <origin xyz="0.04767899757722809 0.02862177809359275 0.017366123416015355" rpy="1.7516230804060163e-46 1.5707963267948963 0" />
      <geometry>
        <mesh filename="meshes/urdf/Leg2_Hip-actuator-assembly_Body-Bracket.stl" scale="0.001 0.001 0.001" />
      </geometry>
    </collision>
  </link>
  <link name="Leg2_Tibia_Leg">
    <inertial>
      <origin xyz="-0.1042198749339957 0.02273014910994723 -0.04195018778396431" rpy="-7.190453749649841e-67 -0.0 -2.465190328815662e-32" />
      <mass value="0.6725091028785471" />
      <inertia ixx="0.0004886387764186932" iyy="0.00420576839243607" izz="0.0038487089396547665" ixy="0.00038652834875009545" iyz="0.00014940626353335975" ixz="-0.0010640318906557293" />
    </inertial>
    <visual name="Leg2_Tibia_Leg_visual">
      <origin xyz="-0.08507464832369398 -0.06462941456089025 0.08108231694602364" rpy="-2.8797932657906435 -0.349065850398866 1.5707963267948966" />
      <geometry>
        <mesh filename="meshes/urdf/Leg2_Tibia_Leg.stl" scale="0.001 0.001 0.001" />
      </geometry>
    </visual>
    <collision name="Leg2_Tibia_Leg_collision">
      <origin xyz="-0.08507464832369398 -0.06462941456089025 0.08108231694602364" rpy="-2.8797932657906435 -0.349065850398866 1.5707963267948966" />
      <geometry>
        <mesh filename="meshes/urdf/Leg2_Tibia_Leg.stl" scale="0.001 0.001 0.001" />
      </geometry>
    </collision>
  </link>
  <link name="Leg2_Tibia_Foot">
    <inertial>
      <origin xyz="-0.004715990367889322 0.007121947889964915 -0.0020245533659755213" rpy="3.851859888774472e-34 3.0814879110195774e-33 -6.681911775230489e-52" />
      <mass value="0.0012152855294447645" />
      <inertia ixx="2.8376244461320633e-08" iyy="2.582259179845659e-08" izz="2.6428233002155383e-08" ixy="-3.6911670596814117e-09" iyz="-2.540965026007117e-10" ixz="1.0141397982591512e-08" />
    </inertial>
    <visual name="Leg2_Tibia_Foot_visual">
      <origin xyz="0.16677737167630655 0.09958037456089149 -0.139099816946024" rpy="0.2617993877991509 0.34906585039886606 -1.5707963267948968" />
      <geometry>
        <mesh filename="meshes/urdf/Leg2_Tibia_Foot.stl" scale="0.001 0.001 0.001" />
      </geometry>
    </visual>
    <collision name="Leg2_Tibia_Foot_collision">
      <origin xyz="0.16677737167630655 0.09958037456089149 -0.139099816946024" rpy="0.2617993877991509 0.34906585039886606 -1.5707963267948968" />
      <geometry>
        <mesh filename="meshes/urdf/Leg2_Tibia_Foot.stl" scale="0.001 0.001 0.001" />
      </geometry>
    </collision>
  </link>
  <link name="Leg2_Tibia_BadTouch">
    <inertial>
      <origin xyz="-0.01430743157891561 0.006658475228879475 -0.018294017400239043" rpy="3.851859888774472e-34 3.0814879110195774e-33 -6.681911775230489e-52" />
      <mass value="0.0028499001119515355" />
      <inertia ixx="6.698251338859305e-07" iyy="1.4485821697084894e-05" izz="1.3974161308839535e-05" ixy="-6.363163842038006e-07" iyz="2.1466702153230888e-07" ixz="1.7482648972288953e-06" />
    </inertial>
    <visual name="Leg2_Tibia_BadTouch_visual">
      <origin xyz="-0.0018152277230344212 0.051406101057133356 -0.024185348028798615" rpy="1.5720566872996597e-15 0.34906585039886584 -1.5707963267948968" />
      <geometry>
        <mesh filename="meshes/urdf/Leg2_Tibia_BadTouch.stl" scale="0.001 0.001 0.001" />
      </geometry>
    </visual>
    <collision name="Leg2_Tibia_BadTouch_collision">
      <origin xyz="-0.0018152277230344212 0.051406101057133356 -0.024185348028798615" rpy="1.5720566872996597e-15 0.34906585039886584 -1.5707963267948968" />
      <geometry>
        <mesh filename="meshes/urdf/Leg2_Tibia_BadTouch.stl" scale="0.001 0.001 0.001" />
      </geometry>
    </collision>
  </link>
  <link name="Leg3_Femur_actuator_assembly_Motor">
    <inertial>
      <origin xyz="-0.016829148946235575 0.02215808670676408 0.026876072229761086" rpy="0.0 -0.0 0.0" />
      <mass value="0.3028214126901055" />
      <inertia ixx="0.00014140196787328953" iyy="0.00022187592407094678" izz="0.00014803206324036713" ixy="-9.311571849972451e-07" iyz="-2.8735500791637544e-05" ixz="5.64611359995062e-07" />
    </inertial>
    <visual name="Leg3_Femur_actuator_assembly_Motor_visual">
      <origin xyz="-0.017016330000000295 0.03527998769740497 0.022600143338931834" rpy="-1.48352986419518 -0.33161255787892274 -1.5707963267948968" />
      <geometry>
        <mesh filename="meshes/urdf/Leg3_Femur-actuator-assembly_Motor.stl" scale="0.001 0.001 0.001" />
      </geometry>
    </visual>
    <collision name="Leg3_Femur_actuator_assembly_Motor_collision">
      <origin xyz="-0.017016330000000295 0.03527998769740497 0.022600143338931834" rpy="-1.48352986419518 -0.33161255787892274 -1.5707963267948968" />
      <geometry>
        <mesh filename="meshes/urdf/Leg3_Femur-actuator-assembly_Motor.stl" scale="0.001 0.001 0.001" />
      </geometry>
    </collision>
  </link>
  <link name="Leg3_Femur_actuator_assembly_Femur">
    <inertial>
      <origin xyz="0.037211651361724586 0.011858797188076817 0.004765925660046389" rpy="6.962307647929205e-36 -0.0 0.0" />
      <mass value="0.06743801039317165" />
      <inertia ixx="4.0605907493853916e-05" iyy="0.00024407531981795723" izz="0.00021954866018461723" ixy="-1.3631058459897056e-05" iyz="-1.017838274881321e-05" ixz="-3.314093314333887e-05" />
    </inertial>
    <visual name="Leg3_Femur_actuator_assembly_Femur_visual">
      <origin xyz="-3.375077994860476e-16 -0.027892797697404995 0.009604256661068239" rpy="2.3561944901923453 0.3316125578789228 1.5707963267948968" />
      <geometry>
        <mesh filename="meshes/urdf/Leg3_Femur-actuator-assembly_Femur.stl" scale="0.001 0.001 0.001" />
      </geometry>
    </visual>
    <collision name="Leg3_Femur_actuator_assembly_Femur_collision">
      <origin xyz="-3.375077994860476e-16 -0.027892797697404995 0.009604256661068239" rpy="2.3561944901923453 0.3316125578789228 1.5707963267948968" />
      <geometry>
        <mesh filename="meshes/urdf/Leg3_Femur-actuator-assembly_Femur.stl" scale="0.001 0.001 0.001" />
      </geometry>
    </collision>
  </link>
  <link name="Leg3_Knee_actuator_assembly_Motor">
    <inertial>
      <origin xyz="-7.881548495362711e-05 -0.011443333776845926 0.004241835955098106" rpy="1.4312466539468394e-33 -0.0 0.0" />
      <mass value="0.3028214126901055" />
      <inertia ixx="0.00013946533174021263" iyy="0.00022259319497845568" izz="0.00014925142846593763" ixy="1.0354665568419295e-06" iyz="-2.74840172467994e-05" ixz="1.337673648146938e-06" />
    </inertial>
    <visual name="Leg3_Knee_actuator_assembly_Motor_visual">
      <origin xyz="-4.618527782440651e-16 -0.024583483335946232 0.008464767154905628" rpy="0.7033676885537146 0.331612557878924 1.5707963267948952" />
      <geometry>
        <mesh filename="meshes/urdf/Leg3_Knee-actuator-assembly_Motor.stl" scale="0.001 0.001 0.001" />
      </geometry>
    </visual>
    <collision name="Leg3_Knee_actuator_assembly_Motor_collision">
      <origin xyz="-4.618527782440651e-16 -0.024583483335946232 0.008464767154905628" rpy="0.7033676885537146 0.331612557878924 1.5707963267948952" />
      <geometry>
        <mesh filename="meshes/urdf/Leg3_Knee-actuator-assembly_Motor.stl" scale="0.001 0.001 0.001" />
      </geometry>
    </collision>
  </link>
  <link name="Leg3_Knee_actuator_assembly_KneeMotorPulley">
    <inertial>
      <origin xyz="9.525713551283843e-15 -0.005762274030233457 0.0019841118664487923" rpy="-1.5196030302648336e-33 -0.0 0.0" />
      <mass value="0.08135375942547957" />
      <inertia ixx="7.261200035934161e-06" iyy="1.191132275912182e-05" izz="7.812525585173744e-06" ixy="5.610848288345232e-17" iyz="-1.6011656589797522e-06" ixz="1.5802226714242043e-16" />
    </inertial>
    <visual name="Leg3_Knee_actuator_assembly_KneeMotorPulley_visual">
      <origin xyz="0.012448362893745837 0.000979455447538573 0.03816742715207012" rpy="-2.2741640153486107 0.33161255787892385 1.5707963267948981" />
      <geometry>
        <mesh filename="meshes/urdf/Leg3_Knee-actuator-assembly_KneeMotorPulley.stl" scale="0.001 0.001 0.001" />
      </geometry>
    </visual>
    <collision name="Leg3_Knee_actuator_assembly_KneeMotorPulley_collision">
      <origin xyz="0.012448362893745837 0.000979455447538573 0.03816742715207012" rpy="-2.2741640153486107 0.33161255787892385 1.5707963267948981" />
      <geometry>
        <mesh filename="meshes/urdf/Leg3_Knee-actuator-assembly_KneeMotorPulley.stl" scale="0.001 0.001 0.001" />
      </geometry>
    </collision>
  </link>
  <link name="Leg3_Knee_actuator_assembly_Knee_motor_bearings">
    <inertial>
      <origin xyz="-0.03290840372194119 -0.007261888544417374 -0.015386675375649084" rpy="-4.601090941284411e-33 -0.0 0.0" />
      <mass value="0.009270686219329867" />
      <inertia ixx="6.408471849645877e-06" iyy="1.2078321979160709e-05" izz="7.080697815632338e-06" ixy="-7.946141825143328e-18" iyz="-1.952285962823704e-06" ixz="-2.2330975705176695e-17" />
    </inertial>
    <visual name="Leg3_Knee_actuator_assembly_Knee_motor_bearings_visual">
      <origin xyz="-0.04889581968953461 0.09407149852899728 -0.09214226576548835" rpy="2.415556887818204 1.1203572383395008 -2.349230407128447" />
      <geometry>
        <mesh filename="meshes/urdf/Leg3_Knee-actuator-assembly_Knee-motor-bearings.stl" scale="0.001 0.001 0.001" />
      </geometry>
    </visual>
    <collision name="Leg3_Knee_actuator_assembly_Knee_motor_bearings_collision">
      <origin xyz="-0.04889581968953461 0.09407149852899728 -0.09214226576548835" rpy="2.415556887818204 1.1203572383395008 -2.349230407128447" />
      <geometry>
        <mesh filename="meshes/urdf/Leg3_Knee-actuator-assembly_Knee-motor-bearings.stl" scale="0.001 0.001 0.001" />
      </geometry>
    </collision>
  </link>
  <link name="Leg3_Knee_actuator_assembly_End_Bearing_Holder">
    <inertial>
      <origin xyz="0.033909579184540316 -0.004667995898852588 -0.02459974902967094" rpy="0.0 -0.0 0.0" />
      <mass value="0.057169625310268736" />
      <inertia ixx="5.1347634596559744e-05" iyy="9.742723908222475e-05" izz="5.734491823150339e-05" ixy="3.140224969637754e-07" iyz="-1.564412805873705e-05" ixz="9.479608215885271e-07" />
    </inertial>
    <visual name="Leg3_Knee_actuator_assembly_End_Bearing_Holder_visual">
      <origin xyz="0.03280111190640747 -0.10715418722904044 0.05414737280676807" rpy="-5.331342427222023e-17 -1.2391837689159737 1.5707963267948968" />
      <geometry>
        <mesh filename="meshes/urdf/Leg3_Knee-actuator-assembly_End-Bearing-Holder.stl" scale="0.001 0.001 0.001" />
      </geometry>
    </visual>
    <collision name="Leg3_Knee_actuator_assembly_End_Bearing_Holder_collision">
      <origin xyz="0.03280111190640747 -0.10715418722904044 0.05414737280676807" rpy="-5.331342427222023e-17 -1.2391837689159737 1.5707963267948968" />
      <geometry>
        <mesh filename="meshes/urdf/Leg3_Knee-actuator-assembly_End-Bearing-Holder.stl" scale="0.001 0.001 0.001" />
      </geometry>
    </collision>
  </link>
  <link name="Leg3_Hip_actuator_assembly_Motor">
    <inertial>
      <origin xyz="0.014254586305143828 0.01379910741140097 0.03445749499235994" rpy="0.0 -0.0 0.0" />
      <mass value="0.3028214126901055" />
      <inertia ixx="0.00014141746037829583" iyy="0.00023174021267842806" izz="0.00013815228212788085" ixy="1.0525676781242103e-06" iyz="1.7994859376896385e-07" ixz="5.361526010575276e-08" />
    </inertial>
    <visual name="Leg3_Hip_actuator_assembly_Motor_visual">
      <origin xyz="0.014088085164716074 -2.4447111002245947e-15 0.03421294999999988" rpy="1.570796326794897 9.836221983249827e-17 1.5707963267948966" />
      <geometry>
        <mesh filename="meshes/urdf/Leg3_Hip-actuator-assembly_Motor.stl" scale="0.001 0.001 0.001" />
      </geometry>
    </visual>
    <collision name="Leg3_Hip_actuator_assembly_Motor_collision">
      <origin xyz="0.014088085164716074 -2.4447111002245947e-15 0.03421294999999988" rpy="1.570796326794897 9.836221983249827e-17 1.5707963267948966" />
      <geometry>
        <mesh filename="meshes/urdf/Leg3_Hip-actuator-assembly_Motor.stl" scale="0.001 0.001 0.001" />
      </geometry>
    </collision>
  </link>
  <link name="Leg3_Hip_actuator_assembly_Hip_Bracket">
    <inertial>
      <origin xyz="0.007563359926921698 -0.012154577139649732 -0.03911982184290766" rpy="-4.446271175410867e-78 -0.0 0.0" />
      <mass value="0.05792781115933178" />
      <inertia ixx="0.00010067920230328242" iyy="9.459170748333471e-05" izz="5.663956347022581e-05" ixy="-1.1533791103242345e-06" iyz="-1.3018228911908146e-05" ixz="-1.5803017318676113e-05" />
    </inertial>
    <visual name="Leg3_Hip_actuator_assembly_Hip_Bracket_visual">
      <origin xyz="0.017249999999999918 -0.06874971769740489 -0.0768015433389322" rpy="-3.141592653589793 0.33161255787892274 1.5707963267948963" />
      <geometry>
        <mesh filename="meshes/urdf/Leg3_Hip-actuator-assembly_Hip-Bracket.stl" scale="0.001 0.001 0.001" />
      </geometry>
    </visual>
    <collision name="Leg3_Hip_actuator_assembly_Hip_Bracket_collision">
      <origin xyz="0.017249999999999918 -0.06874971769740489 -0.0768015433389322" rpy="-3.141592653589793 0.33161255787892274 1.5707963267948963" />
      <geometry>
        <mesh filename="meshes/urdf/Leg3_Hip-actuator-assembly_Hip-Bracket.stl" scale="0.001 0.001 0.001" />
      </geometry>
    </collision>
  </link>
  <link name="Leg3_Hip_actuator_assembly_Body_Bracket">
    <inertial>
      <origin xyz="-0.034799977001900045 -0.004424738499856889 -0.029414785865833598" rpy="0.0 -0.0 0.0" />
      <mass value="0.2737560132535958" />
      <inertia ixx="0.00011826659575640136" iyy="0.00030785752435441224" izz="0.00020548953826174735" ixy="-6.21498778006005e-11" iyz="-9.185276276079258e-08" ixz="3.8625346757831247e-10" />
    </inertial>
    <visual name="Leg3_Hip_actuator_assembly_Body_Bracket_visual">
      <origin xyz="0.04767899757722809 0.02862177809359275 0.017366123416015355" rpy="1.7516230804060163e-46 1.5707963267948963 0" />
      <geometry>
        <mesh filename="meshes/urdf/Leg3_Hip-actuator-assembly_Body-Bracket.stl" scale="0.001 0.001 0.001" />
      </geometry>
    </visual>
    <collision name="Leg3_Hip_actuator_assembly_Body_Bracket_collision">
      <origin xyz="0.04767899757722809 0.02862177809359275 0.017366123416015355" rpy="1.7516230804060163e-46 1.5707963267948963 0" />
      <geometry>
        <mesh filename="meshes/urdf/Leg3_Hip-actuator-assembly_Body-Bracket.stl" scale="0.001 0.001 0.001" />
      </geometry>
    </collision>
  </link>
  <link name="Leg3_Tibia_Leg">
    <inertial>
      <origin xyz="-0.10421987493399563 0.008735467386426663 0.04690596262232576" rpy="1.4312466539468394e-33 -0.0 0.0" />
      <mass value="0.6725091028785471" />
      <inertia ixx="0.000488638776418672" iyy="0.004210498461530271" izz="0.003843978870560545" ixy="0.00036922802029719647" iyz="-0.00014356511465868856" ixz="0.0010701582582717866" />
    </inertial>
    <visual name="Leg3_Tibia_Leg_visual">
      <origin xyz="-0.08507464832369392 -0.0008002645006558851 -0.10368540632779459" rpy="0.2617993877991493 -0.331612557878923 -1.5707963267948966" />
      <geometry>
        <mesh filename="meshes/urdf/Leg3_Tibia_Leg.stl" scale="0.001 0.001 0.001" />
      </geometry>
    </visual>
    <collision name="Leg3_Tibia_Leg_collision">
      <origin xyz="-0.08507464832369392 -0.0008002645006558851 -0.10368540632779459" rpy="0.2617993877991493 -0.331612557878923 -1.5707963267948966" />
      <geometry>
        <mesh filename="meshes/urdf/Leg3_Tibia_Leg.stl" scale="0.001 0.001 0.001" />
      </geometry>
    </collision>
  </link>
  <link name="Leg3_Tibia_Foot">
    <inertial>
      <origin xyz="-0.0047159903678894825 -0.004260701088821772 0.006055355592510896" rpy="1.540743955509789e-33 -0.0 0.0" />
      <mass value="0.0012152855294447645" />
      <inertia ixx="2.837624446125964e-08" iyy="2.581390857259922e-08" izz="2.643691622803985e-08" ixy="-3.513612970709797e-09" iyz="2.433736116417634e-10" ixz="-1.0204273183109956e-08" />
    </inertial>
    <visual name="Leg3_Tibia_Foot_visual">
      <origin xyz="0.16677737167630655 0.010149864500657736 0.1707688163277954" rpy="-2.879793265790641 0.33161255787892285 1.5707963267948963" />
      <geometry>
        <mesh filename="meshes/urdf/Leg3_Tibia_Foot.stl" scale="0.001 0.001 0.001" />
      </geometry>
    </visual>
    <collision name="Leg3_Tibia_Foot_collision">
      <origin xyz="0.16677737167630655 0.010149864500657736 0.1707688163277954" rpy="-2.879793265790641 0.33161255787892285 1.5707963267948963" />
      <geometry>
        <mesh filename="meshes/urdf/Leg3_Tibia_Foot.stl" scale="0.001 0.001 0.001" />
      </geometry>
    </collision>
  </link>
  <link name="Leg3_Tibia_BadTouch">
    <inertial>
      <origin xyz="-0.014307431578915787 0.006338194708694615 0.018407442203850974" rpy="3.4211388289180104e-49 -0.0 0.0" />
      <mass value="0.0028499001119515355" />
      <inertia ixx="6.698251338861747e-07" iyy="1.449315762325304e-05" izz="1.3966825382671384e-05" ixy="-6.057080405899001e-07" iyz="-2.0560790716676337e-07" ixz="-1.7591038801769654e-06" />
    </inertial>
    <visual name="Leg3_Tibia_BadTouch_visual">
      <origin xyz="-0.001815227723034571 -0.024729707493551557 0.05114645939423234" rpy="-3.1415926535897905 0.3316125578789231 1.5707963267948966" />
      <geometry>
        <mesh filename="meshes/urdf/Leg3_Tibia_BadTouch.stl" scale="0.001 0.001 0.001" />
      </geometry>
    </visual>
    <collision name="Leg3_Tibia_BadTouch_collision">
      <origin xyz="-0.001815227723034571 -0.024729707493551557 0.05114645939423234" rpy="-3.1415926535897905 0.3316125578789231 1.5707963267948966" />
      <geometry>
        <mesh filename="meshes/urdf/Leg3_Tibia_BadTouch.stl" scale="0.001 0.001 0.001" />
      </geometry>
    </collision>
  </link>
  <link name="Leg4_Femur_actuator_assembly_Motor">
    <inertial>
      <origin xyz="-0.01682914894623567 0.012200892588599101 0.03262580194101238" rpy="0.0 -0.0 0.0" />
      <mass value="0.3028214126901055" />
      <inertia ixx="0.0001414019678732904" iyy="0.00023174021267842546" izz="0.0001381677746328889" ixy="-1.0642458936766788e-06" iyz="8.752651726269198e-08" ixz="2.3069540264057144e-07" />
    </inertial>
    <visual name="Leg4_Femur_actuator_assembly_Motor_visual">
      <origin xyz="-0.01701633000000039 0.026000000000002483 0.03285490483528404" rpy="-1.48352986419518 -9.020562075079369e-17 -1.5707963267948963" />
      <geometry>
        <mesh filename="meshes/urdf/Leg4_Femur-actuator-assembly_Motor.stl" scale="0.001 0.001 0.001" />
      </geometry>
    </visual>
    <collision name="Leg4_Femur_actuator_assembly_Motor_collision">
      <origin xyz="-0.01701633000000039 0.026000000000002483 0.03285490483528404" rpy="-1.48352986419518 -9.020562075079369e-17 -1.5707963267948963" />
      <geometry>
        <mesh filename="meshes/urdf/Leg4_Femur-actuator-assembly_Motor.stl" scale="0.001 0.001 0.001" />
      </geometry>
    </collision>
  </link>
  <link name="Leg4_Femur_actuator_assembly_Femur">
    <inertial>
      <origin xyz="0.037211651361724454 0.009661077868574921 0.008367116711946912" rpy="7.045397905358787e-49 1.0947644252537636e-47 0.0" />
      <mass value="0.06743801039317165" />
      <inertia ixx="4.060590749385374e-05" iyy="0.00024774206391141285" izz="0.00021588191609116155" ixy="-2.0987865384479222e-06" iyz="-4.706153330538224e-07" ixz="-3.577320644580827e-05" />
    </inertial>
    <visual name="Leg4_Femur_actuator_assembly_Femur_visual">
      <origin xyz="-4.796163466380677e-16 -0.02950000000000248 -4.835283755610931e-09" rpy="2.3561944901923453 8.882296699767487e-17 1.5707963267948963" />
      <geometry>
        <mesh filename="meshes/urdf/Leg4_Femur-actuator-assembly_Femur.stl" scale="0.001 0.001 0.001" />
      </geometry>
    </visual>
    <collision name="Leg4_Femur_actuator_assembly_Femur_collision">
      <origin xyz="-4.796163466380677e-16 -0.02950000000000248 -4.835283755610931e-09" rpy="2.3561944901923453 8.882296699767487e-17 1.5707963267948963" />
      <geometry>
        <mesh filename="meshes/urdf/Leg4_Femur-actuator-assembly_Femur.stl" scale="0.001 0.001 0.001" />
      </geometry>
    </collision>
  </link>
  <link name="Leg4_Knee_actuator_assembly_Motor">
    <inertial>
      <origin xyz="-7.881548495372481e-05 -0.012200892588597969 0.000285159183635475" rpy="0.0 -0.0 0.0" />
      <mass value="0.3028214126901055" />
      <inertia ixx="0.00013946533174021285" iyy="0.00023174021267842655" izz="0.00014010441076596643" ixy="5.435489230130397e-07" iyz="9.191489442538989e-07" ixz="1.601910218325571e-06" />
    </inertial>
    <visual name="Leg4_Knee_actuator_assembly_Motor_visual">
      <origin xyz="-5.506706202140776e-16 -0.026000000000001373 4.8352840753551615e-09" rpy="0.703367688553715 1.2212453270876659e-15 1.5707963267948957" />
      <geometry>
        <mesh filename="meshes/urdf/Leg4_Knee-actuator-assembly_Motor.stl" scale="0.001 0.001 0.001" />
      </geometry>
    </visual>
    <collision name="Leg4_Knee_actuator_assembly_Motor_collision">
      <origin xyz="-5.506706202140776e-16 -0.026000000000001373 4.8352840753551615e-09" rpy="0.703367688553715 1.2212453270876659e-15 1.5707963267948957" />
      <geometry>
        <mesh filename="meshes/urdf/Leg4_Knee-actuator-assembly_Motor.stl" scale="0.001 0.001 0.001" />
      </geometry>
    </collision>
  </link>
  <link name="Leg4_Knee_actuator_assembly_KneeMotorPulley">
    <inertial>
      <origin xyz="9.450218385609333e-15 -0.006094295273218942 -4.8352322234990195e-09" rpy="-5.473822126268817e-48 -0.0 0.0" />
      <mass value="0.08135375942547957" />
      <inertia ixx="7.261200035933724e-06" iyy="1.2462648308957818e-05" izz="7.26120003533725e-06" ixy="1.6538113906136917e-18" iyz="4.879458352452516e-18" ixz="1.6772607608350754e-16" />
    </inertial>
    <visual name="Leg4_Knee_actuator_assembly_KneeMotorPulley_visual">
      <origin xyz="0.012448362893745768 -0.011500000000001159 0.03640688431801714" rpy="-2.274164015348611 1.0325125379290552e-15 1.5707963267948974" />
      <geometry>
        <mesh filename="meshes/urdf/Leg4_Knee-actuator-assembly_KneeMotorPulley.stl" scale="0.001 0.001 0.001" />
      </geometry>
    </visual>
    <collision name="Leg4_Knee_actuator_assembly_KneeMotorPulley_collision">
      <origin xyz="0.012448362893745768 -0.011500000000001159 0.03640688431801714" rpy="-2.274164015348611 1.0325125379290552e-15 1.5707963267948974" />
      <geometry>
        <mesh filename="meshes/urdf/Leg4_Knee-actuator-assembly_KneeMotorPulley.stl" scale="0.001 0.001 0.001" />
      </geometry>
    </collision>
  </link>
  <link name="Leg4_Knee_actuator_assembly_Knee_motor_bearings">
    <inertial>
      <origin xyz="-0.03290840372194129 -0.0018568433438268816 -0.01691262590841065" rpy="-5.473822126268817e-48 -0.0 0.0" />
      <mass value="0.009270686219329867" />
      <inertia ixx="6.4084718496457444e-06" iyy="1.2750547945198754e-05" izz="6.408471849594275e-06" ixy="-2.417601316174831e-19" iyz="1.169893314559609e-20" ixz="-2.3699981864175323e-17" />
    </inertial>
    <visual name="Leg4_Knee_actuator_assembly_Knee_motor_bearings_visual">
      <origin xyz="-0.04889581968953475 0.11894493236997189 -0.05649553858871178" rpy="1.570796326794899 1.260127719939907 -3.1415926535897905" />
      <geometry>
        <mesh filename="meshes/urdf/Leg4_Knee-actuator-assembly_Knee-motor-bearings.stl" scale="0.001 0.001 0.001" />
      </geometry>
    </visual>
    <collision name="Leg4_Knee_actuator_assembly_Knee_motor_bearings_collision">
      <origin xyz="-0.04889581968953475 0.11894493236997189 -0.05649553858871178" rpy="1.570796326794899 1.260127719939907 -3.1415926535897905" />
      <geometry>
        <mesh filename="meshes/urdf/Leg4_Knee-actuator-assembly_Knee-motor-bearings.stl" scale="0.001 0.001 0.001" />
      </geometry>
    </collision>
  </link>
  <link name="Leg4_Knee_actuator_assembly_End_Bearing_Holder">
    <inertial>
      <origin xyz="0.033909579184540246 0.003595220400248629 -0.024779268524865894" rpy="0.0 -0.0 0.0" />
      <mass value="0.057169625310268736" />
      <inertia ixx="5.134763459656064e-05" iyy="0.00010281021554763139" izz="5.196194176609687e-05" ixy="-1.1711751146868091e-08" iyz="1.0829253630418765e-08" ixz="9.985502905468876e-07" />
    </inertial>
    <visual name="Leg4_Knee_actuator_assembly_End_Bearing_Holder_visual">
      <origin xyz="0.03280111190640737 -0.11894493236997188 0.016311357777757406" rpy="1.5707963267948963 -1.5707963267948966 0" />
      <geometry>
        <mesh filename="meshes/urdf/Leg4_Knee-actuator-assembly_End-Bearing-Holder.stl" scale="0.001 0.001 0.001" />
      </geometry>
    </visual>
    <collision name="Leg4_Knee_actuator_assembly_End_Bearing_Holder_collision">
      <origin xyz="0.03280111190640737 -0.11894493236997188 0.016311357777757406" rpy="1.5707963267948963 -1.5707963267948966 0" />
      <geometry>
        <mesh filename="meshes/urdf/Leg4_Knee-actuator-assembly_End-Bearing-Holder.stl" scale="0.001 0.001 0.001" />
      </geometry>
    </collision>
  </link>
  <link name="Leg4_Hip_actuator_assembly_Motor">
    <inertial>
      <origin xyz="0.014254586305143868 0.01379910741140097 0.03445749499235996" rpy="0.0 -0.0 0.0" />
      <mass value="0.3028214126901055" />
      <inertia ixx="0.0001414174603782967" iyy="0.00023174021267842655" izz="0.0001381522821278816" ixy="1.0525676781244814e-06" iyz="1.7994859376907227e-07" ixz="5.361526010456014e-08" />
    </inertial>
    <visual name="Leg4_Hip_actuator_assembly_Motor_visual">
      <origin xyz="0.014088085164716114 -2.4447111002245947e-15 0.0342129499999999" rpy="1.570796326794897 9.836221983249827e-17 1.5707963267948966" />
      <geometry>
        <mesh filename="meshes/urdf/Leg4_Hip-actuator-assembly_Motor.stl" scale="0.001 0.001 0.001" />
      </geometry>
    </visual>
    <collision name="Leg4_Hip_actuator_assembly_Motor_collision">
      <origin xyz="0.014088085164716114 -2.4447111002245947e-15 0.0342129499999999" rpy="1.570796326794897 9.836221983249827e-17 1.5707963267948966" />
      <geometry>
        <mesh filename="meshes/urdf/Leg4_Hip-actuator-assembly_Motor.stl" scale="0.001 0.001 0.001" />
      </geometry>
    </collision>
  </link>
  <link name="Leg4_Hip_actuator_assembly_Hip_Bracket">
    <inertial>
      <origin xyz="0.007563359926921698 0.0012437881617800883 -0.040945661737601155" rpy="-4.446271175410867e-78 -0.0 0.0" />
      <mass value="0.05792781115933178" />
      <inertia ixx="0.00010067920230328182" iyy="9.858380629719354e-05" izz="5.264746465636746e-05" ixy="4.05441780977613e-06" iyz="1.4243321119434625e-06" ixz="-1.5317549933663643e-05" />
    </inertial>
    <visual name="Leg4_Hip_actuator_assembly_Hip_Bracket_visual">
      <origin xyz="0.017249999999999918 -0.04000000000000242 -0.09500000483528422" rpy="-3.141592653589793 1.0963964870939656e-16 1.5707963267948963" />
      <geometry>
        <mesh filename="meshes/urdf/Leg4_Hip-actuator-assembly_Hip-Bracket.stl" scale="0.001 0.001 0.001" />
      </geometry>
    </visual>
    <collision name="Leg4_Hip_actuator_assembly_Hip_Bracket_collision">
      <origin xyz="0.017249999999999918 -0.04000000000000242 -0.09500000483528422" rpy="-3.141592653589793 1.0963964870939656e-16 1.5707963267948963" />
      <geometry>
        <mesh filename="meshes/urdf/Leg4_Hip-actuator-assembly_Hip-Bracket.stl" scale="0.001 0.001 0.001" />
      </geometry>
    </collision>
  </link>
  <link name="Leg4_Hip_actuator_assembly_Body_Bracket">
    <inertial>
      <origin xyz="-0.034799977001900004 -0.004424738499856889 -0.02941478586583357" rpy="0.0 -0.0 0.0" />
      <mass value="0.2737560132535958" />
      <inertia ixx="0.00011826659575640212" iyy="0.0003078575243544088" izz="0.00020548953826174317" ixy="-6.214987801744093e-11" iyz="-9.185276276079258e-08" ixz="3.8625346877093486e-10" />
    </inertial>
    <visual name="Leg4_Hip_actuator_assembly_Body_Bracket_visual">
      <origin xyz="0.0476789975772281 0.02862177809359275 0.017366123416015372" rpy="1.7516230804060163e-46 1.5707963267948963 0" />
      <geometry>
        <mesh filename="meshes/urdf/Leg4_Hip-actuator-assembly_Body-Bracket.stl" scale="0.001 0.001 0.001" />
      </geometry>
    </visual>
    <collision name="Leg4_Hip_actuator_assembly_Body_Bracket_collision">
      <origin xyz="0.0476789975772281 0.02862177809359275 0.017366123416015372" rpy="1.7516230804060163e-46 1.5707963267948963 0" />
      <geometry>
        <mesh filename="meshes/urdf/Leg4_Hip-actuator-assembly_Body-Bracket.stl" scale="0.001 0.001 0.001" />
      </geometry>
    </collision>
  </link>
  <link name="Leg4_Tibia_Leg">
    <inertial>
      <origin xyz="-0.10421987493399568 -0.007011542435093636 0.047194455370022335" rpy="0.0 -0.0 0.0" />
      <mass value="0.6725091028785471" />
      <inertia ixx="0.0004886387764186564" iyy="0.0042600368658873245" izz="0.0037944404662035047" ixy="7.025027001295644e-07" iyz="-3.0485813773796847e-07" ixz="0.0011320633971690138" />
    </inertial>
    <visual name="Leg4_Tibia_Leg_visual">
      <origin xyz="-0.08507464832369395 0.03300000000000251 -0.0982970119291224" rpy="0.2617993877991496 -1.9428902930940183e-16 -1.5707963267948963" />
      <geometry>
        <mesh filename="meshes/urdf/Leg4_Tibia_Leg.stl" scale="0.001 0.001 0.001" />
      </geometry>
    </visual>
    <collision name="Leg4_Tibia_Leg_collision">
      <origin xyz="-0.08507464832369395 0.03300000000000251 -0.0982970119291224" rpy="0.2617993877991496 -1.9428902930940183e-16 -1.5707963267948963" />
      <geometry>
        <mesh filename="meshes/urdf/Leg4_Tibia_Leg.stl" scale="0.001 0.001 0.001" />
      </geometry>
    </collision>
  </link>
  <link name="Leg4_Tibia_Foot">
    <inertial>
      <origin xyz="-0.004715990367889571 -0.006000000023908152 0.004338303909012282" rpy="0.0 -0.0 0.0" />
      <mass value="0.0012152855294447645" />
      <inertia ixx="2.8376244461281676e-08" iyy="2.573010827743884e-08" izz="2.6520716523135865e-08" ixy="5.654283736101356e-17" iyz="1.1697779111466064e-16" ixz="-1.0792250335483084e-08" />
    </inertial>
    <visual name="Leg4_Tibia_Foot_visual">
      <origin xyz="0.1667773716763065 -0.04600000000000089 0.1647695619291231" rpy="-2.879793265790641 1.9428902930940173e-16 1.5707963267948963" />
      <geometry>
        <mesh filename="meshes/urdf/Leg4_Tibia_Foot.stl" scale="0.001 0.001 0.001" />
      </geometry>
    </visual>
    <collision name="Leg4_Tibia_Foot_collision">
      <origin xyz="0.1667773716763065 -0.04600000000000089 0.1647695619291231" rpy="-2.879793265790641 1.9428902930940173e-16 1.5707963267948963" />
      <geometry>
        <mesh filename="meshes/urdf/Leg4_Tibia_Foot.stl" scale="0.001 0.001 0.001" />
      </geometry>
    </collision>
  </link>
  <link name="Leg4_Tibia_BadTouch">
    <inertial>
      <origin xyz="-0.014307431578915895 1.7141843500212416e-15 0.019468089410207785" rpy="0.0 -0.0 0.0" />
      <mass value="0.0028499001119515355" />
      <inertia ixx="6.698251338861679e-07" iyy="1.456395410320127e-05" izz="1.3896028902723197e-05" ixy="2.0752307207730358e-20" iyz="3.293125489181615e-38" ixz="-1.8604646440308696e-06" />
    </inertial>
    <visual name="Leg4_Tibia_BadTouch_visual">
      <origin xyz="-0.0018152277230346781 -0.04003406004253853 0.040308718727737995" rpy="-3.14159265358979 5.533767888366003e-16 1.5707963267948966" />
      <geometry>
        <mesh filename="meshes/urdf/Leg4_Tibia_BadTouch.stl" scale="0.001 0.001 0.001" />
      </geometry>
    </visual>
    <collision name="Leg4_Tibia_BadTouch_collision">
      <origin xyz="-0.0018152277230346781 -0.04003406004253853 0.040308718727737995" rpy="-3.14159265358979 5.533767888366003e-16 1.5707963267948966" />
      <geometry>
        <mesh filename="meshes/urdf/Leg4_Tibia_BadTouch.stl" scale="0.001 0.001 0.001" />
      </geometry>
    </collision>
  </link>
  <link name="Leg5_Femur_actuator_assembly_Motor">
    <inertial>
      <origin xyz="-0.016829148946235658 -0.012200892588598836 -0.032625802270444454" rpy="0.0 -0.0 0.0" />
      <mass value="0.3028214126901055" />
      <inertia ixx="0.0001414019678733225" iyy="0.0002317402126784246" izz="0.00013816777463288802" ixy="1.0642458936767872e-06" iyz="8.752651726312566e-08" ixz="-2.3069540264122196e-07" />
    </inertial>
    <visual name="Leg5_Femur_actuator_assembly_Motor_visual">
      <origin xyz="-0.01701633000000038 -0.0260000000000022 -0.03285490516471619" rpy="1.6580627893946134 1.9428902930940183e-16 1.5707963267948963" />
      <geometry>
        <mesh filename="meshes/urdf/Leg5_Femur-actuator-assembly_Motor.stl" scale="0.001 0.001 0.001" />
      </geometry>
    </visual>
    <collision name="Leg5_Femur_actuator_assembly_Motor_collision">
      <origin xyz="-0.01701633000000038 -0.0260000000000022 -0.03285490516471619" rpy="1.6580627893946134 1.9428902930940183e-16 1.5707963267948963" />
      <geometry>
        <mesh filename="meshes/urdf/Leg5_Femur-actuator-assembly_Motor.stl" scale="0.001 0.001 0.001" />
      </geometry>
    </collision>
  </link>
  <link name="Leg5_Femur_actuator_assembly_Femur">
    <inertial>
      <origin xyz="0.0372116513617245 -0.009661077868574886 -0.008367126382514698" rpy="1.922803467954294e-79 1.0947644252537636e-47 1.2154326714572545e-63" />
      <mass value="0.06743801039317165" />
      <inertia ixx="4.060590749385347e-05" iyy="0.00024774206391141643" izz="0.0002158819160911616" ixy="2.0987865384478447e-06" iyz="-4.706153330540659e-07" ixz="3.5773206445808044e-05" />
    </inertial>
    <visual name="Leg5_Femur_actuator_assembly_Femur_visual">
      <origin xyz="-4.3520742565306136e-16 0.029500000000002507 -4.835283959891967e-09" rpy="-0.785398163397448 -1.9984526946019022e-16 -1.5707963267948961" />
      <geometry>
        <mesh filename="meshes/urdf/Leg5_Femur-actuator-assembly_Femur.stl" scale="0.001 0.001 0.001" />
      </geometry>
    </visual>
    <collision name="Leg5_Femur_actuator_assembly_Femur_collision">
      <origin xyz="-4.3520742565306136e-16 0.029500000000002507 -4.835283959891967e-09" rpy="-0.785398163397448 -1.9984526946019022e-16 -1.5707963267948961" />
      <geometry>
        <mesh filename="meshes/urdf/Leg5_Femur-actuator-assembly_Femur.stl" scale="0.001 0.001 0.001" />
      </geometry>
    </collision>
  </link>
  <link name="Leg5_Knee_actuator_assembly_Motor">
    <inertial>
      <origin xyz="-7.881548495364488e-05 0.012200892588598494 -0.00028514951306753746" rpy="1.539351194922465e-95 -0.0 0.0" />
      <mass value="0.3028214126901055" />
      <inertia ixx="0.00013946533174021003" iyy="0.00023174021267841072" izz="0.00014010441076596622" ixy="-5.435489230130939e-07" iyz="9.191489442538989e-07" ixz="-1.6019102183247036e-06" />
    </inertial>
    <visual name="Leg5_Knee_actuator_assembly_Motor_visual">
      <origin xyz="-4.707345624410664e-16 0.026000000000001893 4.835283888837693e-09" rpy="-2.438224965036078 -1.3461454173579954e-15 -1.5707963267948957" />
      <geometry>
        <mesh filename="meshes/urdf/Leg5_Knee-actuator-assembly_Motor.stl" scale="0.001 0.001 0.001" />
      </geometry>
    </visual>
    <collision name="Leg5_Knee_actuator_assembly_Motor_collision">
      <origin xyz="-4.707345624410664e-16 0.026000000000001893 4.835283888837693e-09" rpy="-2.438224965036078 -1.3461454173579954e-15 -1.5707963267948957" />
      <geometry>
        <mesh filename="meshes/urdf/Leg5_Knee-actuator-assembly_Motor.stl" scale="0.001 0.001 0.001" />
      </geometry>
    </collision>
  </link>
  <link name="Leg5_Knee_actuator_assembly_KneeMotorPulley">
    <inertial>
      <origin xyz="9.419132140919828e-15 0.006094295273218613 -4.835335758457404e-09" rpy="5.798814522305241e-48 -0.0 0.0" />
      <mass value="0.08135375942547957" />
      <inertia ixx="7.261200035937193e-06" iyy="1.2462648308963348e-05" izz="7.26120003533725e-06" ixy="-1.6672495785781509e-18" iyz="4.771038135203948e-18" ixz="-1.6783449630075609e-16" />
    </inertial>
    <visual name="Leg5_Knee_actuator_assembly_KneeMotorPulley_visual">
      <origin xyz="0.012448362893745736 0.011500000000000812 -0.03640689398858498" rpy="0.8674286382411818 -1.1504737342954776e-15 -1.5707963267948974" />
      <geometry>
        <mesh filename="meshes/urdf/Leg5_Knee-actuator-assembly_KneeMotorPulley.stl" scale="0.001 0.001 0.001" />
      </geometry>
    </visual>
    <collision name="Leg5_Knee_actuator_assembly_KneeMotorPulley_collision">
      <origin xyz="0.012448362893745736 0.011500000000000812 -0.03640689398858498" rpy="0.8674286382411818 -1.1504737342954776e-15 -1.5707963267948974" />
      <geometry>
        <mesh filename="meshes/urdf/Leg5_Knee-actuator-assembly_KneeMotorPulley.stl" scale="0.001 0.001 0.001" />
      </geometry>
    </collision>
  </link>
  <link name="Leg5_Knee_actuator_assembly_Knee_motor_bearings">
    <inertial>
      <origin xyz="-0.03290840372194122 0.0018568433438273658 0.016912625578978435" rpy="5.396310605844787e-48 -0.0 0.0" />
      <mass value="0.009270686219329867" />
      <inertia ixx="6.408471849646876e-06" iyy="1.2750547945199805e-05" izz="6.408471849594379e-06" ixy="2.4937974243802526e-19" iyz="-1.595281159667631e-22" ixz="2.358139725155972e-17" />
    </inertial>
    <visual name="Leg5_Knee_actuator_assembly_Knee_motor_bearings_visual">
      <origin xyz="-0.048895819689534714 -0.11894493236997139 0.056495538259279526" rpy="-1.5707963267948937 -1.2601277199399068 3.1415926535897896" />
      <geometry>
        <mesh filename="meshes/urdf/Leg5_Knee-actuator-assembly_Knee-motor-bearings.stl" scale="0.001 0.001 0.001" />
      </geometry>
    </visual>
    <collision name="Leg5_Knee_actuator_assembly_Knee_motor_bearings_collision">
      <origin xyz="-0.048895819689534714 -0.11894493236997139 0.056495538259279526" rpy="-1.5707963267948937 -1.2601277199399068 3.1415926535897896" />
      <geometry>
        <mesh filename="meshes/urdf/Leg5_Knee-actuator-assembly_Knee-motor-bearings.stl" scale="0.001 0.001 0.001" />
      </geometry>
    </collision>
  </link>
  <link name="Leg5_Knee_actuator_assembly_End_Bearing_Holder">
    <inertial>
      <origin xyz="0.03390957918454024 -0.003595220400249002 0.024779268854298167" rpy="0.0 -0.0 0.0" />
      <mass value="0.057169625310268736" />
      <inertia ixx="5.134763459655953e-05" iyy="0.00010281021554763015" izz="5.196194176609619e-05" ixy="1.1711751146864703e-08" iyz="1.0829253631035405e-08" ixz="-9.985502905469554e-07" />
    </inertial>
    <visual name="Leg5_Knee_actuator_assembly_End_Bearing_Holder_visual">
      <origin xyz="0.03280111190640737 0.11894493236997157 -0.0163113574483252" rpy="-1.5707963267948968 1.570796326794896 0" />
      <geometry>
        <mesh filename="meshes/urdf/Leg5_Knee-actuator-assembly_End-Bearing-Holder.stl" scale="0.001 0.001 0.001" />
      </geometry>
    </visual>
    <collision name="Leg5_Knee_actuator_assembly_End_Bearing_Holder_collision">
      <origin xyz="0.03280111190640737 0.11894493236997157 -0.0163113574483252" rpy="-1.5707963267948968 1.570796326794896 0" />
      <geometry>
        <mesh filename="meshes/urdf/Leg5_Knee-actuator-assembly_End-Bearing-Holder.stl" scale="0.001 0.001 0.001" />
      </geometry>
    </collision>
  </link>
  <link name="Leg5_Hip_actuator_assembly_Motor">
    <inertial>
      <origin xyz="-0.014254585975711791 0.013799107411400962 -0.03445749499235994" rpy="0.0 7.382803922328222e-64 0.0" />
      <mass value="0.3028214126901055" />
      <inertia ixx="0.0001414174603782967" iyy="0.00023174021267841072" izz="0.0001381522821278791" ixy="-1.0525676781255114e-06" iyz="-1.7994859376912648e-07" ixz="5.361526010575276e-08" />
    </inertial>
    <visual name="Leg5_Hip_actuator_assembly_Motor_visual">
      <origin xyz="-0.014088084835284037 -2.453592884421596e-15 -0.03421294999999989" rpy="-1.5707963267948961 -9.836221983250081e-17 1.5707963267948966" />
      <geometry>
        <mesh filename="meshes/urdf/Leg5_Hip-actuator-assembly_Motor.stl" scale="0.001 0.001 0.001" />
      </geometry>
    </visual>
    <collision name="Leg5_Hip_actuator_assembly_Motor_collision">
      <origin xyz="-0.014088084835284037 -2.453592884421596e-15 -0.03421294999999989" rpy="-1.5707963267948961 -9.836221983250081e-17 1.5707963267948966" />
      <geometry>
        <mesh filename="meshes/urdf/Leg5_Hip-actuator-assembly_Motor.stl" scale="0.001 0.001 0.001" />
      </geometry>
    </collision>
  </link>
  <link name="Leg5_Hip_actuator_assembly_Hip_Bracket">
    <inertial>
      <origin xyz="0.007563359926921698 -0.0012437881617802305 0.040945652067033225" rpy="8.940706509246467e-94 -0.0 0.0" />
      <mass value="0.05792781115933178" />
      <inertia ixx="0.00010067920230328285" iyy="9.858380629719499e-05" izz="5.2647464656367134e-05" ixy="-4.05441780977613e-06" iyz="1.4243321119439403e-06" ixz="1.5317549933663646e-05" />
    </inertial>
    <visual name="Leg5_Hip_actuator_assembly_Hip_Bracket_visual">
      <origin xyz="0.01724999999999992 0.040000000000002325 0.09499999516471626" rpy="-8.474826246020013e-31 -2.276008450758192e-16 -1.5707963267948963" />
      <geometry>
        <mesh filename="meshes/urdf/Leg5_Hip-actuator-assembly_Hip-Bracket.stl" scale="0.001 0.001 0.001" />
      </geometry>
    </visual>
    <collision name="Leg5_Hip_actuator_assembly_Hip_Bracket_collision">
      <origin xyz="0.01724999999999992 0.040000000000002325 0.09499999516471626" rpy="-8.474826246020013e-31 -2.276008450758192e-16 -1.5707963267948963" />
      <geometry>
        <mesh filename="meshes/urdf/Leg5_Hip-actuator-assembly_Hip-Bracket.stl" scale="0.001 0.001 0.001" />
      </geometry>
    </collision>
  </link>
  <link name="Leg5_Hip_actuator_assembly_Body_Bracket">
    <inertial>
      <origin xyz="-0.03480001266866786 0.004424738499856894 -0.029414785865833643" rpy="0.0 -0.0 0.0" />
      <mass value="0.2737560132535958" />
      <inertia ixx="0.00011826659575640136" iyy="0.00030785752435440183" izz="0.00020548953826173" ixy="-6.214987812586115e-11" iyz="9.185276276080614e-08" ixz="-3.8625346757831247e-10" />
    </inertial>
    <visual name="Leg5_Hip_actuator_assembly_Body_Bracket_visual">
      <origin xyz="-0.11727898724779606 -0.028621778093592735 0.017366123416015303" rpy="-3.141592653589793 1.570796326794896 0" />
      <geometry>
        <mesh filename="meshes/urdf/Leg5_Hip-actuator-assembly_Body-Bracket.stl" scale="0.001 0.001 0.001" />
      </geometry>
    </visual>
    <collision name="Leg5_Hip_actuator_assembly_Body_Bracket_collision">
      <origin xyz="-0.11727898724779606 -0.028621778093592735 0.017366123416015303" rpy="-3.141592653589793 1.570796326794896 0" />
      <geometry>
        <mesh filename="meshes/urdf/Leg5_Hip-actuator-assembly_Body-Bracket.stl" scale="0.001 0.001 0.001" />
      </geometry>
    </collision>
  </link>
  <link name="Leg5_Tibia_Leg">
    <inertial>
      <origin xyz="-0.10421987493399565 0.007011542435094187 -0.04719444569945438" rpy="1.5393511949224646e-95 -0.0 0.0" />
      <mass value="0.6725091028785471" />
      <inertia ixx="0.000488638776418665" iyy="0.004260036865887495" izz="0.003794440466203506" ixy="-7.025027001301065e-07" iyz="-3.0485813773406534e-07" ixz="-0.001132063397169013" />
    </inertial>
    <visual name="Leg5_Tibia_Leg_visual">
      <origin xyz="-0.08507464832369392 -0.03300000000000189 0.09829702159969024" rpy="-2.8797932657906435 3.122502256758242e-16 1.5707963267948963" />
      <geometry>
        <mesh filename="meshes/urdf/Leg5_Tibia_Leg.stl" scale="0.001 0.001 0.001" />
      </geometry>
    </visual>
    <collision name="Leg5_Tibia_Leg_collision">
      <origin xyz="-0.08507464832369392 -0.03300000000000189 0.09829702159969024" rpy="-2.8797932657906435 3.122502256758242e-16 1.5707963267948963" />
      <geometry>
        <mesh filename="meshes/urdf/Leg5_Tibia_Leg.stl" scale="0.001 0.001 0.001" />
      </geometry>
    </collision>
  </link>
  <link name="Leg5_Tibia_Foot">
    <inertial>
      <origin xyz="-0.004715990367889518 0.006000000023911101 -0.004338313579579918" rpy="0.0 -0.0 0.0" />
      <mass value="0.0012152855294447645" />
      <inertia ixx="2.837624446132064e-08" iyy="2.5730108277615023e-08" izz="2.6520716523156194e-08" ixy="-5.654453128001801e-17" iyz="1.1700574380101026e-16" ixz="1.0792250335493248e-08" />
    </inertial>
    <visual name="Leg5_Tibia_Foot_visual">
      <origin xyz="0.16677737167630655 0.046000000000003774 -0.1647695715996907" rpy="0.2617993877991527 -3.122502256758243e-16 -1.5707963267948963" />
      <geometry>
        <mesh filename="meshes/urdf/Leg5_Tibia_Foot.stl" scale="0.001 0.001 0.001" />
      </geometry>
    </visual>
    <collision name="Leg5_Tibia_Foot_collision">
      <origin xyz="0.16677737167630655 0.046000000000003774 -0.1647695715996907" rpy="0.2617993877991527 -3.122502256758243e-16 -1.5707963267948963" />
      <geometry>
        <mesh filename="meshes/urdf/Leg5_Tibia_Foot.stl" scale="0.001 0.001 0.001" />
      </geometry>
    </collision>
  </link>
  <link name="Leg5_Tibia_BadTouch">
    <inertial>
      <origin xyz="-0.014307431578915961 9.947598300641404e-16 -0.019468089080775356" rpy="0.0 -0.0 0.0" />
      <mass value="0.0028499001119515355" />
      <inertia ixx="6.698251338861476e-07" iyy="1.4563954103201274e-05" izz="1.3896028902723207e-05" ixy="-1.982952040766401e-20" iyz="1.365580369028401e-20" ixz="1.860464644030861e-06" />
    </inertial>
    <visual name="Leg5_Tibia_BadTouch_visual">
      <origin xyz="-0.001815227723034743 0.04003406004254127 -0.04030871839830553" rpy="3.261280134836379e-15 -6.192962809237184e-16 -1.5707963267948963" />
      <geometry>
        <mesh filename="meshes/urdf/Leg5_Tibia_BadTouch.stl" scale="0.001 0.001 0.001" />
      </geometry>
    </visual>
    <collision name="Leg5_Tibia_BadTouch_collision">
      <origin xyz="-0.001815227723034743 0.04003406004254127 -0.04030871839830553" rpy="3.261280134836379e-15 -6.192962809237184e-16 -1.5707963267948963" />
      <geometry>
        <mesh filename="meshes/urdf/Leg5_Tibia_BadTouch.stl" scale="0.001 0.001 0.001" />
      </geometry>
    </collision>
  </link>
  <link name="Leg6_Femur_actuator_assembly_Motor">
    <inertial>
      <origin xyz="-0.016829148946235523 -0.022158086706763475 -0.026876072559193675" rpy="0.0 -0.0 0.0" />
      <mass value="0.3028214126901055" />
      <inertia ixx="0.00014140196787329479" iyy="0.00022187592407092737" izz="0.0001480320632403724" ixy="9.311571849968119e-07" iyz="-2.8735500791635823e-05" ixz="-5.646113599949538e-07" />
    </inertial>
    <visual name="Leg6_Femur_actuator_assembly_Motor_visual">
      <origin xyz="-0.01701633000000024 -0.03527998769740444 -0.022600143668364367" rpy="1.6580627893946118 0.3316125578789227 1.570796326794897" />
      <geometry>
        <mesh filename="meshes/urdf/Leg6_Femur-actuator-assembly_Motor.stl" scale="0.001 0.001 0.001" />
      </geometry>
    </visual>
    <collision name="Leg6_Femur_actuator_assembly_Motor_collision">
      <origin xyz="-0.01701633000000024 -0.03527998769740444 -0.022600143668364367" rpy="1.6580627893946118 0.3316125578789227 1.570796326794897" />
      <geometry>
        <mesh filename="meshes/urdf/Leg6_Femur-actuator-assembly_Motor.stl" scale="0.001 0.001 0.001" />
      </geometry>
    </collision>
  </link>
  <link name="Leg6_Femur_actuator_assembly_Femur">
    <inertial>
      <origin xyz="0.03721165136172457 -0.011858797188077582 -0.004765925330613783" rpy="-1.232595164407831e-32 -7.703719777548943e-34 0.0" />
      <mass value="0.06743801039317165" />
      <inertia ixx="4.060590749385523e-05" iyy="0.00024407531981796027" izz="0.0002195486601846181" ixy="1.3631058459897197e-05" iyz="-1.017838274881441e-05" ixz="3.314093314333916e-05" />
    </inertial>
    <visual name="Leg6_Femur_actuator_assembly_Femur_visual">
      <origin xyz="-3.241851231905457e-16 0.027892797697404426 -0.009604256331635598" rpy="-0.7853981633974494 -0.33161255787892274 -1.570796326794897" />
      <geometry>
        <mesh filename="meshes/urdf/Leg6_Femur-actuator-assembly_Femur.stl" scale="0.001 0.001 0.001" />
      </geometry>
    </visual>
    <collision name="Leg6_Femur_actuator_assembly_Femur_collision">
      <origin xyz="-3.241851231905457e-16 0.027892797697404426 -0.009604256331635598" rpy="-0.7853981633974494 -0.33161255787892274 -1.570796326794897" />
      <geometry>
        <mesh filename="meshes/urdf/Leg6_Femur-actuator-assembly_Femur.stl" scale="0.001 0.001 0.001" />
      </geometry>
    </collision>
  </link>
  <link name="Leg6_Knee_actuator_assembly_Motor">
    <inertial>
      <origin xyz="-7.881548495362268e-05 0.011443333776846174 -0.004241836284530365" rpy="7.930496114303799e-34 -0.0 0.0" />
      <mass value="0.3028214126901055" />
      <inertia ixx="0.00013946533174021003" iyy="0.0002225931949784571" izz="0.00014925142846593936" ixy="-1.0354665568425186e-06" iyz="-2.7484017246802442e-05" ixz="-1.33767364814738e-06" />
    </inertial>
    <visual name="Leg6_Knee_actuator_assembly_Motor_visual">
      <origin xyz="-4.618527782440651e-16 0.02458348333594648 -0.00846476748433787" rpy="-2.4382249650360777 -0.33161255787892385 -1.5707963267948948" />
      <geometry>
        <mesh filename="meshes/urdf/Leg6_Knee-actuator-assembly_Motor.stl" scale="0.001 0.001 0.001" />
      </geometry>
    </visual>
    <collision name="Leg6_Knee_actuator_assembly_Motor_collision">
      <origin xyz="-4.618527782440651e-16 0.02458348333594648 -0.00846476748433787" rpy="-2.4382249650360777 -0.33161255787892385 -1.5707963267948948" />
      <geometry>
        <mesh filename="meshes/urdf/Leg6_Knee-actuator-assembly_Motor.stl" scale="0.001 0.001 0.001" />
      </geometry>
    </collision>
  </link>
  <link name="Leg6_Knee_actuator_assembly_KneeMotorPulley">
    <inertial>
      <origin xyz="9.565681580170348e-15 0.005762274030233528 -0.0019841115370166306" rpy="3.9651029235834504e-50 6.162975822039155e-33 0.0" />
      <mass value="0.08135375942547957" />
      <inertia ixx="7.261200035935457e-06" iyy="1.1911322759121379e-05" izz="7.812525585173744e-06" ixy="-5.626949881628045e-17" iyz="-1.6011656589799696e-06" ixz="-1.581847926200332e-16" />
    </inertial>
    <visual name="Leg6_Knee_actuator_assembly_KneeMotorPulley_visual">
      <origin xyz="0.012448362893745827 -0.0009794554475385552 -0.03816742682263801" rpy="0.8674286382411807 -0.33161255787892374 -1.570796326794898" />
      <geometry>
        <mesh filename="meshes/urdf/Leg6_Knee-actuator-assembly_KneeMotorPulley.stl" scale="0.001 0.001 0.001" />
      </geometry>
    </visual>
    <collision name="Leg6_Knee_actuator_assembly_KneeMotorPulley_collision">
      <origin xyz="0.012448362893745827 -0.0009794554475385552 -0.03816742682263801" rpy="0.8674286382411807 -0.33161255787892374 -1.570796326794898" />
      <geometry>
        <mesh filename="meshes/urdf/Leg6_Knee-actuator-assembly_KneeMotorPulley.stl" scale="0.001 0.001 0.001" />
      </geometry>
    </collision>
  </link>
  <link name="Leg6_Knee_actuator_assembly_Knee_motor_bearings">
    <inertial>
      <origin xyz="-0.03290840372194123 0.007261888544417747 0.015386675046216568" rpy="3.0814879110195774e-33 -6.162975822039155e-33 0.0" />
      <mass value="0.009270686219329867" />
      <inertia ixx="6.408471849646224e-06" iyy="1.207832197916165e-05" izz="7.08069781563223e-06" ixy="7.924251801353123e-18" iyz="-1.952285962823731e-06" ixz="2.22665556419423e-17" />
    </inertial>
    <visual name="Leg6_Knee_actuator_assembly_Knee_motor_bearings_visual">
      <origin xyz="-0.048895819689534714 -0.09407149852899709 0.09214226543605585" rpy="-0.726035765771591 -1.1203572383394995 2.349230407128448" />
      <geometry>
        <mesh filename="meshes/urdf/Leg6_Knee-actuator-assembly_Knee-motor-bearings.stl" scale="0.001 0.001 0.001" />
      </geometry>
    </visual>
    <collision name="Leg6_Knee_actuator_assembly_Knee_motor_bearings_collision">
      <origin xyz="-0.048895819689534714 -0.09407149852899709 0.09214226543605585" rpy="-0.726035765771591 -1.1203572383394995 2.349230407128448" />
      <geometry>
        <mesh filename="meshes/urdf/Leg6_Knee-actuator-assembly_Knee-motor-bearings.stl" scale="0.001 0.001 0.001" />
      </geometry>
    </collision>
  </link>
  <link name="Leg6_Knee_actuator_assembly_End_Bearing_Holder">
    <inertial>
      <origin xyz="0.033909579184540344 0.004667995898851878 0.024599749359103952" rpy="0.0 -0.0 0.0" />
      <mass value="0.057169625310268736" />
      <inertia ixx="5.1347634596556085e-05" iyy="9.742723908222865e-05" izz="5.734491823150244e-05" ixy="-3.1402249696382974e-07" iyz="-1.5644128058736786e-05" ixz="-9.479608215885817e-07" />
    </inertial>
    <visual name="Leg6_Knee_actuator_assembly_End_Bearing_Holder_visual">
      <origin xyz="0.032801111906407464 0.10715418722903997 -0.0541473724773352" rpy="3.141592653589789 1.239183768915973 -1.5707963267949012" />
      <geometry>
        <mesh filename="meshes/urdf/Leg6_Knee-actuator-assembly_End-Bearing-Holder.stl" scale="0.001 0.001 0.001" />
      </geometry>
    </visual>
    <collision name="Leg6_Knee_actuator_assembly_End_Bearing_Holder_collision">
      <origin xyz="0.032801111906407464 0.10715418722903997 -0.0541473724773352" rpy="3.141592653589789 1.239183768915973 -1.5707963267949012" />
      <geometry>
        <mesh filename="meshes/urdf/Leg6_Knee-actuator-assembly_End-Bearing-Holder.stl" scale="0.001 0.001 0.001" />
      </geometry>
    </collision>
  </link>
  <link name="Leg6_Hip_actuator_assembly_Motor">
    <inertial>
      <origin xyz="-0.014254585975711756 0.013799107411400962 -0.034457494992359956" rpy="0.0 7.382803922328222e-64 0.0" />
      <mass value="0.3028214126901055" />
      <inertia ixx="0.00014141746037829583" iyy="0.0002317402126784246" izz="0.00013815228212787564" ixy="-1.052567678124644e-06" iyz="-1.7994859376896385e-07" ixz="5.361526010315068e-08" />
    </inertial>
    <visual name="Leg6_Hip_actuator_assembly_Motor_visual">
      <origin xyz="-0.014088084835284 -2.453592884421596e-15 -0.0342129499999999" rpy="-1.5707963267948961 -9.836221983250081e-17 1.5707963267948966" />
      <geometry>
        <mesh filename="meshes/urdf/Leg6_Hip-actuator-assembly_Motor.stl" scale="0.001 0.001 0.001" />
      </geometry>
    </visual>
    <collision name="Leg6_Hip_actuator_assembly_Motor_collision">
      <origin xyz="-0.014088084835284 -2.453592884421596e-15 -0.0342129499999999" rpy="-1.5707963267948961 -9.836221983250081e-17 1.5707963267948966" />
      <geometry>
        <mesh filename="meshes/urdf/Leg6_Hip-actuator-assembly_Motor.stl" scale="0.001 0.001 0.001" />
      </geometry>
    </collision>
  </link>
  <link name="Leg6_Hip_actuator_assembly_Hip_Bracket">
    <inertial>
      <origin xyz="0.007563359926921658 0.01215457713964975 0.03911981217233976" rpy="8.940706509246467e-94 -0.0 0.0" />
      <mass value="0.05792781115933178" />
      <inertia ixx="0.00010067920230328285" iyy="9.459170748333558e-05" izz="5.663956347022581e-05" ixy="1.1533791103241261e-06" iyz="-1.3018228911908146e-05" ixz="1.5803017318676005e-05" />
    </inertial>
    <visual name="Leg6_Hip_actuator_assembly_Hip_Bracket_visual">
      <origin xyz="0.017249999999999887 0.06874971769740501 0.07680153366836433" rpy="-9.085365707636397e-31 -0.33161255787892296 -1.5707963267948963" />
      <geometry>
        <mesh filename="meshes/urdf/Leg6_Hip-actuator-assembly_Hip-Bracket.stl" scale="0.001 0.001 0.001" />
      </geometry>
    </visual>
    <collision name="Leg6_Hip_actuator_assembly_Hip_Bracket_collision">
      <origin xyz="0.017249999999999887 0.06874971769740501 0.07680153366836433" rpy="-9.085365707636397e-31 -0.33161255787892296 -1.5707963267948963" />
      <geometry>
        <mesh filename="meshes/urdf/Leg6_Hip-actuator-assembly_Hip-Bracket.stl" scale="0.001 0.001 0.001" />
      </geometry>
    </collision>
  </link>
  <link name="Leg6_Hip_actuator_assembly_Body_Bracket">
    <inertial>
      <origin xyz="-0.03480001266866793 0.004424738499856894 -0.02941478586583365" rpy="0.0 -0.0 0.0" />
      <mass value="0.2737560132535958" />
      <inertia ixx="0.00011826659575640049" iyy="0.0003078575243544088" izz="0.00020548953826174735" ixy="-6.214987812586115e-11" iyz="9.185276276079258e-08" ixz="-3.8625346671095073e-10" />
    </inertial>
    <visual name="Leg6_Hip_actuator_assembly_Body_Bracket_visual">
      <origin xyz="-0.11727898724779603 -0.028621778093592735 0.017366123416015285" rpy="-3.141592653589793 1.570796326794896 0" />
      <geometry>
        <mesh filename="meshes/urdf/Leg6_Hip-actuator-assembly_Body-Bracket.stl" scale="0.001 0.001 0.001" />
      </geometry>
    </visual>
    <collision name="Leg6_Hip_actuator_assembly_Body_Bracket_collision">
      <origin xyz="-0.11727898724779603 -0.028621778093592735 0.017366123416015285" rpy="-3.141592653589793 1.570796326794896 0" />
      <geometry>
        <mesh filename="meshes/urdf/Leg6_Hip-actuator-assembly_Body-Bracket.stl" scale="0.001 0.001 0.001" />
      </geometry>
    </collision>
  </link>
  <link name="Leg6_Tibia_Leg">
    <inertial>
      <origin xyz="-0.10421987493399563 -0.00873546738642558 -0.046905962951758584" rpy="7.930496114303799e-34 -0.0 0.0" />
      <mass value="0.6725091028785471" />
      <inertia ixx="0.0004886387764186928" iyy="0.004210498461530474" izz="0.003843978870560566" ixy="-0.0003692280202971982" iyz="-0.00014356511465872534" ixz="-0.0010701582582717858" />
    </inertial>
    <visual name="Leg6_Tibia_Leg_visual">
      <origin xyz="-0.08507464832369398 0.000800264500657022 0.10368540599836198" rpy="-2.8797932657906444 0.3316125578789229 1.5707963267948968" />
      <geometry>
        <mesh filename="meshes/urdf/Leg6_Tibia_Leg.stl" scale="0.001 0.001 0.001" />
      </geometry>
    </visual>
    <collision name="Leg6_Tibia_Leg_collision">
      <origin xyz="-0.08507464832369398 0.000800264500657022 0.10368540599836198" rpy="-2.8797932657906444 0.3316125578789229 1.5707963267948968" />
      <geometry>
        <mesh filename="meshes/urdf/Leg6_Tibia_Leg.stl" scale="0.001 0.001 0.001" />
      </geometry>
    </collision>
  </link>
  <link name="Leg6_Tibia_Foot">
    <inertial>
      <origin xyz="-0.004715990367889554 0.004260701088824313 -0.006055365263078727" rpy="-2.8821009713633173e-33 -0.0 0.0" />
      <mass value="0.0012152855294447645" />
      <inertia ixx="2.8376244461212206e-08" iyy="2.581390857260599e-08" izz="2.643691622804662e-08" ixy="3.513612970699634e-09" iyz="2.433736116553176e-10" ixz="1.0204273183148065e-08" />
    </inertial>
    <visual name="Leg6_Tibia_Foot_visual">
      <origin xyz="0.16677737167630682 -0.010149864500655106 -0.17076882599836285" rpy="0.26179938779915446 -0.33161255787892285 -1.5707963267948963" />
      <geometry>
        <mesh filename="meshes/urdf/Leg6_Tibia_Foot.stl" scale="0.001 0.001 0.001" />
      </geometry>
    </visual>
    <collision name="Leg6_Tibia_Foot_collision">
      <origin xyz="0.16677737167630682 -0.010149864500655106 -0.17076882599836285" rpy="0.26179938779915446 -0.33161255787892285 -1.5707963267948963" />
      <geometry>
        <mesh filename="meshes/urdf/Leg6_Tibia_Foot.stl" scale="0.001 0.001 0.001" />
      </geometry>
    </collision>
  </link>
  <link name="Leg6_Tibia_BadTouch">
    <inertial>
      <origin xyz="-0.014307431578915905 -0.006338194708691951 -0.018407441874418992" rpy="-2.8821009713633173e-33 -0.0 0.0" />
      <mass value="0.0028499001119515355" />
      <inertia ixx="6.698251338862556e-07" iyy="1.4493157623253173e-05" izz="1.3966825382671422e-05" ixy="6.057080405898926e-07" iyz="-2.0560790716685406e-07" ixz="1.7591038801769517e-06" />
    </inertial>
    <visual name="Leg6_Tibia_BadTouch_visual">
      <origin xyz="-0.0018152277230346603 0.02472970749355426 -0.05114645906480028" rpy="5.2142883649193785e-15 -0.331612557878923 -1.5707963267948961" />
      <geometry>
        <mesh filename="meshes/urdf/Leg6_Tibia_BadTouch.stl" scale="0.001 0.001 0.001" />
      </geometry>
    </visual>
    <collision name="Leg6_Tibia_BadTouch_collision">
      <origin xyz="-0.0018152277230346603 0.02472970749355426 -0.05114645906480028" rpy="5.2142883649193785e-15 -0.331612557878923 -1.5707963267948961" />
      <geometry>
        <mesh filename="meshes/urdf/Leg6_Tibia_BadTouch.stl" scale="0.001 0.001 0.001" />
      </geometry>
    </collision>
  </link>
  <link name="Leg7_Femur_actuator_assembly_Motor">
    <inertial>
      <origin xyz="-0.016829148946235672 0.0003064096123075544 0.03483117054921049" rpy="0.0 -0.0 0.0" />
      <mass value="0.3028214126901055" />
      <inertia ixx="0.00014140196787329126" iyy="0.00022073805579178032" izz="0.00014916993151953446" ixy="-1.0789664876655666e-06" iyz="3.0140651094091083e-05" ixz="-1.472107655782129e-07" />
    </inertial>
    <visual name="Leg7_Femur_actuator_assembly_Motor_visual">
      <origin xyz="-0.017016330000000388 0.013194971215500307 0.03976602954297274" rpy="-1.48352986419518 0.3490658503988658 -1.5707963267948968" />
      <geometry>
        <mesh filename="meshes/urdf/Leg7_Femur-actuator-assembly_Motor.stl" scale="0.001 0.001 0.001" />
      </geometry>
    </visual>
    <collision name="Leg7_Femur_actuator_assembly_Motor_collision">
      <origin xyz="-0.017016330000000388 0.013194971215500307 0.03976602954297274" rpy="-1.48352986419518 0.3490658503988658 -1.5707963267948968" />
      <geometry>
        <mesh filename="meshes/urdf/Leg7_Femur-actuator-assembly_Motor.stl" scale="0.001 0.001 0.001" />
      </geometry>
    </collision>
  </link>
  <link name="Leg7_Femur_actuator_assembly_Femur">
    <inertial>
      <origin xyz="0.037211651361724385 0.006216720568817405 0.011166810297576912" rpy="-9.208246890614371e-35 -0.0 0.0" />
      <mass value="0.06743801039317165" />
      <inertia ixx="4.0605907493853916e-05" iyy="0.00024431764030362953" izz="0.0002193063396989452" ixy="1.026294297302963e-05" iyz="9.879141870086925e-06" ixz="-3.4333645391666763e-05" />
    </inertial>
    <visual name="Leg7_Femur_actuator_assembly_Femur_visual">
      <origin xyz="-5.329070518200751e-16 -0.027720931215499983 -0.010089589542973024" rpy="2.3561944901923453 -0.34906585039886584 1.5707963267948968" />
      <geometry>
        <mesh filename="meshes/urdf/Leg7_Femur-actuator-assembly_Femur.stl" scale="0.001 0.001 0.001" />
      </geometry>
    </visual>
    <collision name="Leg7_Femur_actuator_assembly_Femur_collision">
      <origin xyz="-5.329070518200751e-16 -0.027720931215499983 -0.010089589542973024" rpy="2.3561944901923453 -0.34906585039886584 1.5707963267948968" />
      <geometry>
        <mesh filename="meshes/urdf/Leg7_Femur-actuator-assembly_Femur.stl" scale="0.001 0.001 0.001" />
      </geometry>
    </collision>
  </link>
  <link name="Leg7_Knee_actuator_assembly_Motor">
    <inertial>
      <origin xyz="-7.881548495371593e-05 -0.011562613397790855 -0.0039049912898965647" rpy="5.460121358702692e-67 -0.0 0.0" />
      <mass value="0.3028214126901055" />
      <inertia ixx="0.00013946533174021697" iyy="0.00022043004259226975" izz="0.00015141458085212584" ixy="-3.7116650475127695e-08" iyz="3.015528797765261e-05" ixz="1.6912078918754333e-06" />
    </inertial>
    <visual name="Leg7_Knee_actuator_assembly_Motor_visual">
      <origin xyz="-5.506706202140776e-16 -0.02443200427462571 -0.008892521421441889" rpy="0.7033676885537155 -0.3490658503988646 1.570796326794895" />
      <geometry>
        <mesh filename="meshes/urdf/Leg7_Knee-actuator-assembly_Motor.stl" scale="0.001 0.001 0.001" />
      </geometry>
    </visual>
    <collision name="Leg7_Knee_actuator_assembly_Motor_collision">
      <origin xyz="-5.506706202140776e-16 -0.02443200427462571 -0.008892521421441889" rpy="0.7033676885537155 -0.3490658503988646 1.570796326794895" />
      <geometry>
        <mesh filename="meshes/urdf/Leg7_Knee-actuator-assembly_Motor.stl" scale="0.001 0.001 0.001" />
      </geometry>
    </collision>
  </link>
  <link name="Leg7_Knee_actuator_assembly_KneeMotorPulley">
    <inertial>
      <origin xyz="9.414691248821327e-15 -0.00572676233571217 -0.0020843745494323685" rpy="1.561884880754821e-33 -0.0 0.0" />
      <mass value="0.08135375942547957" />
      <inertia ixx="7.261200035934591e-06" iyy="1.185419444523373e-05" izz="7.869653899061606e-06" ixy="-5.583671388143134e-17" iyz="1.6717132513581132e-06" ixz="1.5813020884387914e-16" />
    </inertial>
    <visual name="Leg7_Knee_actuator_assembly_KneeMotorPulley_visual">
      <origin xyz="0.012448362893745719 -0.023258352623852972 0.03027805062821626" rpy="-2.274164015348612 -0.3490658503988648 1.5707963267948981" />
      <geometry>
        <mesh filename="meshes/urdf/Leg7_Knee-actuator-assembly_KneeMotorPulley.stl" scale="0.001 0.001 0.001" />
      </geometry>
    </visual>
    <collision name="Leg7_Knee_actuator_assembly_KneeMotorPulley_collision">
      <origin xyz="0.012448362893745719 -0.023258352623852972 0.03027805062821626" rpy="-2.274164015348612 -0.3490658503988648 1.5707963267948981" />
      <geometry>
        <mesh filename="meshes/urdf/Leg7_Knee-actuator-assembly_KneeMotorPulley.stl" scale="0.001 0.001 0.001" />
      </geometry>
    </collision>
  </link>
  <link name="Leg7_Knee_actuator_assembly_Knee_motor_bearings">
    <inertial>
      <origin xyz="-0.032908403721941266 0.0040395924521696 -0.016527749796203237" rpy="1.5618848807548207e-33 -0.0 0.0" />
      <mass value="0.009270686219329867" />
      <inertia ixx="6.4084718496459e-06" iyy="1.2008665972834304e-05" izz="7.150353821958964e-06" ixy="7.874386501468582e-18" iyz="2.0383039669719227e-06" ixz="-2.2279719242300872e-17" />
    </inertial>
    <visual name="Leg7_Knee_actuator_assembly_Knee_motor_bearings_visual">
      <origin xyz="-0.04889581968953469 0.1310942831364247 -0.012406880107466432" rpy="0.698595883447016 1.1077791797796959 2.3246023184988633" />
      <geometry>
        <mesh filename="meshes/urdf/Leg7_Knee-actuator-assembly_Knee-motor-bearings.stl" scale="0.001 0.001 0.001" />
      </geometry>
    </visual>
    <collision name="Leg7_Knee_actuator_assembly_Knee_motor_bearings_collision">
      <origin xyz="-0.04889581968953469 0.1310942831364247 -0.012406880107466432" rpy="0.698595883447016 1.1077791797796959 2.3246023184988633" />
      <geometry>
        <mesh filename="meshes/urdf/Leg7_Knee-actuator-assembly_Knee-motor-bearings.stl" scale="0.001 0.001 0.001" />
      </geometry>
    </collision>
  </link>
  <link name="Leg7_Knee_actuator_assembly_End_Bearing_Holder">
    <inertial>
      <origin xyz="0.03390957918454021 0.011853406889750923 -0.022055263218043936" rpy="0.0 -0.0 0.0" />
      <mass value="0.057169625310268736" />
      <inertia ixx="5.134763459656126e-05" iyy="9.68551365330767e-05" izz="5.791702078065085e-05" ixy="-3.5252975961991935e-07" iyz="1.63506158699265e-05" ixz="9.343246847047045e-07" />
    </inertial>
    <visual name="Leg7_Knee_actuator_assembly_End_Bearing_Holder_visual">
      <origin xyz="0.03280111190640737 -0.11735049231576787 -0.025353905511617612" rpy="3.141592653589793 -1.2217304763960313 -1.5707963267948963" />
      <geometry>
        <mesh filename="meshes/urdf/Leg7_Knee-actuator-assembly_End-Bearing-Holder.stl" scale="0.001 0.001 0.001" />
      </geometry>
    </visual>
    <collision name="Leg7_Knee_actuator_assembly_End_Bearing_Holder_collision">
      <origin xyz="0.03280111190640737 -0.11735049231576787 -0.025353905511617612" rpy="3.141592653589793 -1.2217304763960313 -1.5707963267948963" />
      <geometry>
        <mesh filename="meshes/urdf/Leg7_Knee-actuator-assembly_End-Bearing-Holder.stl" scale="0.001 0.001 0.001" />
      </geometry>
    </collision>
  </link>
  <link name="Leg7_Hip_actuator_assembly_Motor">
    <inertial>
      <origin xyz="-0.014254585975711791 0.013799107411400962 -0.034457494992359956" rpy="0.0 7.382803922328222e-64 0.0" />
      <mass value="0.3028214126901055" />
      <inertia ixx="0.00014141746037829583" iyy="0.0002317402126784298" izz="0.00013815228212788258" ixy="-1.0525676781252945e-06" iyz="-1.7994859376896385e-07" ixz="5.361526010575276e-08" />
    </inertial>
    <visual name="Leg7_Hip_actuator_assembly_Motor_visual">
      <origin xyz="-0.014088084835284 -2.453592884421596e-15 -0.0342129499999999" rpy="-1.5707963267948961 -9.836221983250081e-17 1.5707963267948966" />
      <geometry>
        <mesh filename="meshes/urdf/Leg7_Hip-actuator-assembly_Motor.stl" scale="0.001 0.001 0.001" />
      </geometry>
    </visual>
    <collision name="Leg7_Hip_actuator_assembly_Motor_collision">
      <origin xyz="-0.014088084835284 -2.453592884421596e-15 -0.0342129499999999" rpy="-1.5707963267948961 -9.836221983250081e-17 1.5707963267948966" />
      <geometry>
        <mesh filename="meshes/urdf/Leg7_Hip-actuator-assembly_Motor.stl" scale="0.001 0.001 0.001" />
      </geometry>
    </collision>
  </link>
  <link name="Leg7_Hip_actuator_assembly_Hip_Bracket">
    <inertial>
      <origin xyz="0.007563359926921671 0.01517301799973966 -0.03805093587426427" rpy="8.940706509246467e-94 -0.0 0.0" />
      <mass value="0.05792781115933178" />
      <inertia ixx="0.00010067920230328199" iyy="9.22947320687287e-05" izz="5.893653888483161e-05" ixy="9.048817121139252e-06" iyz="1.585475732003572e-05" ixz="-1.3007096080781614e-05" />
    </inertial>
    <visual name="Leg7_Hip_actuator_assembly_Hip_Bracket_visual">
      <origin xyz="0.017249999999999908 -0.0050957912155001495 -0.10295160954297312" rpy="-3.141592653589793 -0.34906585039886573 1.5707963267948968" />
      <geometry>
        <mesh filename="meshes/urdf/Leg7_Hip-actuator-assembly_Hip-Bracket.stl" scale="0.001 0.001 0.001" />
      </geometry>
    </visual>
    <collision name="Leg7_Hip_actuator_assembly_Hip_Bracket_collision">
      <origin xyz="0.017249999999999908 -0.0050957912155001495 -0.10295160954297312" rpy="-3.141592653589793 -0.34906585039886573 1.5707963267948968" />
      <geometry>
        <mesh filename="meshes/urdf/Leg7_Hip-actuator-assembly_Hip-Bracket.stl" scale="0.001 0.001 0.001" />
      </geometry>
    </collision>
  </link>
  <link name="Leg7_Hip_actuator_assembly_Body_Bracket">
    <inertial>
      <origin xyz="-0.03480001266866786 0.004424738499856894 -0.02941478586583365" rpy="0.0 -0.0 0.0" />
      <mass value="0.2737560132535958" />
      <inertia ixx="0.00011826659575640049" iyy="0.0003078575243544053" izz="0.0002054895382617404" ixy="-6.214987809875609e-11" iyz="9.185276276079258e-08" ixz="-3.862534684456742e-10" />
    </inertial>
    <visual name="Leg7_Hip_actuator_assembly_Body_Bracket_visual">
      <origin xyz="-0.11727898724779603 -0.028621778093592735 0.017366123416015285" rpy="-3.141592653589793 1.570796326794896 0" />
      <geometry>
        <mesh filename="meshes/urdf/Leg7_Hip-actuator-assembly_Body-Bracket.stl" scale="0.001 0.001 0.001" />
      </geometry>
    </visual>
    <collision name="Leg7_Hip_actuator_assembly_Body_Bracket_collision">
      <origin xyz="-0.11727898724779603 -0.028621778093592735 0.017366123416015285" rpy="-3.141592653589793 1.570796326794896 0" />
      <geometry>
        <mesh filename="meshes/urdf/Leg7_Hip-actuator-assembly_Body-Bracket.stl" scale="0.001 0.001 0.001" />
      </geometry>
    </collision>
  </link>
  <link name="Leg7_Tibia_Leg">
    <inertial>
      <origin xyz="-0.10421987493399568 -0.022730149109947924 0.041950187454531884" rpy="5.4601213587026905e-67 -0.0 0.0" />
      <mass value="0.6725091028785471" />
      <inertia ixx="0.0004886387764186512" iyy="0.004205768392436075" izz="0.0038487089396547595" ixy="-0.0003865283487500957" iyz="0.00014940626353335628" ixz="0.0010640318906557328" />
    </inertial>
    <visual name="Leg7_Tibia_Leg_visual">
      <origin xyz="-0.08507464832369394 0.06462941456088953 -0.0810823172754561" rpy="0.2617993877991497 0.3490658503988656 -1.5707963267948966" />
      <geometry>
        <mesh filename="meshes/urdf/Leg7_Tibia_Leg.stl" scale="0.001 0.001 0.001" />
      </geometry>
    </visual>
    <collision name="Leg7_Tibia_Leg_collision">
      <origin xyz="-0.08507464832369394 0.06462941456088953 -0.0810823172754561" rpy="0.2617993877991497 0.3490658503988656 -1.5707963267948966" />
      <geometry>
        <mesh filename="meshes/urdf/Leg7_Tibia_Leg.stl" scale="0.001 0.001 0.001" />
      </geometry>
    </collision>
  </link>
  <link name="Leg7_Tibia_Foot">
    <inertial>
      <origin xyz="-0.004715990367889642 -0.007121947889962748 0.002024553695408491" rpy="1.917909130679587e-66 -0.0 -2.1382117680737565e-50" />
      <mass value="0.0012152855294447645" />
      <inertia ixx="2.8376244461293535e-08" iyy="2.5822591798500637e-08" izz="2.6428233002162152e-08" ixy="3.691167059678024e-09" iyz="-2.540965025803829e-10" ixz="-1.0141397982574573e-08" />
    </inertial>
    <visual name="Leg7_Tibia_Foot_visual">
      <origin xyz="0.16677737167630657 -0.09958037456088908 0.13909981727545673" rpy="-2.8797932657906404 -0.3490658503988656 1.5707963267948968" />
      <geometry>
        <mesh filename="meshes/urdf/Leg7_Tibia_Foot.stl" scale="0.001 0.001 0.001" />
      </geometry>
    </visual>
    <collision name="Leg7_Tibia_Foot_collision">
      <origin xyz="0.16677737167630657 -0.09958037456088908 0.13909981727545673" rpy="-2.8797932657906404 -0.3490658503988656 1.5707963267948968" />
      <geometry>
        <mesh filename="meshes/urdf/Leg7_Tibia_Foot.stl" scale="0.001 0.001 0.001" />
      </geometry>
    </collision>
  </link>
  <link name="Leg7_Tibia_BadTouch">
    <inertial>
      <origin xyz="-0.014307431578916056 -0.006658475228877059 0.018294017729671704" rpy="0.0 -0.0 0.0" />
      <mass value="0.0028499001119515355" />
      <inertia ixx="6.698251338861476e-07" iyy="1.4485821697084927e-05" izz="1.3974161308839531e-05" ixy="6.363163842037871e-07" iyz="2.146670215323631e-07" ixz="-1.7482648972288733e-06" />
    </inertial>
    <visual name="Leg7_Tibia_BadTouch_visual">
      <origin xyz="-0.001815227723034819 -0.051406101057130976 0.024185348358231242" rpy="-3.1415926535897896 -0.34906585039886595 1.5707963267948968" />
      <geometry>
        <mesh filename="meshes/urdf/Leg7_Tibia_BadTouch.stl" scale="0.001 0.001 0.001" />
      </geometry>
    </visual>
    <collision name="Leg7_Tibia_BadTouch_collision">
      <origin xyz="-0.001815227723034819 -0.051406101057130976 0.024185348358231242" rpy="-3.1415926535897896 -0.34906585039886595 1.5707963267948968" />
      <geometry>
        <mesh filename="meshes/urdf/Leg7_Tibia_BadTouch.stl" scale="0.001 0.001 0.001" />
      </geometry>
    </collision>
  </link>
  <link name="Leg8_Femur_actuator_assembly_Motor">
    <inertial>
      <origin xyz="-0.01682914894623565 0.012200892588599337 0.032625801941012424" rpy="0.0 -0.0 0.0" />
      <mass value="0.3028214126901055" />
      <inertia ixx="0.00014140196787328974" iyy="0.00023174021267842503" izz="0.0001381677746328884" ixy="-1.06424589367676e-06" iyz="8.752651726269198e-08" ixz="2.3069540264067986e-07" />
    </inertial>
    <visual name="Leg8_Femur_actuator_assembly_Motor_visual">
      <origin xyz="-0.017016330000000374 0.0260000000000027 0.03285490483528409" rpy="-1.48352986419518 -1.1102230246251538e-16 -1.5707963267948968" />
      <geometry>
        <mesh filename="meshes/urdf/Leg8_Femur-actuator-assembly_Motor.stl" scale="0.001 0.001 0.001" />
      </geometry>
    </visual>
    <collision name="Leg8_Femur_actuator_assembly_Motor_collision">
      <origin xyz="-0.017016330000000374 0.0260000000000027 0.03285490483528409" rpy="-1.48352986419518 -1.1102230246251538e-16 -1.5707963267948968" />
      <geometry>
        <mesh filename="meshes/urdf/Leg8_Femur-actuator-assembly_Motor.stl" scale="0.001 0.001 0.001" />
      </geometry>
    </collision>
  </link>
  <link name="Leg8_Femur_actuator_assembly_Femur">
    <inertial>
      <origin xyz="0.03721165136172445 0.009661077868574664 0.00836711671194669" rpy="0.0 -0.0 0.0" />
      <mass value="0.06743801039317165" />
      <inertia ixx="4.060590749385385e-05" iyy="0.0002477420639114126" izz="0.0002158819160911613" ixy="-2.0987865384480887e-06" iyz="-4.706153330536322e-07" ixz="-3.57732064458082e-05" />
    </inertial>
    <visual name="Leg8_Femur_actuator_assembly_Femur_visual">
      <origin xyz="-4.707345624410664e-16 -0.02950000000000271 -4.83528398653732e-09" rpy="2.3561944901923453 8.882296699767486e-17 1.5707963267948968" />
      <geometry>
        <mesh filename="meshes/urdf/Leg8_Femur-actuator-assembly_Femur.stl" scale="0.001 0.001 0.001" />
      </geometry>
    </visual>
    <collision name="Leg8_Femur_actuator_assembly_Femur_collision">
      <origin xyz="-4.707345624410664e-16 -0.02950000000000271 -4.83528398653732e-09" rpy="2.3561944901923453 8.882296699767486e-17 1.5707963267948968" />
      <geometry>
        <mesh filename="meshes/urdf/Leg8_Femur-actuator-assembly_Femur.stl" scale="0.001 0.001 0.001" />
      </geometry>
    </collision>
  </link>
  <link name="Leg8_Knee_actuator_assembly_Motor">
    <inertial>
      <origin xyz="-7.88154849537337e-05 -0.012200892588597752 0.0002851591836354839" rpy="6.413963312176937e-97 -0.0 0.0" />
      <mass value="0.3028214126901055" />
      <inertia ixx="0.00013946533174021263" iyy="0.0002317402126784259" izz="0.00014010441076596622" ixy="5.435489230132566e-07" iyz="9.191489442538989e-07" ixz="1.601910218325571e-06" />
    </inertial>
    <visual name="Leg8_Knee_actuator_assembly_Motor_visual">
      <origin xyz="-5.684341886080802e-16 -0.02600000000000115 4.835284084236946e-09" rpy="0.7033676885537148 1.2212453270876665e-15 1.5707963267948952" />
      <geometry>
        <mesh filename="meshes/urdf/Leg8_Knee-actuator-assembly_Motor.stl" scale="0.001 0.001 0.001" />
      </geometry>
    </visual>
    <collision name="Leg8_Knee_actuator_assembly_Motor_collision">
      <origin xyz="-5.684341886080802e-16 -0.02600000000000115 4.835284084236946e-09" rpy="0.7033676885537148 1.2212453270876665e-15 1.5707963267948952" />
      <geometry>
        <mesh filename="meshes/urdf/Leg8_Knee-actuator-assembly_Motor.stl" scale="0.001 0.001 0.001" />
      </geometry>
    </collision>
  </link>
  <link name="Leg8_Knee_actuator_assembly_KneeMotorPulley">
    <inertial>
      <origin xyz="9.494627306594338e-15 -0.006094295273219217 -4.8352322146172355e-09" rpy="-8.325733098859881e-78 -0.0 0.0" />
      <mass value="0.08135375942547957" />
      <inertia ixx="7.261200035934157e-06" iyy="1.246264830895809e-05" izz="7.261200035337196e-06" ixy="1.6676526561514658e-18" iyz="4.987878569701057e-18" ixz="1.6772607608350754e-16" />
    </inertial>
    <visual name="Leg8_Knee_actuator_assembly_KneeMotorPulley_visual">
      <origin xyz="0.012448362893745797 -0.011500000000001415 0.03640688431801707" rpy="-2.2741640153486116 1.0325125379290565e-15 1.570796326794898" />
      <geometry>
        <mesh filename="meshes/urdf/Leg8_Knee-actuator-assembly_KneeMotorPulley.stl" scale="0.001 0.001 0.001" />
      </geometry>
    </visual>
    <collision name="Leg8_Knee_actuator_assembly_KneeMotorPulley_collision">
      <origin xyz="0.012448362893745797 -0.011500000000001415 0.03640688431801707" rpy="-2.2741640153486116 1.0325125379290565e-15 1.570796326794898" />
      <geometry>
        <mesh filename="meshes/urdf/Leg8_Knee-actuator-assembly_KneeMotorPulley.stl" scale="0.001 0.001 0.001" />
      </geometry>
    </collision>
  </link>
  <link name="Leg8_Knee_actuator_assembly_Knee_motor_bearings">
    <inertial>
      <origin xyz="-0.032908403721941294 -0.0018568433438266574 -0.016912625908410524" rpy="1.9497390676637634e-78 -0.0 0.0" />
      <mass value="0.009270686219329867" />
      <inertia ixx="6.4084718496459545e-06" iyy="1.2750547945198802e-05" izz="6.4084718495942245e-06" ixy="-2.277126274594204e-19" iyz="7.4379371242413e-20" ixz="-2.3686429337019255e-17" />
    </inertial>
    <visual name="Leg8_Knee_actuator_assembly_Knee_motor_bearings_visual">
      <origin xyz="-0.04889581968953472 0.11894493236997206 -0.05649553858871161" rpy="1.5707963267948992 1.2601277199399066 -3.141592653589789" />
      <geometry>
        <mesh filename="meshes/urdf/Leg8_Knee-actuator-assembly_Knee-motor-bearings.stl" scale="0.001 0.001 0.001" />
      </geometry>
    </visual>
    <collision name="Leg8_Knee_actuator_assembly_Knee_motor_bearings_collision">
      <origin xyz="-0.04889581968953472 0.11894493236997206 -0.05649553858871161" rpy="1.5707963267948992 1.2601277199399066 -3.141592653589789" />
      <geometry>
        <mesh filename="meshes/urdf/Leg8_Knee-actuator-assembly_Knee-motor-bearings.stl" scale="0.001 0.001 0.001" />
      </geometry>
    </collision>
  </link>
  <link name="Leg8_Knee_actuator_assembly_End_Bearing_Holder">
    <inertial>
      <origin xyz="0.03390957918454024 0.003595220400248369 -0.024779268524866047" rpy="0.0 -0.0 0.0" />
      <mass value="0.057169625310268736" />
      <inertia ixx="5.134763459656007e-05" iyy="0.00010281021554763183" izz="5.196194176609631e-05" ixy="-1.1711751146881643e-08" iyz="1.0829253631035405e-08" ixz="9.98550290546874e-07" />
    </inertial>
    <visual name="Leg8_Knee_actuator_assembly_End_Bearing_Holder_visual">
      <origin xyz="0.0328011119064074 -0.11894493236997217 0.016311357777757256" rpy="1.5707963267948968 -1.570796326794896 0" />
      <geometry>
        <mesh filename="meshes/urdf/Leg8_Knee-actuator-assembly_End-Bearing-Holder.stl" scale="0.001 0.001 0.001" />
      </geometry>
    </visual>
    <collision name="Leg8_Knee_actuator_assembly_End_Bearing_Holder_collision">
      <origin xyz="0.0328011119064074 -0.11894493236997217 0.016311357777757256" rpy="1.5707963267948968 -1.570796326794896 0" />
      <geometry>
        <mesh filename="meshes/urdf/Leg8_Knee-actuator-assembly_End-Bearing-Holder.stl" scale="0.001 0.001 0.001" />
      </geometry>
    </collision>
  </link>
  <link name="Leg8_Hip_actuator_assembly_Motor">
    <inertial>
      <origin xyz="-0.014254585975711742 0.013799107411400962 -0.03445749499235991" rpy="0.0 7.382803922328222e-64 0.0" />
      <mass value="0.3028214126901055" />
      <inertia ixx="0.00014141746037829692" iyy="0.00023174021267842676" izz="0.0001381522821278817" ixy="-1.052567678124644e-06" iyz="-1.7994859376901806e-07" ixz="5.361526010456014e-08" />
    </inertial>
    <visual name="Leg8_Hip_actuator_assembly_Motor_visual">
      <origin xyz="-0.014088084835283987 -2.453592884421596e-15 -0.03421294999999985" rpy="-1.5707963267948961 -9.836221983250081e-17 1.5707963267948966" />
      <geometry>
        <mesh filename="meshes/urdf/Leg8_Hip-actuator-assembly_Motor.stl" scale="0.001 0.001 0.001" />
      </geometry>
    </visual>
    <collision name="Leg8_Hip_actuator_assembly_Motor_collision">
      <origin xyz="-0.014088084835283987 -2.453592884421596e-15 -0.03421294999999985" rpy="-1.5707963267948961 -9.836221983250081e-17 1.5707963267948966" />
      <geometry>
        <mesh filename="meshes/urdf/Leg8_Hip-actuator-assembly_Motor.stl" scale="0.001 0.001 0.001" />
      </geometry>
    </collision>
  </link>
  <link name="Leg8_Hip_actuator_assembly_Hip_Bracket">
    <inertial>
      <origin xyz="0.007563359926921698 0.0012437881617798309 -0.04094566173760124" rpy="8.940706509246467e-94 -0.0 0.0" />
      <mass value="0.05792781115933178" />
      <inertia ixx="0.00010067920230328171" iyy="9.858380629719347e-05" izz="5.264746465636727e-05" ixy="4.054417809776089e-06" iyz="1.4243321119436455e-06" ixz="-1.5317549933663653e-05" />
    </inertial>
    <visual name="Leg8_Hip_actuator_assembly_Hip_Bracket_visual">
      <origin xyz="0.01724999999999994 -0.04000000000000272 -0.0950000048352843" rpy="-3.141592653589793 1.4433411822893262e-16 1.5707963267948968" />
      <geometry>
        <mesh filename="meshes/urdf/Leg8_Hip-actuator-assembly_Hip-Bracket.stl" scale="0.001 0.001 0.001" />
      </geometry>
    </visual>
    <collision name="Leg8_Hip_actuator_assembly_Hip_Bracket_collision">
      <origin xyz="0.01724999999999994 -0.04000000000000272 -0.0950000048352843" rpy="-3.141592653589793 1.4433411822893262e-16 1.5707963267948968" />
      <geometry>
        <mesh filename="meshes/urdf/Leg8_Hip-actuator-assembly_Hip-Bracket.stl" scale="0.001 0.001 0.001" />
      </geometry>
    </collision>
  </link>
  <link name="Leg8_Hip_actuator_assembly_Body_Bracket">
    <inertial>
      <origin xyz="-0.03480001266866787 0.004424738499856894 -0.02941478586583365" rpy="0.0 -0.0 0.0" />
      <mass value="0.2737560132535958" />
      <inertia ixx="0.00011826659575640147" iyy="0.00030785752435440617" izz="0.00020548953826174187" ixy="-6.214987810553236e-11" iyz="9.185276276086035e-08" ixz="-3.862534696382966e-10" />
    </inertial>
    <visual name="Leg8_Hip_actuator_assembly_Body_Bracket_visual">
      <origin xyz="-0.11727898724779603 -0.028621778093592735 0.017366123416015285" rpy="-3.141592653589793 1.570796326794896 0" />
      <geometry>
        <mesh filename="meshes/urdf/Leg8_Hip-actuator-assembly_Body-Bracket.stl" scale="0.001 0.001 0.001" />
      </geometry>
    </visual>
    <collision name="Leg8_Hip_actuator_assembly_Body_Bracket_collision">
      <origin xyz="-0.11727898724779603 -0.028621778093592735 0.017366123416015285" rpy="-3.141592653589793 1.570796326794896 0" />
      <geometry>
        <mesh filename="meshes/urdf/Leg8_Hip-actuator-assembly_Body-Bracket.stl" scale="0.001 0.001 0.001" />
      </geometry>
    </collision>
  </link>
  <link name="Leg8_Tibia_Leg">
    <inertial>
      <origin xyz="-0.10421987493399566 -0.007011542435093414 0.047194455370022315" rpy="6.413963312176936e-97 -0.0 0.0" />
      <mass value="0.6725091028785471" />
      <inertia ixx="0.0004886387764186893" iyy="0.004260036865887342" izz="0.003794440466203496" ixy="7.02502700132058e-07" iyz="-3.0485813773189693e-07" ixz="0.0011320633971690132" />
    </inertial>
    <visual name="Leg8_Tibia_Leg_visual">
      <origin xyz="-0.08507464832369394 0.03300000000000265 -0.09829701192912225" rpy="0.2617993877991496 -2.2204460492503082e-16 -1.5707963267948968" />
      <geometry>
        <mesh filename="meshes/urdf/Leg8_Tibia_Leg.stl" scale="0.001 0.001 0.001" />
      </geometry>
    </visual>
    <collision name="Leg8_Tibia_Leg_collision">
      <origin xyz="-0.08507464832369394 0.03300000000000265 -0.09829701192912225" rpy="0.2617993877991496 -2.2204460492503082e-16 -1.5707963267948968" />
      <geometry>
        <mesh filename="meshes/urdf/Leg8_Tibia_Leg.stl" scale="0.001 0.001 0.001" />
      </geometry>
    </collision>
  </link>
  <link name="Leg8_Tibia_Foot">
    <inertial>
      <origin xyz="-0.004715990367889269 -0.00600000002390888 0.004338303909012069" rpy="3.4211388289180104e-49 -0.0 0.0" />
      <mass value="0.0012152855294447645" />
      <inertia ixx="2.8376244461286752e-08" iyy="2.5730108277567582e-08" izz="2.6520716523166358e-08" ixy="5.654453214106201e-17" iyz="1.1700997836665628e-16" ixz="-1.0792250335483082e-08" />
    </inertial>
    <visual name="Leg8_Tibia_Foot_visual">
      <origin xyz="0.16677737167630663 -0.04600000000000149 0.16476956192912293" rpy="-2.8797932657906413 2.2204460492503072e-16 1.5707963267948968" />
      <geometry>
        <mesh filename="meshes/urdf/Leg8_Tibia_Foot.stl" scale="0.001 0.001 0.001" />
      </geometry>
    </visual>
    <collision name="Leg8_Tibia_Foot_collision">
      <origin xyz="0.16677737167630663 -0.04600000000000149 0.16476956192912293" rpy="-2.8797932657906413 2.2204460492503072e-16 1.5707963267948968" />
      <geometry>
        <mesh filename="meshes/urdf/Leg8_Tibia_Foot.stl" scale="0.001 0.001 0.001" />
      </geometry>
    </collision>
  </link>
  <link name="Leg8_Tibia_BadTouch">
    <inertial>
      <origin xyz="-0.014307431578915853 1.0746958878371515e-15 0.019468089410207216" rpy="0.0 -0.0 0.0" />
      <mass value="0.0028499001119515355" />
      <inertia ixx="6.698251338861474e-07" iyy="1.4563954103201284e-05" izz="1.38960289027232e-05" ixy="1.8615439295341403e-20" iyz="1.0164395367051603e-20" ixz="-1.8604646440308694e-06" />
    </inertial>
    <visual name="Leg8_Tibia_BadTouch_visual">
      <origin xyz="-0.0018152277230346337 -0.04003406004253919 0.040308718727737454" rpy="-3.141592653589791 2.931682674400796e-16 1.5707963267948968" />
      <geometry>
        <mesh filename="meshes/urdf/Leg8_Tibia_BadTouch.stl" scale="0.001 0.001 0.001" />
      </geometry>
    </visual>
    <collision name="Leg8_Tibia_BadTouch_collision">
      <origin xyz="-0.0018152277230346337 -0.04003406004253919 0.040308718727737454" rpy="-3.141592653589791 2.931682674400796e-16 1.5707963267948968" />
      <geometry>
        <mesh filename="meshes/urdf/Leg8_Tibia_BadTouch.stl" scale="0.001 0.001 0.001" />
      </geometry>
    </collision>
  </link>
  <joint name="Leg1_Hip_actuator_assembly_Body_Bracket_Rigid_1" type="fixed">
    <origin xyz="0.48240000000000005 0.08825 0.0" rpy="-1.5707963267948966 -0.0 0.0" />
    <parent link="Body" />
    <child link="Leg1_Hip_actuator_assembly_Body_Bracket" />
  </joint>
  <joint name="Leg2_Hip_actuator_assembly_Body_Bracket_Rigid_2" type="fixed">
    <origin xyz="0.3448 0.15265 0.0" rpy="-1.5707963267948966 -0.0 0.0" />
    <parent link="Body" />
    <child link="Leg2_Hip_actuator_assembly_Body_Bracket" />
  </joint>
  <joint name="Leg3_Hip_actuator_assembly_Body_Bracket_Rigid_3" type="fixed">
    <origin xyz="0.2072 0.15265 0.0" rpy="-1.5707963267948966 -0.0 0.0" />
    <parent link="Body" />
    <child link="Leg3_Hip_actuator_assembly_Body_Bracket" />
  </joint>
  <joint name="Leg4_Hip_actuator_assembly_Body_Bracket_Rigid_4" type="fixed">
    <origin xyz="0.0696 0.08825 0.0" rpy="-1.5707963267948966 -0.0 0.0" />
    <parent link="Body" />
    <child link="Leg4_Hip_actuator_assembly_Body_Bracket" />
  </joint>
  <joint name="Leg5_Hip_actuator_assembly_Body_Bracket_Rigid_5" type="fixed">
    <origin xyz="0.48240000000000005 -0.08825 0.0" rpy="1.5707963267948966 -0.0 0.0" />
    <parent link="Body" />
    <child link="Leg5_Hip_actuator_assembly_Body_Bracket" />
  </joint>
  <joint name="Leg6_Hip_actuator_assembly_Body_Bracket_Rigid_6" type="fixed">
    <origin xyz="0.3448 -0.15265 0.0" rpy="1.5707963267948966 -0.0 0.0" />
    <parent link="Body" />
    <child link="Leg6_Hip_actuator_assembly_Body_Bracket" />
  </joint>
  <joint name="Leg7_Hip_actuator_assembly_Body_Bracket_Rigid_7" type="fixed">
    <origin xyz="0.2072 -0.15265 0.0" rpy="1.5707963267948966 -0.0 0.0" />
    <parent link="Body" />
    <child link="Leg7_Hip_actuator_assembly_Body_Bracket" />
  </joint>
  <joint name="Leg8_Hip_actuator_assembly_Body_Bracket_Rigid_8" type="fixed">
    <origin xyz="0.0696 -0.08825 0.0" rpy="1.5707963267948966 -0.0 0.0" />
    <parent link="Body" />
    <child link="Leg8_Hip_actuator_assembly_Body_Bracket" />
  </joint>
  <joint name="Leg1_Femur_actuator_assembly_Femur_Revolute_2" type="revolute">
    <origin xyz="-0.01701633 0.0035000000000000053 -0.03285491" rpy="3.141592653589793 2.465190328815707e-32 1.387778780781446e-17" />
    <parent link="Leg1_Femur_actuator_assembly_Motor" />
    <child link="Leg1_Femur_actuator_assembly_Femur" />
    <axis xyz="1.3877787807814457e-17 -0.9999999999999999 -1.0546606231172699e-16" />
    <limit lower="-0.785398" upper="1.832596" effort="1000000" velocity="1000000" />
  </joint>
  <joint name="Leg1_Knee_actuator_assembly_Knee_motor_bearings_Rigid_5" type="fixed">
    <origin xyz="0.03287312 0.025999999999999995 -0.0169811" rpy="2.5153926499872094e-17 -0.0 0.0" />
    <parent link="Leg1_Knee_actuator_assembly_Motor" />
    <child link="Leg1_Knee_actuator_assembly_Knee_motor_bearings" />
  </joint>
  <joint name="Leg1_Knee_actuator_assembly_KneeMotorPulley_Rigid_6" type="fixed">
    <origin xyz="0.0 -0.0034999999999999966 0.0" rpy="3.141592653589793 -0.0 0.0" />
    <parent link="Leg1_Knee_actuator_assembly_Motor" />
    <child link="Leg1_Knee_actuator_assembly_KneeMotorPulley" />
  </joint>
  <joint name="Leg1_Hip_actuator_assembly_Hip_Bracket_Hip" type="revolute">
    <origin xyz="0.014088090000000051 0.0295 0.034212950000000006" rpy="-1.5707963267948968 5.67908592351187e-32 -1.5707963267948966" />
    <parent link="Leg1_Hip_actuator_assembly_Motor" />
    <child link="Leg1_Hip_actuator_assembly_Hip_Bracket" />
    <axis xyz="-1.0 -2.4651903288156756e-32 -7.511126783110047e-33" />
    <limit lower="-1.570796" upper="1.570796" effort="1000000" velocity="1000000" />
  </joint>
  <joint name="Leg1_Hip_actuator_assembly_Motor_Rigid_11" type="fixed">
    <origin xyz="-0.04888808000000005 0.01525 -0.06921295" rpy="-7.487052658805355e-33 -0.0 2.465190328815662e-32" />
    <parent link="Leg1_Hip_actuator_assembly_Body_Bracket" />
    <child link="Leg1_Hip_actuator_assembly_Motor" />
  </joint>
  <joint name="Leg1_Tibia_Foot_Foot" type="fixed">
    <origin xyz="-0.25185202 0.012999999999999998 -0.06647254999999994" rpy="-3.141592653589793 -4.9303806576313227e-32 -1.1113601665929603e-63" />
    <parent link="Leg1_Tibia_Leg" />
    <child link="Leg1_Tibia_Foot" />
  </joint>
  <joint name="Leg1_Tibia_BadTouch_Rigid_7" type="fixed">
    <origin xyz="-0.13080536 0.007000000000000002 -0.08495926999999995" rpy="-3.141592653589793 -4.9303806576313227e-32 -1.1113601665929603e-63" />
    <parent link="Leg1_Tibia_Leg" />
    <child link="Leg1_Tibia_BadTouch" />
  </joint>
  <joint name="Leg1_Tibia" type="revolute">
    <origin xyz="0.15499677 -0.0034999999999999966 -0.025" rpy="-3.141592653589793 -1.4636356336878855e-33 1.387778780781446e-17" />
    <parent link="Leg1_Femur_actuator_assembly_Femur" />
    <child link="Leg1_Tibia_Leg" />
    <axis xyz="0.0 -1.0 -2.2541062116020984e-32" />
    <limit lower="0.0" upper="2.7" effort="1000000" velocity="1000000" />
  </joint>
  <joint name="Leg1_Femur_actuator_assembly_Motor_Rigid_16" type="fixed">
    <origin xyz="0.03426633 0.013999999999999995 0.06214509" rpy="-3.141592653589793 2.465190328815725e-32 -4.93038065763137e-32" />
    <parent link="Leg1_Hip_actuator_assembly_Hip_Bracket" />
    <child link="Leg1_Femur_actuator_assembly_Motor" />
  </joint>
  <joint name="Leg1_Knee_actuator_assembly_End_Bearing_Holder_Rigid_18" type="fixed">
    <origin xyz="-0.018672890000000004 -0.036500000000000005 0.06873601999999998" rpy="1.0546606231172699e-16 2.465190328815725e-32 -4.93038065763137e-32" />
    <parent link="Leg1_Hip_actuator_assembly_Hip_Bracket" />
    <child link="Leg1_Knee_actuator_assembly_End_Bearing_Holder" />
  </joint>
  <joint name="Leg1_Knee_actuator_assembly_Motor_Rigid_19" type="fixed">
    <origin xyz="0.0 -0.020999999999999998 0.0" rpy="-3.141592653589793 -1.4636356336878855e-33 1.387778780781446e-17" />
    <parent link="Leg1_Femur_actuator_assembly_Femur" />
    <child link="Leg1_Knee_actuator_assembly_Motor" />
  </joint>
  <joint name="Leg2_Femur_actuator_assembly_Femur_Revolute_2" type="revolute">
    <origin xyz="-0.017016330000000003 0.014525959999999997 -0.02967644" rpy="3.141592653589793 5.225294096901429e-17 1.387778780781447e-17" />
    <parent link="Leg2_Femur_actuator_assembly_Motor" />
    <child link="Leg2_Femur_actuator_assembly_Femur" />
    <axis xyz="1.4155233132381125e-17 -0.939693 -0.34202" />
    <limit lower="-0.785398" upper="1.832596" effort="1000000" velocity="1000000" />
  </joint>
  <joint name="Leg2_Knee_actuator_assembly_Knee_motor_bearings_Rigid_5" type="fixed">
    <origin xyz="0.032873119999999985 0.030239879999999993 -0.007064499999999967" rpy="7.091054437324482e-17 1.2828127435224422e-17 -1.6653345369377346e-16" />
    <parent link="Leg2_Knee_actuator_assembly_Motor" />
    <child link="Leg2_Knee_actuator_assembly_Knee_motor_bearings" />
  </joint>
  <joint name="Leg2_Knee_actuator_assembly_KneeMotorPulley_Rigid_6" type="fixed">
    <origin xyz="0.0 -0.0032889300000000254 -0.0011970699999999824" rpy="3.141592653589793 1.2828127435224422e-17 -1.6653345369377346e-16" />
    <parent link="Leg2_Knee_actuator_assembly_Motor" />
    <child link="Leg2_Knee_actuator_assembly_KneeMotorPulley" />
  </joint>
  <joint name="Leg2_Hip_actuator_assembly_Hip_Bracket_Hip" type="revolute">
    <origin xyz="0.014088090000000015 0.0295 0.034212950000000006" rpy="-1.5707963267948968 5.67908592351187e-32 -1.5707963267948966" />
    <parent link="Leg2_Hip_actuator_assembly_Motor" />
    <child link="Leg2_Hip_actuator_assembly_Hip_Bracket" />
    <axis xyz="-1.0 -2.4651903288156756e-32 -7.511126783110047e-33" />
    <limit lower="-1.570796" upper="1.570796" effort="1000000" velocity="1000000" />
  </joint>
  <joint name="Leg2_Hip_actuator_assembly_Motor_Rigid_11" type="fixed">
    <origin xyz="-0.04888807999999997 0.01525 -0.06921295000000001" rpy="-7.487052658805355e-33 -0.0 2.465190328815662e-32" />
    <parent link="Leg2_Hip_actuator_assembly_Body_Bracket" />
    <child link="Leg2_Hip_actuator_assembly_Motor" />
  </joint>
  <joint name="Leg2_Tibia_Foot_Foot" type="fixed">
    <origin xyz="-0.2518520199999999 0.03495096000000009 -0.058017500000000055" rpy="-3.141592653589793 3.6415066552172075e-17 -1.6653345369377346e-16" />
    <parent link="Leg2_Tibia_Leg" />
    <child link="Leg2_Tibia_Foot" />
  </joint>
  <joint name="Leg2_Tibia_BadTouch_Rigid_7" type="fixed">
    <origin xyz="-0.13080535999999993 0.035635630000000036 -0.07744146" rpy="-3.141592653589793 3.6415066552172075e-17 -1.6653345369377346e-16" />
    <parent link="Leg2_Tibia_Leg" />
    <child link="Leg2_Tibia_BadTouch" />
  </joint>
  <joint name="Leg2_Tibia" type="revolute">
    <origin xyz="0.15499677 0.0052615800000000235 -0.02468939000000006" rpy="-3.141592653589793 1.1605841558605057e-17 -1.5265566588595895e-16" />
    <parent link="Leg2_Femur_actuator_assembly_Femur" />
    <child link="Leg2_Tibia_Leg" />
    <axis xyz="-1.615741237056297e-16 -0.9396930000000002 -0.34202000000000005" />
    <limit lower="0.0" upper="2.7" effort="1000000" velocity="1000000" />
  </joint>
  <joint name="Leg2_Femur_actuator_assembly_Motor_Rigid_16" type="fixed">
    <origin xyz="0.03426633 -0.008099179999999997 0.06318557000000002" rpy="-3.141592653589793 5.551115123125782e-17 -3.1123312397483497e-32" />
    <parent link="Leg2_Hip_actuator_assembly_Hip_Bracket" />
    <child link="Leg2_Femur_actuator_assembly_Motor" />
  </joint>
  <joint name="Leg2_Knee_actuator_assembly_End_Bearing_Holder_Rigid_18" type="fixed">
    <origin xyz="-0.018672890000000004 -0.05780788999999999 0.05210699000000002" rpy="1.05466062311727e-16 5.551115123125782e-17 -3.1123312397483497e-32" />
    <parent link="Leg2_Hip_actuator_assembly_Hip_Bracket" />
    <child link="Leg2_Knee_actuator_assembly_End_Bearing_Holder" />
  </joint>
  <joint name="Leg2_Knee_actuator_assembly_Motor_Rigid_19" type="fixed">
    <origin xyz="-4.440892098500626e-18 -0.019733550000000016 -0.0071824300000000105" rpy="-3.141592653589793 1.1605841558605057e-17 -1.5265566588595895e-16" />
    <parent link="Leg2_Femur_actuator_assembly_Femur" />
    <child link="Leg2_Knee_actuator_assembly_Motor" />
  </joint>
  <joint name="Leg3_Femur_actuator_assembly_Femur_Revolute_2" type="revolute">
    <origin xyz="-0.01701633 0.007387189999999997 0.0322044" rpy="3.141592653589793 5.016871380616563e-19 -1.232595164407831e-32" />
    <parent link="Leg3_Femur_actuator_assembly_Motor" />
    <child link="Leg3_Femur_actuator_assembly_Femur" />
    <axis xyz="-1.6333327816445317e-19 0.945519 -0.3255679999999999" />
    <limit lower="-0.785398" upper="1.832596" effort="1000000" velocity="1000000" />
  </joint>
  <joint name="Leg3_Knee_actuator_assembly_Knee_motor_bearings_Rigid_5" type="fixed">
    <origin xyz="0.03287312 -0.01905497999999998 0.024520720000000003" rpy="7.405648889701683e-18 1.448321076862661e-17 -5.55111512312578e-17" />
    <parent link="Leg3_Knee_actuator_assembly_Motor" />
    <child link="Leg3_Knee_actuator_assembly_Knee_motor_bearings" />
  </joint>
  <joint name="Leg3_Knee_actuator_assembly_KneeMotorPulley_Rigid_6" type="fixed">
    <origin xyz="-4.440892098500626e-18 0.0033093099999999963 -0.0011394899999999986" rpy="3.141592653589793 1.448321076862661e-17 -5.55111512312578e-17" />
    <parent link="Leg3_Knee_actuator_assembly_Motor" />
    <child link="Leg3_Knee_actuator_assembly_KneeMotorPulley" />
  </joint>
  <joint name="Leg3_Hip_actuator_assembly_Hip_Bracket_Hip" type="revolute">
    <origin xyz="0.014088089999999998 0.0295 0.034212950000000006" rpy="-1.5707963267948968 5.67908592351187e-32 -1.5707963267948966" />
    <parent link="Leg3_Hip_actuator_assembly_Motor" />
    <child link="Leg3_Hip_actuator_assembly_Hip_Bracket" />
    <axis xyz="-1.0 -2.4651903288156756e-32 -7.511126783110047e-33" />
    <limit lower="-1.570796" upper="1.570796" effort="1000000" velocity="1000000" />
  </joint>
  <joint name="Leg3_Hip_actuator_assembly_Motor_Rigid_11" type="fixed">
    <origin xyz="-0.048888079999999993 0.01525 -0.06921295000000001" rpy="-7.487052658805355e-33 -0.0 2.465190328815662e-32" />
    <parent link="Leg3_Hip_actuator_assembly_Body_Bracket" />
    <child link="Leg3_Hip_actuator_assembly_Motor" />
  </joint>
  <joint name="Leg3_Tibia_Foot_Foot" type="fixed">
    <origin xyz="-0.25185202 0.009349600000000003 0.06708341000000001" rpy="3.141592653589793 -6.840267502603835e-17 -1.9186998132062052e-33" />
    <parent link="Leg3_Tibia_Leg" />
    <child link="Leg3_Tibia_Foot" />
  </joint>
  <joint name="Leg3_Tibia_BadTouch_Rigid_7" type="fixed">
    <origin xyz="-0.13080536 0.021041410000000003 0.08260954999999999" rpy="3.141592653589793 -6.840267502603835e-17 -1.9186998132062052e-33" />
    <parent link="Leg3_Tibia_Leg" />
    <child link="Leg3_Tibia_BadTouch" />
  </joint>
  <joint name="Leg3_Tibia" type="revolute">
    <origin xyz="0.15499677 0.011448520000000002 0.02249847000000001" rpy="-3.141592653589793 -1.2389836656718867e-17 -1.4407415222200021e-33" />
    <parent link="Leg3_Femur_actuator_assembly_Femur" />
    <child link="Leg3_Tibia_Leg" />
    <axis xyz="4.197067618819102e-18 0.9455190000000002 -0.325568" />
    <limit lower="0.0" upper="2.7" effort="1000000" velocity="1000000" />
  </joint>
  <joint name="Leg3_Femur_actuator_assembly_Motor_Rigid_16" type="fixed">
    <origin xyz="0.03426633 -0.03346973 -0.05420140000000002" rpy="-3.141592653589793 1.2789126161629393e-32 -6.162975822039166e-32" />
    <parent link="Leg3_Hip_actuator_assembly_Hip_Bracket" />
    <child link="Leg3_Femur_actuator_assembly_Motor" />
  </joint>
  <joint name="Leg3_Knee_actuator_assembly_End_Bearing_Holder_Rigid_18" type="fixed">
    <origin xyz="-0.018672890000000004 0.01213317 -0.07687443000000002" rpy="1.0546606231172697e-16 1.2789126161629393e-32 -6.162975822039166e-32" />
    <parent link="Leg3_Hip_actuator_assembly_Hip_Bracket" />
    <child link="Leg3_Knee_actuator_assembly_End_Bearing_Holder" />
  </joint>
  <joint name="Leg3_Knee_actuator_assembly_Motor_Rigid_19" type="fixed">
    <origin xyz="4.440892098500626e-18 0.01985589000000001 -0.0068369400000000006" rpy="-3.141592653589793 -1.2389836656718867e-17 -1.4407415222200021e-33" />
    <parent link="Leg3_Femur_actuator_assembly_Femur" />
    <child link="Leg3_Knee_actuator_assembly_Motor" />
  </joint>
  <joint name="Leg4_Femur_actuator_assembly_Femur_Revolute_2" type="revolute">
    <origin xyz="-0.01701633 -0.0034999999999999966 0.032854900000000006" rpy="3.141592653589793 -3.6977854932234846e-32 1.387778780781446e-17" />
    <parent link="Leg4_Femur_actuator_assembly_Motor" />
    <child link="Leg4_Femur_actuator_assembly_Femur" />
    <axis xyz="-1.3877787807814457e-17 0.9999999999999999 1.05466062311727e-16" />
    <limit lower="-0.785398" upper="1.832596" effort="1000000" velocity="1000000" />
  </joint>
  <joint name="Leg4_Knee_actuator_assembly_Knee_motor_bearings_Rigid_5" type="fixed">
    <origin xyz="0.03287312 -0.026000000000000006 0.01698111" rpy="2.5153926499871872e-17 9.860761315262648e-32 -2.0814500972858717e-64" />
    <parent link="Leg4_Knee_actuator_assembly_Motor" />
    <child link="Leg4_Knee_actuator_assembly_Knee_motor_bearings" />
  </joint>
  <joint name="Leg4_Knee_actuator_assembly_KneeMotorPulley_Rigid_6" type="fixed">
    <origin xyz="0.0 0.0034999999999999966 0.0" rpy="3.141592653589793 9.860761315262648e-32 -2.0814500972858717e-64" />
    <parent link="Leg4_Knee_actuator_assembly_Motor" />
    <child link="Leg4_Knee_actuator_assembly_KneeMotorPulley" />
  </joint>
  <joint name="Leg4_Hip_actuator_assembly_Hip_Bracket_Hip" type="revolute">
    <origin xyz="0.014088089999999998 0.0295 0.034212950000000006" rpy="-1.5707963267948968 5.67908592351187e-32 -1.5707963267948966" />
    <parent link="Leg4_Hip_actuator_assembly_Motor" />
    <child link="Leg4_Hip_actuator_assembly_Hip_Bracket" />
    <axis xyz="-1.0 -2.4651903288156756e-32 -7.511126783110047e-33" />
    <limit lower="-1.570796" upper="1.570796" effort="1000000" velocity="1000000" />
  </joint>
  <joint name="Leg4_Hip_actuator_assembly_Motor_Rigid_11" type="fixed">
    <origin xyz="-0.04888808 0.01525 -0.06921295" rpy="-7.487052658805355e-33 -0.0 2.465190328815662e-32" />
    <parent link="Leg4_Hip_actuator_assembly_Body_Bracket" />
    <child link="Leg4_Hip_actuator_assembly_Motor" />
  </joint>
  <joint name="Leg4_Tibia_Foot_Foot" type="fixed">
    <origin xyz="-0.25185202 -0.013000000000000008 0.06647254999999999" rpy="3.141592653589793 4.3140830754274083e-32 -9.106344175625686e-65" />
    <parent link="Leg4_Tibia_Leg" />
    <child link="Leg4_Tibia_Foot" />
  </joint>
  <joint name="Leg4_Tibia_BadTouch_Rigid_7" type="fixed">
    <origin xyz="-0.13080536 -0.007000000000000002 0.08495928" rpy="3.141592653589793 4.3140830754274083e-32 -9.106344175625686e-65" />
    <parent link="Leg4_Tibia_Leg" />
    <child link="Leg4_Tibia_BadTouch" />
  </joint>
  <joint name="Leg4_Tibia" type="revolute">
    <origin xyz="0.15499677 0.0034999999999999966 0.02500000000000001" rpy="-3.141592653589793 -5.076744221000113e-32 1.387778780781446e-17" />
    <parent link="Leg4_Femur_actuator_assembly_Femur" />
    <child link="Leg4_Tibia_Leg" />
    <axis xyz="0.0 1.0 -2.110841172135633e-33" />
    <limit lower="0.0" upper="2.7" effort="1000000" velocity="1000000" />
  </joint>
  <joint name="Leg4_Femur_actuator_assembly_Motor_Rigid_16" type="fixed">
    <origin xyz="0.03426633 -0.013999999999999995 -0.06214510000000001" rpy="-3.141592653589793 1.232595164407858e-32 -4.930380657631343e-32" />
    <parent link="Leg4_Hip_actuator_assembly_Hip_Bracket" />
    <child link="Leg4_Femur_actuator_assembly_Motor" />
  </joint>
  <joint name="Leg4_Knee_actuator_assembly_End_Bearing_Holder_Rigid_18" type="fixed">
    <origin xyz="-0.018672890000000004 0.036500000000000005 -0.06873602999999999" rpy="1.0546606231172699e-16 1.232595164407858e-32 -4.930380657631343e-32" />
    <parent link="Leg4_Hip_actuator_assembly_Hip_Bracket" />
    <child link="Leg4_Knee_actuator_assembly_End_Bearing_Holder" />
  </joint>
  <joint name="Leg4_Knee_actuator_assembly_Motor_Rigid_19" type="fixed">
    <origin xyz="0.0 0.021000000000000005 0.0" rpy="-3.141592653589793 -5.076744221000113e-32 1.387778780781446e-17" />
    <parent link="Leg4_Femur_actuator_assembly_Femur" />
    <child link="Leg4_Knee_actuator_assembly_Motor" />
  </joint>
  <joint name="Leg5_Femur_actuator_assembly_Femur_Revolute_2" type="revolute">
    <origin xyz="-0.01701633 0.0034999999999999966 -0.03285491" rpy="3.141592653589793 -7.395570986447069e-32 0.0" />
    <parent link="Leg5_Femur_actuator_assembly_Motor" />
    <child link="Leg5_Femur_actuator_assembly_Femur" />
    <axis xyz="0.0 -0.9999999999999999 -1.0546606231172699e-16" />
    <limit lower="-0.785398" upper="1.832596" effort="1000000" velocity="1000000" />
  </joint>
  <joint name="Leg5_Knee_actuator_assembly_Knee_motor_bearings_Rigid_5" type="fixed">
    <origin xyz="0.03287312 0.026000000000000006 -0.0169811" rpy="2.5153926499871872e-17 -1.7256332301709633e-31 5.551115123125783e-17" />
    <parent link="Leg5_Knee_actuator_assembly_Motor" />
    <child link="Leg5_Knee_actuator_assembly_Knee_motor_bearings" />
  </joint>
  <joint name="Leg5_Knee_actuator_assembly_KneeMotorPulley_Rigid_6" type="fixed">
    <origin xyz="0.0 -0.0034999999999999966 0.0" rpy="3.141592653589793 -1.7256332301709633e-31 5.551115123125783e-17" />
    <parent link="Leg5_Knee_actuator_assembly_Motor" />
    <child link="Leg5_Knee_actuator_assembly_KneeMotorPulley" />
  </joint>
  <joint name="Leg5_Hip_actuator_assembly_Hip_Bracket_Hip" type="revolute">
    <origin xyz="-0.014088080000000005 0.0295 -0.034212950000000006" rpy="-1.5707963267948968 -1.716485062935135e-32 -1.5707963267948966" />
    <parent link="Leg5_Hip_actuator_assembly_Motor" />
    <child link="Leg5_Hip_actuator_assembly_Hip_Bracket" />
    <axis xyz="-1.0 -9.860761315262641e-32 -7.511126783110318e-33" />
    <limit lower="-1.570796" upper="1.570796" effort="1000000" velocity="1000000" />
  </joint>
  <joint name="Leg5_Hip_actuator_assembly_Motor_Rigid_11" type="fixed">
    <origin xyz="-0.02071190999999999 -0.01525 -0.06921295" rpy="-3.141592653589793 1.0947644252537633e-47 9.860761315262646e-32" />
    <parent link="Leg5_Hip_actuator_assembly_Body_Bracket" />
    <child link="Leg5_Hip_actuator_assembly_Motor" />
  </joint>
  <joint name="Leg5_Tibia_Foot_Foot" type="fixed">
    <origin xyz="-0.25185202 0.013000000000000008 -0.06647254999999994" rpy="-3.141592653589793 -6.77927340424307e-32 5.551115123125783e-17" />
    <parent link="Leg5_Tibia_Leg" />
    <child link="Leg5_Tibia_Foot" />
  </joint>
  <joint name="Leg5_Tibia_BadTouch_Rigid_7" type="fixed">
    <origin xyz="-0.13080536 0.007000000000000002 -0.08495926999999995" rpy="-3.141592653589793 -6.77927340424307e-32 5.551115123125783e-17" />
    <parent link="Leg5_Tibia_Leg" />
    <child link="Leg5_Tibia_BadTouch" />
  </joint>
  <joint name="Leg5_Tibia" type="revolute">
    <origin xyz="0.15499677 -0.0035000000000000053 -0.025" rpy="-3.141592653589793 -1.4791141972893971e-31 -1.5599635009748363e-47" />
    <parent link="Leg5_Femur_actuator_assembly_Femur" />
    <child link="Leg5_Tibia_Leg" />
    <axis xyz="-0.0 -1.0 2.110841172135633e-33" />
    <limit lower="0.0" upper="2.7" effort="1000000" velocity="1000000" />
  </joint>
  <joint name="Leg5_Femur_actuator_assembly_Motor_Rigid_16" type="fixed">
    <origin xyz="0.03426633 0.013999999999999986 0.06214509" rpy="-3.141592653589793 -8.224896002365597e-46 8.597034325155041e-47" />
    <parent link="Leg5_Hip_actuator_assembly_Hip_Bracket" />
    <child link="Leg5_Femur_actuator_assembly_Motor" />
  </joint>
  <joint name="Leg5_Knee_actuator_assembly_End_Bearing_Holder_Rigid_18" type="fixed">
    <origin xyz="-0.018672890000000004 -0.03650000000000001 0.06873601999999998" rpy="1.05466062311727e-16 -8.224896002365597e-46 8.597034325155041e-47" />
    <parent link="Leg5_Hip_actuator_assembly_Hip_Bracket" />
    <child link="Leg5_Knee_actuator_assembly_End_Bearing_Holder" />
  </joint>
  <joint name="Leg5_Knee_actuator_assembly_Motor_Rigid_19" type="fixed">
    <origin xyz="0.0 -0.021000000000000005 0.0" rpy="-3.141592653589793 -1.4791141972893971e-31 -1.5599635009748363e-47" />
    <parent link="Leg5_Femur_actuator_assembly_Femur" />
    <child link="Leg5_Knee_actuator_assembly_Motor" />
  </joint>
  <joint name="Leg6_Femur_actuator_assembly_Femur_Revolute_2" type="revolute">
    <origin xyz="-0.017016329999999996 -0.007387189999999997 -0.032204399999999966" rpy="3.141592653589793 4.67085562468139e-18 2.4651903288156613e-32" />
    <parent link="Leg6_Femur_actuator_assembly_Motor" />
    <child link="Leg6_Femur_actuator_assembly_Femur" />
    <axis xyz="1.5206811240162669e-18 -0.9455190000000002 0.3255679999999999" />
    <limit lower="-0.785398" upper="1.832596" effort="1000000" velocity="1000000" />
  </joint>
  <joint name="Leg6_Knee_actuator_assembly_Knee_motor_bearings_Rigid_5" type="fixed">
    <origin xyz="0.03287312 0.019054979999999996 -0.02452071999999994" rpy="-6.506607863041895e-17 2.7730278791122933e-17 -2.220446049250313e-16" />
    <parent link="Leg6_Knee_actuator_assembly_Motor" />
    <child link="Leg6_Knee_actuator_assembly_Knee_motor_bearings" />
  </joint>
  <joint name="Leg6_Knee_actuator_assembly_KneeMotorPulley_Rigid_6" type="fixed">
    <origin xyz="0.0 -0.0033093099999999963 0.0011394900000000518" rpy="3.141592653589793 2.7730278791122933e-17 -2.220446049250313e-16" />
    <parent link="Leg6_Knee_actuator_assembly_Motor" />
    <child link="Leg6_Knee_actuator_assembly_KneeMotorPulley" />
  </joint>
  <joint name="Leg6_Hip_actuator_assembly_Hip_Bracket_Hip" type="revolute">
    <origin xyz="-0.01408807999999997 0.0295 -0.034212950000000006" rpy="-1.5707963267948968 -1.716485062935135e-32 -1.5707963267948966" />
    <parent link="Leg6_Hip_actuator_assembly_Motor" />
    <child link="Leg6_Hip_actuator_assembly_Hip_Bracket" />
    <axis xyz="-1.0 -9.860761315262641e-32 -7.511126783110318e-33" />
    <limit lower="-1.570796" upper="1.570796" effort="1000000" velocity="1000000" />
  </joint>
  <joint name="Leg6_Hip_actuator_assembly_Motor_Rigid_11" type="fixed">
    <origin xyz="-0.02071190999999999 -0.01525 -0.06921295000000001" rpy="-3.141592653589793 1.0947644252537633e-47 9.860761315262646e-32" />
    <parent link="Leg6_Hip_actuator_assembly_Body_Bracket" />
    <child link="Leg6_Hip_actuator_assembly_Motor" />
  </joint>
  <joint name="Leg6_Tibia_Foot_Foot" type="fixed">
    <origin xyz="-0.25185202 -0.009349599999999967 -0.06708342000000002" rpy="3.141592653589793 -7.338929875790842e-17 -1.1102230246251563e-16" />
    <parent link="Leg6_Tibia_Leg" />
    <child link="Leg6_Tibia_Foot" />
  </joint>
  <joint name="Leg6_Tibia_BadTouch_Rigid_7" type="fixed">
    <origin xyz="-0.13080536 -0.021041410000000003 -0.08260955000000003" rpy="3.141592653589793 -7.338929875790842e-17 -1.1102230246251563e-16" />
    <parent link="Leg6_Tibia_Leg" />
    <child link="Leg6_Tibia_BadTouch" />
  </joint>
  <joint name="Leg6_Tibia" type="revolute">
    <origin xyz="0.15499676999999995 -0.011448520000000002 -0.022498470000000027" rpy="-3.141592653589793 -9.615456113415308e-18 -1.6653345369377346e-16" />
    <parent link="Leg6_Femur_actuator_assembly_Femur" />
    <child link="Leg6_Tibia_Leg" />
    <axis xyz="-1.6211171054303168e-16 -0.945519 0.3255680000000001" />
    <limit lower="0.0" upper="2.7" effort="1000000" velocity="1000000" />
  </joint>
  <joint name="Leg6_Femur_actuator_assembly_Motor_Rigid_16" type="fixed">
    <origin xyz="0.03426633 0.03346973 0.05420139000000002" rpy="-3.141592653589793 1.2789126161628715e-32 2.46519032881567e-32" />
    <parent link="Leg6_Hip_actuator_assembly_Hip_Bracket" />
    <child link="Leg6_Femur_actuator_assembly_Motor" />
  </joint>
  <joint name="Leg6_Knee_actuator_assembly_End_Bearing_Holder_Rigid_18" type="fixed">
    <origin xyz="-0.018672890000000004 -0.01213317 0.07687442000000001" rpy="1.05466062311727e-16 1.2789126161628715e-32 2.46519032881567e-32" />
    <parent link="Leg6_Hip_actuator_assembly_Hip_Bracket" />
    <child link="Leg6_Knee_actuator_assembly_End_Bearing_Holder" />
  </joint>
  <joint name="Leg6_Knee_actuator_assembly_Motor_Rigid_19" type="fixed">
    <origin xyz="-4.440892098500626e-18 -0.01985589000000001 0.0068369400000000274" rpy="-3.141592653589793 -9.615456113415308e-18 -1.6653345369377346e-16" />
    <parent link="Leg6_Femur_actuator_assembly_Femur" />
    <child link="Leg6_Knee_actuator_assembly_Motor" />
  </joint>
  <joint name="Leg7_Femur_actuator_assembly_Femur_Revolute_2" type="revolute">
    <origin xyz="-0.017016329999999996 -0.014525959999999997 0.02967644" rpy="3.141592653589793 -6.635241162449039e-18 -1.3877787807814457e-17" />
    <parent link="Leg7_Femur_actuator_assembly_Motor" />
    <child link="Leg7_Femur_actuator_assembly_Femur" />
    <axis xyz="1.0771474876107774e-17 0.939693 0.34202000000000005" />
    <limit lower="-0.785398" upper="1.832596" effort="1000000" velocity="1000000" />
  </joint>
  <joint name="Leg7_Knee_actuator_assembly_Knee_motor_bearings_Rigid_5" type="fixed">
    <origin xyz="0.03287312 -0.030239879999999993 0.007064500000000002" rpy="1.5535068771782477e-17 -4.915736034471464e-17 5.551115123125783e-17" />
    <parent link="Leg7_Knee_actuator_assembly_Motor" />
    <child link="Leg7_Knee_actuator_assembly_Knee_motor_bearings" />
  </joint>
  <joint name="Leg7_Knee_actuator_assembly_KneeMotorPulley_Rigid_6" type="fixed">
    <origin xyz="0.0 0.0032889300000000076 0.0011970700000000002" rpy="3.141592653589793 -4.915736034471464e-17 5.551115123125783e-17" />
    <parent link="Leg7_Knee_actuator_assembly_Motor" />
    <child link="Leg7_Knee_actuator_assembly_KneeMotorPulley" />
  </joint>
  <joint name="Leg7_Hip_actuator_assembly_Hip_Bracket_Hip" type="revolute">
    <origin xyz="-0.014088080000000005 0.0295 -0.034212950000000006" rpy="-1.5707963267948968 -1.716485062935135e-32 -1.5707963267948966" />
    <parent link="Leg7_Hip_actuator_assembly_Motor" />
    <child link="Leg7_Hip_actuator_assembly_Hip_Bracket" />
    <axis xyz="-1.0 -9.860761315262641e-32 -7.511126783110318e-33" />
    <limit lower="-1.570796" upper="1.570796" effort="1000000" velocity="1000000" />
  </joint>
  <joint name="Leg7_Hip_actuator_assembly_Motor_Rigid_11" type="fixed">
    <origin xyz="-0.02071190999999999 -0.01525 -0.06921295000000001" rpy="-3.141592653589793 1.0947644252537633e-47 9.860761315262646e-32" />
    <parent link="Leg7_Hip_actuator_assembly_Body_Bracket" />
    <child link="Leg7_Hip_actuator_assembly_Motor" />
  </joint>
  <joint name="Leg7_Tibia_Foot_Foot" type="fixed">
    <origin xyz="-0.25185202 -0.034950960000000024 0.05801750000000002" rpy="3.141592653589793 -3.0617647340929665e-18 -3.7676135224011757e-35" />
    <parent link="Leg7_Tibia_Leg" />
    <child link="Leg7_Tibia_Foot" />
  </joint>
  <joint name="Leg7_Tibia_BadTouch_Rigid_7" type="fixed">
    <origin xyz="-0.13080536 -0.03563563 0.07744146" rpy="3.141592653589793 -3.0617647340929665e-18 -3.7676135224011757e-35" />
    <parent link="Leg7_Tibia_Leg" />
    <child link="Leg7_Tibia_BadTouch" />
  </joint>
  <joint name="Leg7_Tibia" type="revolute">
    <origin xyz="0.15499677 -0.0052615800000000235 0.024689390000000005" rpy="-3.141592653589793 -2.765618483931159e-17 -1.387778780781446e-17" />
    <parent link="Leg7_Femur_actuator_assembly_Femur" />
    <child link="Leg7_Tibia_Leg" />
    <axis xyz="-7.189583156360531e-18 0.939693 0.34202" />
    <limit lower="0.0" upper="2.7" effort="1000000" velocity="1000000" />
  </joint>
  <joint name="Leg7_Femur_actuator_assembly_Motor_Rigid_16" type="fixed">
    <origin xyz="0.03426633 0.008099179999999997 -0.06318557999999998" rpy="-3.141592653589793 -1.3352616924852523e-32 8.456209532292938e-47" />
    <parent link="Leg7_Hip_actuator_assembly_Hip_Bracket" />
    <child link="Leg7_Femur_actuator_assembly_Motor" />
  </joint>
  <joint name="Leg7_Knee_actuator_assembly_End_Bearing_Holder_Rigid_18" type="fixed">
    <origin xyz="-0.018672890000000004 0.05780789000000001 -0.05210699999999997" rpy="1.05466062311727e-16 -1.3352616924852523e-32 8.456209532292938e-47" />
    <parent link="Leg7_Hip_actuator_assembly_Hip_Bracket" />
    <child link="Leg7_Knee_actuator_assembly_End_Bearing_Holder" />
  </joint>
  <joint name="Leg7_Knee_actuator_assembly_Motor_Rigid_19" type="fixed">
    <origin xyz="0.0 0.019733550000000016 0.007182429999999993" rpy="-3.141592653589793 -2.765618483931159e-17 -1.387778780781446e-17" />
    <parent link="Leg7_Femur_actuator_assembly_Femur" />
    <child link="Leg7_Knee_actuator_assembly_Motor" />
  </joint>
  <joint name="Leg8_Femur_actuator_assembly_Femur_Revolute_2" type="revolute">
    <origin xyz="-0.01701633 -0.0035000000000000053 0.032854900000000006" rpy="3.141592653589793 -9.860761315262595e-32 -3.503246160812043e-46" />
    <parent link="Leg8_Femur_actuator_assembly_Motor" />
    <child link="Leg8_Femur_actuator_assembly_Femur" />
    <axis xyz="-0.0 0.9999999999999999 1.0546606231172699e-16" />
    <limit lower="-0.785398" upper="1.832596" effort="1000000" velocity="1000000" />
  </joint>
  <joint name="Leg8_Knee_actuator_assembly_Knee_motor_bearings_Rigid_5" type="fixed">
    <origin xyz="0.03287312 -0.025999999999999995 0.01698111" rpy="2.5153926499872057e-17 3.821045009664276e-31 -5.551115123125783e-17" />
    <parent link="Leg8_Knee_actuator_assembly_Motor" />
    <child link="Leg8_Knee_actuator_assembly_Knee_motor_bearings" />
  </joint>
  <joint name="Leg8_Knee_actuator_assembly_KneeMotorPulley_Rigid_6" type="fixed">
    <origin xyz="0.0 0.0034999999999999966 0.0" rpy="3.141592653589793 3.821045009664276e-31 -5.551115123125783e-17" />
    <parent link="Leg8_Knee_actuator_assembly_Motor" />
    <child link="Leg8_Knee_actuator_assembly_KneeMotorPulley" />
  </joint>
  <joint name="Leg8_Hip_actuator_assembly_Hip_Bracket_Hip" type="revolute">
    <origin xyz="-0.014088079999999996 0.0295 -0.034212950000000006" rpy="-1.5707963267948968 -1.716485062935135e-32 -1.5707963267948966" />
    <parent link="Leg8_Hip_actuator_assembly_Motor" />
    <child link="Leg8_Hip_actuator_assembly_Hip_Bracket" />
    <axis xyz="-1.0 -9.860761315262641e-32 -7.511126783110318e-33" />
    <limit lower="-1.570796" upper="1.570796" effort="1000000" velocity="1000000" />
  </joint>
  <joint name="Leg8_Hip_actuator_assembly_Motor_Rigid_11" type="fixed">
    <origin xyz="-0.020711909999999997 -0.01525 -0.06921295" rpy="-3.141592653589793 1.0947644252537633e-47 9.860761315262646e-32" />
    <parent link="Leg8_Hip_actuator_assembly_Body_Bracket" />
    <child link="Leg8_Hip_actuator_assembly_Motor" />
  </joint>
  <joint name="Leg8_Tibia_Foot_Foot" type="fixed">
    <origin xyz="-0.25185202 -0.012999999999999998 0.06647254999999999" rpy="3.141592653589793 -1.7256332301709635e-31 -2.775557561562892e-17" />
    <parent link="Leg8_Tibia_Leg" />
    <child link="Leg8_Tibia_Foot" />
  </joint>
  <joint name="Leg8_Tibia_BadTouch_Rigid_7" type="fixed">
    <origin xyz="-0.13080536 -0.007000000000000002 0.08495928" rpy="3.141592653589793 -1.7256332301709635e-31 -2.775557561562892e-17" />
    <parent link="Leg8_Tibia_Leg" />
    <child link="Leg8_Tibia_BadTouch" />
  </joint>
  <joint name="Leg8_Tibia" type="revolute">
    <origin xyz="0.15499677 0.0034999999999999875 0.025" rpy="-3.141592653589793 -1.232595164407831e-32 -1.2999695841456969e-48" />
    <parent link="Leg8_Femur_actuator_assembly_Femur" />
    <child link="Leg8_Tibia_Leg" />
    <axis xyz="0.0 1.0 -2.110841172135633e-33" />
    <limit lower="0.0" upper="2.7" effort="1000000" velocity="1000000" />
  </joint>
  <joint name="Leg8_Femur_actuator_assembly_Motor_Rigid_16" type="fixed">
    <origin xyz="0.03426633 -0.013999999999999999 -0.06214510000000001" rpy="-3.141592653589793 -9.860761315262595e-32 -2.747540295028193e-46" />
    <parent link="Leg8_Hip_actuator_assembly_Hip_Bracket" />
    <child link="Leg8_Femur_actuator_assembly_Motor" />
  </joint>
  <joint name="Leg8_Knee_actuator_assembly_End_Bearing_Holder_Rigid_18" type="fixed">
    <origin xyz="-0.018672890000000004 0.0365 -0.06873602999999999" rpy="1.05466062311727e-16 -9.860761315262595e-32 -2.747540295028193e-46" />
    <parent link="Leg8_Hip_actuator_assembly_Hip_Bracket" />
    <child link="Leg8_Knee_actuator_assembly_End_Bearing_Holder" />
  </joint>
  <joint name="Leg8_Knee_actuator_assembly_Motor_Rigid_19" type="fixed">
    <origin xyz="0.0 0.020999999999999998 0.0" rpy="-3.141592653589793 -1.232595164407831e-32 -1.2999695841456969e-48" />
    <parent link="Leg8_Femur_actuator_assembly_Femur" />
    <child link="Leg8_Knee_actuator_assembly_Motor" />
  </joint>
</robot>