<mujoco model="SpiderBody">
  <compiler angle="radian" eulerseq="XYZ" />
  <default>
    <geom contype="1" conaffinity="1" />
  </default>
  <visual>
    <global offwidth="1200" offheight="800" />
  </visual>
  <asset>
    <mesh name="Body" file="meshes/Body.stl" scale="0.001 0.001 0.001" />
    <mesh name="Leg1_Femur-actuator-assembly_Motor" file="meshes/Leg1_Femur-actuator-assembly_Motor.stl" scale="0.001 0.001 0.001" />
    <mesh name="Leg1_Femur-actuator-assembly_Femur" file="meshes/Leg1_Femur-actuator-assembly_Femur.stl" scale="0.001 0.001 0.001" />
    <mesh name="Leg1_Knee-actuator-assembly_Motor" file="meshes/Leg1_Knee-actuator-assembly_Motor.stl" scale="0.001 0.001 0.001" />
    <mesh name="Leg1_Knee-actuator-assembly_KneeMotorPulley" file="meshes/Leg1_Knee-actuator-assembly_KneeMotorPulley.stl" scale="0.001 0.001 0.001" />
    <mesh name="Leg1_Knee-actuator-assembly_Knee-motor-bearings" file="meshes/Leg1_Knee-actuator-assembly_Knee-motor-bearings.stl" scale="0.001 0.001 0.001" />
    <mesh name="Leg1_Knee-actuator-assembly_End-Bearing-Holder" file="meshes/Leg1_Knee-actuator-assembly_End-Bearing-Holder.stl" scale="0.001 0.001 0.001" />
    <mesh name="Leg1_Hip-actuator-assembly_Motor" file="meshes/Leg1_Hip-actuator-assembly_Motor.stl" scale="0.001 0.001 0.001" />
    <mesh name="Leg1_Hip-actuator-assembly_Hip-Bracket" file="meshes/Leg1_Hip-actuator-assembly_Hip-Bracket.stl" scale="0.001 0.001 0.001" />
    <mesh name="Leg1_Hip-actuator-assembly_Body-Bracket" file="meshes/Leg1_Hip-actuator-assembly_Body-Bracket.stl" scale="0.001 0.001 0.001" />
    <mesh name="Leg1_Tibia_Tibia-Full" file="meshes/Leg1_Tibia_Tibia-Full.stl" scale="0.001 0.001 0.001" />
    <mesh name="Leg1_Tibia_Tibia-Partial" file="meshes/Leg1_Tibia_Tibia-Partial.stl" scale="0.001 0.001 0.001" />
    <mesh name="Leg2_Femur-actuator-assembly_Motor" file="meshes/Leg2_Femur-actuator-assembly_Motor.stl" scale="0.001 0.001 0.001" />
    <mesh name="Leg2_Femur-actuator-assembly_Femur" file="meshes/Leg2_Femur-actuator-assembly_Femur.stl" scale="0.001 0.001 0.001" />
    <mesh name="Leg2_Knee-actuator-assembly_Motor" file="meshes/Leg2_Knee-actuator-assembly_Motor.stl" scale="0.001 0.001 0.001" />
    <mesh name="Leg2_Knee-actuator-assembly_KneeMotorPulley" file="meshes/Leg2_Knee-actuator-assembly_KneeMotorPulley.stl" scale="0.001 0.001 0.001" />
    <mesh name="Leg2_Knee-actuator-assembly_Knee-motor-bearings" file="meshes/Leg2_Knee-actuator-assembly_Knee-motor-bearings.stl" scale="0.001 0.001 0.001" />
    <mesh name="Leg2_Knee-actuator-assembly_End-Bearing-Holder" file="meshes/Leg2_Knee-actuator-assembly_End-Bearing-Holder.stl" scale="0.001 0.001 0.001" />
    <mesh name="Leg2_Hip-actuator-assembly_Motor" file="meshes/Leg2_Hip-actuator-assembly_Motor.stl" scale="0.001 0.001 0.001" />
    <mesh name="Leg2_Hip-actuator-assembly_Hip-Bracket" file="meshes/Leg2_Hip-actuator-assembly_Hip-Bracket.stl" scale="0.001 0.001 0.001" />
    <mesh name="Leg2_Hip-actuator-assembly_Body-Bracket" file="meshes/Leg2_Hip-actuator-assembly_Body-Bracket.stl" scale="0.001 0.001 0.001" />
    <mesh name="Leg2_Tibia_Tibia-Full" file="meshes/Leg2_Tibia_Tibia-Full.stl" scale="0.001 0.001 0.001" />
    <mesh name="Leg2_Tibia_Tibia-Partial" file="meshes/Leg2_Tibia_Tibia-Partial.stl" scale="0.001 0.001 0.001" />
    <mesh name="Leg3_Femur-actuator-assembly_Motor" file="meshes/Leg3_Femur-actuator-assembly_Motor.stl" scale="0.001 0.001 0.001" />
    <mesh name="Leg3_Femur-actuator-assembly_Femur" file="meshes/Leg3_Femur-actuator-assembly_Femur.stl" scale="0.001 0.001 0.001" />
    <mesh name="Leg3_Knee-actuator-assembly_Motor" file="meshes/Leg3_Knee-actuator-assembly_Motor.stl" scale="0.001 0.001 0.001" />
    <mesh name="Leg3_Knee-actuator-assembly_KneeMotorPulley" file="meshes/Leg3_Knee-actuator-assembly_KneeMotorPulley.stl" scale="0.001 0.001 0.001" />
    <mesh name="Leg3_Knee-actuator-assembly_Knee-motor-bearings" file="meshes/Leg3_Knee-actuator-assembly_Knee-motor-bearings.stl" scale="0.001 0.001 0.001" />
    <mesh name="Leg3_Knee-actuator-assembly_End-Bearing-Holder" file="meshes/Leg3_Knee-actuator-assembly_End-Bearing-Holder.stl" scale="0.001 0.001 0.001" />
    <mesh name="Leg3_Hip-actuator-assembly_Motor" file="meshes/Leg3_Hip-actuator-assembly_Motor.stl" scale="0.001 0.001 0.001" />
    <mesh name="Leg3_Hip-actuator-assembly_Hip-Bracket" file="meshes/Leg3_Hip-actuator-assembly_Hip-Bracket.stl" scale="0.001 0.001 0.001" />
    <mesh name="Leg3_Hip-actuator-assembly_Body-Bracket" file="meshes/Leg3_Hip-actuator-assembly_Body-Bracket.stl" scale="0.001 0.001 0.001" />
    <mesh name="Leg3_Tibia_Tibia-Full" file="meshes/Leg3_Tibia_Tibia-Full.stl" scale="0.001 0.001 0.001" />
    <mesh name="Leg3_Tibia_Tibia-Partial" file="meshes/Leg3_Tibia_Tibia-Partial.stl" scale="0.001 0.001 0.001" />
    <mesh name="Leg4_Femur-actuator-assembly_Motor" file="meshes/Leg4_Femur-actuator-assembly_Motor.stl" scale="0.001 0.001 0.001" />
    <mesh name="Leg4_Femur-actuator-assembly_Femur" file="meshes/Leg4_Femur-actuator-assembly_Femur.stl" scale="0.001 0.001 0.001" />
    <mesh name="Leg4_Knee-actuator-assembly_Motor" file="meshes/Leg4_Knee-actuator-assembly_Motor.stl" scale="0.001 0.001 0.001" />
    <mesh name="Leg4_Knee-actuator-assembly_KneeMotorPulley" file="meshes/Leg4_Knee-actuator-assembly_KneeMotorPulley.stl" scale="0.001 0.001 0.001" />
    <mesh name="Leg4_Knee-actuator-assembly_Knee-motor-bearings" file="meshes/Leg4_Knee-actuator-assembly_Knee-motor-bearings.stl" scale="0.001 0.001 0.001" />
    <mesh name="Leg4_Knee-actuator-assembly_End-Bearing-Holder" file="meshes/Leg4_Knee-actuator-assembly_End-Bearing-Holder.stl" scale="0.001 0.001 0.001" />
    <mesh name="Leg4_Hip-actuator-assembly_Motor" file="meshes/Leg4_Hip-actuator-assembly_Motor.stl" scale="0.001 0.001 0.001" />
    <mesh name="Leg4_Hip-actuator-assembly_Hip-Bracket" file="meshes/Leg4_Hip-actuator-assembly_Hip-Bracket.stl" scale="0.001 0.001 0.001" />
    <mesh name="Leg4_Hip-actuator-assembly_Body-Bracket" file="meshes/Leg4_Hip-actuator-assembly_Body-Bracket.stl" scale="0.001 0.001 0.001" />
    <mesh name="Leg4_Tibia_Tibia-Full" file="meshes/Leg4_Tibia_Tibia-Full.stl" scale="0.001 0.001 0.001" />
    <mesh name="Leg4_Tibia_Tibia-Partial" file="meshes/Leg4_Tibia_Tibia-Partial.stl" scale="0.001 0.001 0.001" />
    <mesh name="Leg5_Femur-actuator-assembly_Motor" file="meshes/Leg5_Femur-actuator-assembly_Motor.stl" scale="0.001 0.001 0.001" />
    <mesh name="Leg5_Femur-actuator-assembly_Femur" file="meshes/Leg5_Femur-actuator-assembly_Femur.stl" scale="0.001 0.001 0.001" />
    <mesh name="Leg5_Knee-actuator-assembly_Motor" file="meshes/Leg5_Knee-actuator-assembly_Motor.stl" scale="0.001 0.001 0.001" />
    <mesh name="Leg5_Knee-actuator-assembly_KneeMotorPulley" file="meshes/Leg5_Knee-actuator-assembly_KneeMotorPulley.stl" scale="0.001 0.001 0.001" />
    <mesh name="Leg5_Knee-actuator-assembly_Knee-motor-bearings" file="meshes/Leg5_Knee-actuator-assembly_Knee-motor-bearings.stl" scale="0.001 0.001 0.001" />
    <mesh name="Leg5_Knee-actuator-assembly_End-Bearing-Holder" file="meshes/Leg5_Knee-actuator-assembly_End-Bearing-Holder.stl" scale="0.001 0.001 0.001" />
    <mesh name="Leg5_Hip-actuator-assembly_Motor" file="meshes/Leg5_Hip-actuator-assembly_Motor.stl" scale="0.001 0.001 0.001" />
    <mesh name="Leg5_Hip-actuator-assembly_Hip-Bracket" file="meshes/Leg5_Hip-actuator-assembly_Hip-Bracket.stl" scale="0.001 0.001 0.001" />
    <mesh name="Leg5_Hip-actuator-assembly_Body-Bracket" file="meshes/Leg5_Hip-actuator-assembly_Body-Bracket.stl" scale="0.001 0.001 0.001" />
    <mesh name="Leg5_Tibia_Tibia-Full" file="meshes/Leg5_Tibia_Tibia-Full.stl" scale="0.001 0.001 0.001" />
    <mesh name="Leg5_Tibia_Tibia-Partial" file="meshes/Leg5_Tibia_Tibia-Partial.stl" scale="0.001 0.001 0.001" />
    <mesh name="Leg6_Femur-actuator-assembly_Motor" file="meshes/Leg6_Femur-actuator-assembly_Motor.stl" scale="0.001 0.001 0.001" />
    <mesh name="Leg6_Femur-actuator-assembly_Femur" file="meshes/Leg6_Femur-actuator-assembly_Femur.stl" scale="0.001 0.001 0.001" />
    <mesh name="Leg6_Knee-actuator-assembly_Motor" file="meshes/Leg6_Knee-actuator-assembly_Motor.stl" scale="0.001 0.001 0.001" />
    <mesh name="Leg6_Knee-actuator-assembly_KneeMotorPulley" file="meshes/Leg6_Knee-actuator-assembly_KneeMotorPulley.stl" scale="0.001 0.001 0.001" />
    <mesh name="Leg6_Knee-actuator-assembly_Knee-motor-bearings" file="meshes/Leg6_Knee-actuator-assembly_Knee-motor-bearings.stl" scale="0.001 0.001 0.001" />
    <mesh name="Leg6_Knee-actuator-assembly_End-Bearing-Holder" file="meshes/Leg6_Knee-actuator-assembly_End-Bearing-Holder.stl" scale="0.001 0.001 0.001" />
    <mesh name="Leg6_Hip-actuator-assembly_Motor" file="meshes/Leg6_Hip-actuator-assembly_Motor.stl" scale="0.001 0.001 0.001" />
    <mesh name="Leg6_Hip-actuator-assembly_Hip-Bracket" file="meshes/Leg6_Hip-actuator-assembly_Hip-Bracket.stl" scale="0.001 0.001 0.001" />
    <mesh name="Leg6_Hip-actuator-assembly_Body-Bracket" file="meshes/Leg6_Hip-actuator-assembly_Body-Bracket.stl" scale="0.001 0.001 0.001" />
    <mesh name="Leg6_Tibia_Tibia-Full" file="meshes/Leg6_Tibia_Tibia-Full.stl" scale="0.001 0.001 0.001" />
    <mesh name="Leg6_Tibia_Tibia-Partial" file="meshes/Leg6_Tibia_Tibia-Partial.stl" scale="0.001 0.001 0.001" />
    <mesh name="Leg7_Femur-actuator-assembly_Motor" file="meshes/Leg7_Femur-actuator-assembly_Motor.stl" scale="0.001 0.001 0.001" />
    <mesh name="Leg7_Femur-actuator-assembly_Femur" file="meshes/Leg7_Femur-actuator-assembly_Femur.stl" scale="0.001 0.001 0.001" />
    <mesh name="Leg7_Knee-actuator-assembly_Motor" file="meshes/Leg7_Knee-actuator-assembly_Motor.stl" scale="0.001 0.001 0.001" />
    <mesh name="Leg7_Knee-actuator-assembly_KneeMotorPulley" file="meshes/Leg7_Knee-actuator-assembly_KneeMotorPulley.stl" scale="0.001 0.001 0.001" />
    <mesh name="Leg7_Knee-actuator-assembly_Knee-motor-bearings" file="meshes/Leg7_Knee-actuator-assembly_Knee-motor-bearings.stl" scale="0.001 0.001 0.001" />
    <mesh name="Leg7_Knee-actuator-assembly_End-Bearing-Holder" file="meshes/Leg7_Knee-actuator-assembly_End-Bearing-Holder.stl" scale="0.001 0.001 0.001" />
    <mesh name="Leg7_Hip-actuator-assembly_Motor" file="meshes/Leg7_Hip-actuator-assembly_Motor.stl" scale="0.001 0.001 0.001" />
    <mesh name="Leg7_Hip-actuator-assembly_Hip-Bracket" file="meshes/Leg7_Hip-actuator-assembly_Hip-Bracket.stl" scale="0.001 0.001 0.001" />
    <mesh name="Leg7_Hip-actuator-assembly_Body-Bracket" file="meshes/Leg7_Hip-actuator-assembly_Body-Bracket.stl" scale="0.001 0.001 0.001" />
    <mesh name="Leg7_Tibia_Tibia-Full" file="meshes/Leg7_Tibia_Tibia-Full.stl" scale="0.001 0.001 0.001" />
    <mesh name="Leg7_Tibia_Tibia-Partial" file="meshes/Leg7_Tibia_Tibia-Partial.stl" scale="0.001 0.001 0.001" />
    <mesh name="Leg8_Femur-actuator-assembly_Motor" file="meshes/Leg8_Femur-actuator-assembly_Motor.stl" scale="0.001 0.001 0.001" />
    <mesh name="Leg8_Femur-actuator-assembly_Femur" file="meshes/Leg8_Femur-actuator-assembly_Femur.stl" scale="0.001 0.001 0.001" />
    <mesh name="Leg8_Knee-actuator-assembly_Motor" file="meshes/Leg8_Knee-actuator-assembly_Motor.stl" scale="0.001 0.001 0.001" />
    <mesh name="Leg8_Knee-actuator-assembly_KneeMotorPulley" file="meshes/Leg8_Knee-actuator-assembly_KneeMotorPulley.stl" scale="0.001 0.001 0.001" />
    <mesh name="Leg8_Knee-actuator-assembly_Knee-motor-bearings" file="meshes/Leg8_Knee-actuator-assembly_Knee-motor-bearings.stl" scale="0.001 0.001 0.001" />
    <mesh name="Leg8_Knee-actuator-assembly_End-Bearing-Holder" file="meshes/Leg8_Knee-actuator-assembly_End-Bearing-Holder.stl" scale="0.001 0.001 0.001" />
    <mesh name="Leg8_Hip-actuator-assembly_Motor" file="meshes/Leg8_Hip-actuator-assembly_Motor.stl" scale="0.001 0.001 0.001" />
    <mesh name="Leg8_Hip-actuator-assembly_Hip-Bracket" file="meshes/Leg8_Hip-actuator-assembly_Hip-Bracket.stl" scale="0.001 0.001 0.001" />
    <mesh name="Leg8_Hip-actuator-assembly_Body-Bracket" file="meshes/Leg8_Hip-actuator-assembly_Body-Bracket.stl" scale="0.001 0.001 0.001" />
    <mesh name="Leg8_Tibia_Tibia-Full" file="meshes/Leg8_Tibia_Tibia-Full.stl" scale="0.001 0.001 0.001" />
    <mesh name="Leg8_Tibia_Tibia-Partial" file="meshes/Leg8_Tibia_Tibia-Partial.stl" scale="0.001 0.001 0.001" />
    <texture type="2d" name="groundplane" builtin="checker" mark="edge" rgb1="0.2 0.3 0.4" rgb2="0.1 0.2 0.3" markrgb="0.8 0.8 0.8" width="300" height="300" />
    <material name="groundplane" texture="groundplane" texuniform="true" texrepeat="5 5" reflectance="0.2" />
  </asset>
  <worldbody>
    <geom name="floor" size="40 40 40" type="plane" material="groundplane" contype="1" conaffinity="1" />
    <light directional="true" pos="-0.5 0.5 3" dir="0 0 -1" />
    <body name="Body" pos="0.0 0.0 0.134" euler="0.0 -0.0 0.0">
      <joint name="root" type="free" pos="0 0 0" armature="0" damping="0" limited="false" margin="0.01" />
      <camera name="bodycam" mode="targetbodycom" target="Body" pos="-0.817 -1.628 0.6" />
      <camera name="groundcam" mode="targetbodycom" target="Body" pos="-1.0 0 0.1" />

      <site name="imu_site" pos="0.24115 0 0" size="0.01" />
      <geom name="head" pos="0.49 0 0.015" size="0.025" type="sphere" rgba="0 1 0 1" />
      <geom name="Body_geom" type="mesh" mesh="Body" pos="0 0 0" euler="0 0 0" />
      <inertial mass="2.567558330651746" pos="0.2412000000000002 1.7296168291426336e-18 0.004854024896265552" fullinertia="0.01262901309898984 0.05067644480183947 0.06301756012942178 1.0711431741583518e-18 2.168404344971009e-18 -1.1167056214726778e-19" />
      <body name="Leg1_Hip-actuator-assembly_Body-Bracket" pos="0.5300789975772281 0.10561612341601537 -0.02862177809359275" euler="-1.5707963267948966 -2.078232164254877e-46 -1.5707963267948968">
        <geom name="Leg1_Hip-actuator-assembly_Body-Bracket_geom" type="mesh" mesh="Leg1_Hip-actuator-assembly_Body-Bracket" pos="0 0 0" euler="0 0 0" />
        <inertial mass="0.2737560132535958" pos="0.046780909281849185 -0.03304651659344973 -0.0824789745791283" fullinertia="0.00020548953826175976 0.0003078575243544244 0.00011826659575640263 9.18527627607933e-08 -3.8625346667689653e-10 -6.214987801741575e-11" />
        <body name="Leg1_Hip-actuator-assembly_Motor" pos="0.05236612341601522 -0.013371778093595157 -0.08247899241251176" euler="5.669937756276022e-31 -1.061584664946281e-30 1.5707963267948966">
          <geom name="Leg1_Hip-actuator-assembly_Motor_geom" type="mesh" mesh="Leg1_Hip-actuator-assembly_Motor" pos="0 0 0" euler="0 0 0" />
          <inertial mass="0.3028214126901055" pos="0.013799107411403501 0.0002445449923600619 0.0001665011404277553" fullinertia="0.00023174021267842747 0.00013815228212788833 0.00014141746037829735 1.799485937690842e-07 1.0525676781229182e-06 5.361526010573221e-08" />
          <body name="Leg1_Hip-actuator-assembly_Hip-Bracket" pos="0.012250000000002446 0.09499999999999954 0.040000000000002416" euler="-1.5707963267948966 1.5707963267948966 0">
            <joint name="Leg1_Hip" type="hinge" axis="1.044698303301379e-30 -1.0000000000000029 2.0382828214422557e-16" pos="0.04000000516471871 -0.017249999999999977 -0.09500000000000068" range="-0.3 1.570796" limited="true" />
            <geom name="Leg1_Hip-actuator-assembly_Hip-Bracket_geom" type="mesh" mesh="Leg1_Hip-actuator-assembly_Hip-Bracket" pos="0 0 0" euler="0 0 0" />
            <inertial mass="0.05792781115933178" pos="0.041243788161782514 -0.009686640073078253 -0.05405434309768331" fullinertia="9.85838062971938e-05 0.00010067920230327995 5.26474646563654e-05 4.054417809776247e-06 -1.4243321119437283e-06 1.531754993366378e-05" />
            <body name="Leg1_Femur-actuator-assembly_Motor" pos="-7.105427357601002e-17 -2.886579864025407e-16 -1.9539925233402755e-16" euler="-1.4835298641951802 1.2301127401794757e-16 -2.848511181556418e-20">
              <geom name="Leg1_Femur-actuator-assembly_Motor_geom" type="mesh" mesh="Leg1_Femur-actuator-assembly_Motor" pos="0 0 0" euler="0 0 0" />
              <inertial mass="0.3028214126901055" pos="0.013799107411403387 0.0002445449923600398 0.00016650114042775498" fullinertia="0.00023174021267842563 0.00013815228212787426 0.000141417460378303 1.7994859376945436e-07 1.0525676781241184e-06 5.3615260105584865e-08" />
              <body name="Leg1_Femur-actuator-assembly_Femur" pos="0.0 1.5987211554602254e-16 2.220446049250313e-18" euler="1.4835298641951802 -9.213561862185276e-18 -1.0465783018494714e-16">
                <joint name="Leg1_Femur" type="hinge" axis="1.0000000000000022 -2.848544170504046e-20 -5.3875665748200195e-17" pos="0.02950000516471869 3.6429108963445334e-16 1.0943297004469161e-16" range="-0.785398 1.832596" limited="true" />
                <geom name="Leg1_Femur-actuator-assembly_Femur_geom" type="mesh" mesh="Leg1_Femur-actuator-assembly_Femur" pos="0 0 0" euler="0 0 0" />
                <inertial mass="0.06743801039317165" pos="0.039161077868577525 0.03222905940208431 0.02039616263196659" fullinertia="0.0002477420639114133 9.247070534670079e-05 0.0001640171182383209 -1.8168414869322653e-06 -1.1512909002669982e-06 -8.763800429865387e-05" />
                <body name="Leg1_Tibia_Tibia-Full" pos="-7.105427357601002e-17 0.01965999558828654 0.018992913719242655" euler="4.930380657631325e-32 4.9303806524363403e-32 -2.848568968151033e-20">
                  <joint name="Leg1_Tibia" type="hinge" axis="-1.0000000000000022 -2.4799724658473147e-25 5.3875665748200146e-17" pos="0.03300000516471871 0.10761700441171412 0.07292908628075771" range="-1.047198 1.570796" limited="true" />
                  <geom name="Leg1_Tibia_Tibia-Full_geom" type="mesh" mesh="Leg1_Tibia_Tibia-Full" pos="0 0 0" euler="0 0 0" />
                  <inertial mass="0.5325920058039666" pos="0.03903387077261382 0.0025357289803729006 0.157455047889404" fullinertia="0.003029413276509664 0.0008274226390222517 0.0022188878881804425 4.086753975669457e-05 -2.9640896882607377e-05 0.0012309838645819656" />
                  <body name="Leg1_Tibia_Tibia-Partial" pos="-7.105427357601002e-17 3.552713678800501e-17 7.105427357601002e-17" euler="2.4651903288156624e-32 -2.1629170918652414e-46 2.4797514612865137e-25">
                    <geom name="Leg1_Tibia_Tibia-Partial_geom" type="mesh" mesh="Leg1_Tibia_Tibia-Partial" pos="0 0 0" euler="0 0 0" />
                    <inertial mass="0.04268806780866727" pos="0.04302588971407911 0.09756567365453613 0.08371692150453562" fullinertia="3.765972186276742e-05 1.957061285260733e-05 1.8372073814611717e-05 3.177520329347394e-07 -3.0109774704859846e-07 1.5137133715213636e-05" />
                  </body>
                  <site name="Leg1_Tibia_bad_touch1_site" pos="0.04 0.048 0.148" size="0.005" type="sphere" rgba="1 0 0 1" />
                  <geom name="Leg1_Tibia_bad_touch1_site" pos="0.04 0.048 0.148" size="0.005" type="sphere" rgba="1 0 0 1" />
                  <site name="Leg1_Tibia_bad_touch2_site" pos="0.04 -0.05 0.195" size="0.005" type="sphere" rgba="1 0 0 1" />
                  <geom name="Leg1_Tibia_bad_touch2_site" pos="0.04 -0.05 0.195" size="0.005" type="sphere" rgba="1 0 0 1" />
                  <site name="Leg1_Tibia_foot_site" pos="0.04 -0.1195 0.2018" size="0.007 0.005" type="cylinder" rgba="0 1 0 1" euler="0 1.5708 0" />
                  <geom name="Leg1_Tibia_foot_site" pos="0.04 -0.1195 0.2018" size="0.007 0.005" type="cylinder" rgba="0 1 0 1" euler="0 1.5708 0" friction="2.0 0.1 0.01" />
                </body>
                <body name="Leg1_Knee-actuator-assembly_Motor" pos="0.0765000000000036 -3.552713678800501e-17 0.0" euler="-0.0820304748437336 -1.3034353007344026e-16 3.141592653589792">
                  <geom name="Leg1_Knee-actuator-assembly_Motor_geom" type="mesh" mesh="Leg1_Knee-actuator-assembly_Motor" pos="0 0 0" euler="0 0 0" />
                  <inertial mass="0.3028214126901055" pos="0.013799107411403487 0.0002445449923600579 0.00016650114042775625" fullinertia="0.00023174021267842666 0.00013815228212789144 0.00014141746037830708 1.799485937687502e-07 1.052567678123221e-06 5.3615260104876745e-08" />
                  <body name="Leg1_Knee-actuator-assembly_Knee-motor-bearings" pos="0.11894493236997257 -0.013337526072353889 -0.040499725337706176" euler="-1.5707963267948981 1.178097245096173 -1.5707963267948972">
                    <geom name="Leg1_Knee-actuator-assembly_Knee-motor-bearings_geom" type="mesh" mesh="Leg1_Knee-actuator-assembly_Knee-motor-bearings" pos="0 0 0" euler="0 0 0" />
                    <inertial mass="0.009270686219329867" pos="-0.042575332613045816 -0.0031217780936082136 -0.12080177571379892" fullinertia="6.4084718495850655e-06 6.4084718496545765e-06 1.275054794519867e-05 -3.6367359590363385e-18 -1.8060653865657466e-19 1.0650317937702857e-19" />
                  </body>
                  <body name="Leg1_Knee-actuator-assembly_KneeMotorPulley" pos="0.04100000000000236 -0.033041575943744336 -0.01971490744865175" euler="1.5707963267948966 5.3805566485503884e-20 -3.141592653589793">
                    <geom name="Leg1_Knee-actuator-assembly_KneeMotorPulley_geom" type="mesh" mesh="Leg1_Knee-actuator-assembly_KneeMotorPulley" pos="0 0 0" euler="0 0 0" />
                    <inertial mass="0.08135375942547957" pos="0.005405704726782252 0.019714907448618903 0.033041575943703556" fullinertia="1.2462648308958848e-05 7.261200035422354e-06 7.261200035848472e-06 -2.983900692300092e-18 -4.548903064848449e-18 -2.674364652936788e-16" />
                  </body>
                </body>
              </body>
            </body>
            <body name="Leg1_Knee-actuator-assembly_End-Bearing-Holder" pos="-0.04244493236996938 -0.0031217780935925135 -0.042575332613041326" euler="3.141592653589793 1.5707963267948966 0">
              <geom name="Leg1_Knee-actuator-assembly_End-Bearing-Holder_geom" type="mesh" mesh="Leg1_Knee-actuator-assembly_End-Bearing-Holder" pos="0 0 0" euler="0 0 0" />
              <inertial mass="0.057169625310268736" pos="-0.04109062630262349 -0.001108467278132863 -0.12254015277022076" fullinertia="5.196194176609584e-05 5.1347634596559825e-05 0.00010281021554763191 -9.985502905468006e-07 -1.0829253630980598e-08 -1.1711751146800545e-08" />
            </body>
          </body>
        </body>
      </body>
      <body name="Leg2_Hip-actuator-assembly_Body-Bracket" pos="0.39247899757722804 0.17001612341601535 -0.02862177809359275" euler="-1.5707963267948966 -2.078232164254877e-46 -1.5707963267948968">
        <geom name="Leg2_Hip-actuator-assembly_Body-Bracket_geom" type="mesh" mesh="Leg2_Hip-actuator-assembly_Body-Bracket" pos="0 0 0" euler="0 0 0" />
        <inertial mass="0.2737560132535958" pos="0.0467809092818492 -0.03304651659344973 -0.0824789745791283" fullinertia="0.00020548953826175976 0.00030785752435441745 0.00011826659575640188 9.18527627607933e-08 -3.8625346841162e-10 -6.214987796320564e-11" />
        <body name="Leg2_Hip-actuator-assembly_Motor" pos="0.052366123416015216 -0.013371778093595157 -0.08247899241251187" euler="5.669937756276022e-31 -1.061584664946281e-30 1.5707963267948966">
          <geom name="Leg2_Hip-actuator-assembly_Motor_geom" type="mesh" mesh="Leg2_Hip-actuator-assembly_Motor" pos="0 0 0" euler="0 0 0" />
          <inertial mass="0.3028214126901055" pos="0.013799107411403501 0.0002445449923600619 0.0001665011404277553" fullinertia="0.00023174021267842747 0.0001381522821278814 0.00014141746037829648 1.799485937689758e-07 1.0525676781242192e-06 5.361526010486485e-08" />
          <body name="Leg2_Hip-actuator-assembly_Hip-Bracket" pos="0.012250000000002443 0.09499999999999954 0.04000000000000238" euler="-1.5707963267948966 1.5707963267948966 0">
            <joint name="Leg2_Hip" type="hinge" axis="1.044698303301379e-30 -1.0000000000000029 2.0382828214422557e-16" pos="0.040000005164718654 -0.017249999999999977 -0.09500000000000065" range="-0.7 1.2" limited="true" />
            <geom name="Leg2_Hip-actuator-assembly_Hip-Bracket_geom" type="mesh" mesh="Leg2_Hip-actuator-assembly_Hip-Bracket" pos="0 0 0" euler="0 0 0" />
            <inertial mass="0.05792781115933178" pos="0.04124378816178259 -0.009686640073078253 -0.05405434309768333" fullinertia="9.858380629719369e-05 0.00010067920230328255 5.264746465636887e-05 4.05441780977603e-06 -1.4243321119432946e-06 1.5317549933663755e-05" />
            <body name="Leg2_Femur-actuator-assembly_Motor" pos="0.0 -2.886579864025407e-16 -1.7763568394002506e-16" euler="-1.4835298641951802 1.2301127401794757e-16 -2.848511181556418e-20">
              <geom name="Leg2_Femur-actuator-assembly_Motor_geom" type="mesh" mesh="Leg2_Femur-actuator-assembly_Motor" pos="0 0 0" euler="0 0 0" />
              <inertial mass="0.3028214126901055" pos="0.013799107411403387 0.0002445449923600575 0.00016650114042775343" fullinertia="0.00023174021267842216 0.00013815228212787418 0.00014141746037829616 1.7994859377298617e-07 1.0525676781246802e-06 5.361526010477002e-08" />
              <body name="Leg2_Femur-actuator-assembly_Femur" pos="0.0 1.0658141036401502e-16 1.1102230246251566e-18" euler="1.4835298641951802 -9.213561862185276e-18 -1.0465783018494714e-16">
                <joint name="Leg2_Femur" type="hinge" axis="1.0000000000000022 -2.848544170504046e-20 -5.3875665748200195e-17" pos="0.029500005164718634 3.6429108963445334e-16 1.3718854566032069e-16" range="-0.785398 1.832596" limited="true" />
                <geom name="Leg2_Femur-actuator-assembly_Femur_geom" type="mesh" mesh="Leg2_Femur-actuator-assembly_Femur" pos="0 0 0" euler="0 0 0" />
                <inertial mass="0.06743801039317165" pos="0.039161077868577525 0.03222905940208431 0.02039616263196659" fullinertia="0.0002477420639114137 9.247070534669906e-05 0.00016401711823831917 -1.8168414869322382e-06 -1.1512909002652635e-06 -8.763800429865386e-05" />
                <body name="Leg2_Tibia_Tibia-Full" pos="0.0 0.01965999558828654 0.018992913719242638" euler="4.930380657631325e-32 4.9303806524363403e-32 -2.848568968151033e-20">
                  <joint name="Leg2_Tibia" type="hinge" axis="-1.0000000000000022 -2.4799724658473147e-25 5.3875665748200146e-17" pos="0.033000005164718654 0.10761700441171412 0.07292908628075774" range="-1.047198 1.570796" limited="true" />
                  <geom name="Leg2_Tibia_Tibia-Full_geom" type="mesh" mesh="Leg2_Tibia_Tibia-Full" pos="0 0 0" euler="0 0 0" />
                  <inertial mass="0.5325920058039666" pos="0.03903387077261382 0.0025357289803729006 0.157455047889404" fullinertia="0.003029413276509685 0.0008274226390222517 0.002218887888180408 4.0867539756694676e-05 -2.9640896882607377e-05 0.0012309838645819659" />
                  <body name="Leg2_Tibia_Tibia-Partial" pos="0.0 3.552713678800501e-17 7.105427357601002e-17" euler="2.4651903288156624e-32 -2.1629170918652414e-46 2.4797514612865137e-25">
                    <geom name="Leg2_Tibia_Tibia-Partial_geom" type="mesh" mesh="Leg2_Tibia_Tibia-Partial" pos="0 0 0" euler="0 0 0" />
                    <inertial mass="0.04268806780866727" pos="0.04302588971407915 0.09756567365453613 0.08371692150453562" fullinertia="3.765972186276829e-05 1.95706128526108e-05 1.837207381461345e-05 3.177520329347394e-07 -3.0109774704859846e-07 1.513713371521342e-05" />
                  </body>
                  <site name="Leg2_Tibia_bad_touch1_site" pos="0.04 0.048 0.148" size="0.005" type="sphere" rgba="1 0 0 1" />
                  <geom name="Leg2_Tibia_bad_touch1_site" pos="0.04 0.048 0.148" size="0.005" type="sphere" rgba="1 0 0 1" />
                  <site name="Leg2_Tibia_bad_touch2_site" pos="0.04 -0.05 0.195" size="0.005" type="sphere" rgba="1 0 0 1" />
                  <geom name="Leg2_Tibia_bad_touch2_site" pos="0.04 -0.05 0.195" size="0.005" type="sphere" rgba="1 0 0 1" />
                  <site name="Leg2_Tibia_foot_site" pos="0.04 -0.1195 0.2018" size="0.007 0.005" type="cylinder" rgba="0 1 0 1" euler="0 1.5708 0" />
                  <geom name="Leg2_Tibia_foot_site" pos="0.04 -0.1195 0.2018" size="0.007 0.005" type="cylinder" rgba="0 1 0 1" euler="0 1.5708 0" friction="2.0 0.1 0.01" />
                </body>
                <body name="Leg2_Knee-actuator-assembly_Motor" pos="0.07650000000000365 -3.552713678800501e-17 0.0" euler="-0.0820304748437336 -1.3034353007344026e-16 3.141592653589792">
                  <geom name="Leg2_Knee-actuator-assembly_Motor_geom" type="mesh" mesh="Leg2_Knee-actuator-assembly_Motor" pos="0 0 0" euler="0 0 0" />
                  <inertial mass="0.3028214126901055" pos="0.013799107411403487 0.0002445449923600579 0.00016650114042775625" fullinertia="0.00023174021267842666 0.00013815228212788456 0.00014141746037830012 1.7994859376933035e-07 1.05256767812675e-06 5.361526010466329e-08" />
                  <body name="Leg2_Knee-actuator-assembly_Knee-motor-bearings" pos="0.1189449323699726 -0.013337526072353889 -0.040499725337706176" euler="-1.5707963267948981 1.178097245096173 -1.5707963267948972">
                    <geom name="Leg2_Knee-actuator-assembly_Knee-motor-bearings_geom" type="mesh" mesh="Leg2_Knee-actuator-assembly_Knee-motor-bearings" pos="0 0 0" euler="0 0 0" />
                    <inertial mass="0.009270686219329867" pos="-0.042575332613045816 -0.0031217780936082136 -0.12080177571379899" fullinertia="6.408471849585739e-06 6.408471849655205e-06 1.275054794519867e-05 -3.652406068560543e-18 2.4644558315639314e-20 1.815128133839956e-19" />
                  </body>
                  <body name="Leg2_Knee-actuator-assembly_KneeMotorPulley" pos="0.04100000000000236 -0.033041575943744336 -0.019714907448651717" euler="1.5707963267948966 5.3805566485503884e-20 -3.141592653589793">
                    <geom name="Leg2_Knee-actuator-assembly_KneeMotorPulley_geom" type="mesh" mesh="Leg2_Knee-actuator-assembly_KneeMotorPulley" pos="0 0 0" euler="0 0 0" />
                    <inertial mass="0.08135375942547957" pos="0.005405704726782288 0.019714907448618885 0.033041575943703556" fullinertia="1.2462648308958631e-05 7.261200035422366e-06 7.261200035850195e-06 -2.9661331104867094e-18 -4.332791780854766e-18 -2.6729479903325054e-16" />
                  </body>
                </body>
              </body>
            </body>
            <body name="Leg2_Knee-actuator-assembly_End-Bearing-Holder" pos="-0.04244493236996938 -0.0031217780935925135 -0.04257533261304136" euler="3.141592653589793 1.5707963267948966 0">
              <geom name="Leg2_Knee-actuator-assembly_End-Bearing-Holder_geom" type="mesh" mesh="Leg2_Knee-actuator-assembly_End-Bearing-Holder" pos="0 0 0" euler="0 0 0" />
              <inertial mass="0.057169625310268736" pos="-0.04109062630262349 -0.001108467278132863 -0.12254015277022076" fullinertia="5.1961941766096706e-05 5.134763459656156e-05 0.00010281021554763234 -9.985502905468548e-07 -1.0829253630113236e-08 -1.1711751146800545e-08" />
            </body>
          </body>
        </body>
      </body>
      <body name="Leg3_Hip-actuator-assembly_Body-Bracket" pos="0.2548789975772281 0.17001612341601535 -0.02862177809359275" euler="-1.5707963267948966 -2.078232164254877e-46 -1.5707963267948968">
        <geom name="Leg3_Hip-actuator-assembly_Body-Bracket_geom" type="mesh" mesh="Leg3_Hip-actuator-assembly_Body-Bracket" pos="0 0 0" euler="0 0 0" />
        <inertial mass="0.2737560132535958" pos="0.0467809092818492 -0.03304651659344973 -0.0824789745791283" fullinertia="0.00020548953826174935 0.000307857524354414 0.00011826659575640188 9.18527627607933e-08 -3.8625346754425827e-10 -6.214987780057532e-11" />
        <body name="Leg3_Hip-actuator-assembly_Motor" pos="0.052366123416015216 -0.013371778093595157 -0.08247899241251183" euler="5.669937756276022e-31 -1.061584664946281e-30 1.5707963267948966">
          <geom name="Leg3_Hip-actuator-assembly_Motor_geom" type="mesh" mesh="Leg3_Hip-actuator-assembly_Motor" pos="0 0 0" euler="0 0 0" />
          <inertial mass="0.3028214126901055" pos="0.013799107411403501 0.0002445449923600619 0.0001665011404277553" fullinertia="0.00023174021267843094 0.00013815228212788312 0.00014141746037829648 1.799485937689758e-07 1.0525676781242192e-06 5.361526010573221e-08" />
          <body name="Leg3_Hip-actuator-assembly_Hip-Bracket" pos="0.012250000000002443 0.09499999999999954 0.04000000000000245" euler="-1.5707963267948966 1.5707963267948966 0">
            <joint name="Leg3_Hip" type="hinge" axis="1.044698303301379e-30 -1.0000000000000029 2.0382828214422557e-16" pos="0.04000000516471868 -0.017249999999999977 -0.09500000000000065" range="-1.2 0.6" limited="true" />
            <geom name="Leg3_Hip-actuator-assembly_Hip-Bracket_geom" type="mesh" mesh="Leg3_Hip-actuator-assembly_Hip-Bracket" pos="0 0 0" euler="0 0 0" />
            <inertial mass="0.05792781115933178" pos="0.041243788161782556 -0.009686640073078253 -0.05405434309768333" fullinertia="9.858380629719369e-05 0.00010067920230328299 5.2647464656367784e-05 4.054417809776192e-06 -1.4243321119437283e-06 1.5317549933663755e-05" />
            <body name="Leg3_Femur-actuator-assembly_Motor" pos="-3.552713678800501e-17 -2.886579864025407e-16 -1.7763568394002506e-16" euler="-1.4835298641951802 1.2301127401794757e-16 -2.848511181556418e-20">
              <geom name="Leg3_Femur-actuator-assembly_Motor_geom" type="mesh" mesh="Leg3_Femur-actuator-assembly_Motor" pos="0 0 0" euler="0 0 0" />
              <inertial mass="0.3028214126901055" pos="0.013799107411403421 0.0002445449923600575 0.00016650114042775343" fullinertia="0.00023174021267842216 0.00013815228212788453 0.00014141746037829624 1.79948593766017e-07 1.0525676781246368e-06 5.361526010386539e-08" />
              <body name="Leg3_Femur-actuator-assembly_Femur" pos="-3.552713678800501e-17 1.0658141036401502e-16 1.1102230246251566e-18" euler="1.4835298641951802 -9.213561862185276e-18 -1.0465783018494714e-16">
                <joint name="Leg3_Femur" type="hinge" axis="1.0000000000000022 -2.848544170504046e-20 -5.3875665748200195e-17" pos="0.02950000516471866 3.6429108963445334e-16 1.3718854566032066e-16" range="-0.785398 1.832596" limited="true" />
                <geom name="Leg3_Femur-actuator-assembly_Femur_geom" type="mesh" mesh="Leg3_Femur-actuator-assembly_Femur" pos="0 0 0" euler="0 0 0" />
                <inertial mass="0.06743801039317165" pos="0.039161077868577455 0.03222905940208431 0.02039616263196659" fullinertia="0.0002477420639114137 9.247070534669819e-05 0.00016401711823831744 -1.8168414869322653e-06 -1.151290900267432e-06 -8.763800429865386e-05" />
                <body name="Leg3_Tibia_Tibia-Full" pos="0.0 0.01965999558828654 0.018992913719242638" euler="4.930380657631325e-32 4.9303806524363403e-32 -2.848568968151033e-20">
                  <joint name="Leg3_Tibia" type="hinge" axis="-1.0000000000000022 -2.4799724658473147e-25 5.3875665748200146e-17" pos="0.03300000516471868 0.10761700441171412 0.07292908628075774" range="-1.047198 1.570796" limited="true" />
                  <geom name="Leg3_Tibia_Tibia-Full_geom" type="mesh" mesh="Leg3_Tibia_Tibia-Full" pos="0 0 0" euler="0 0 0" />
                  <inertial mass="0.5325920058039666" pos="0.03903387077261382 0.0025357289803729006 0.157455047889404" fullinertia="0.003029413276509685 0.0008274226390222517 0.0022188878881803974 4.086753975669457e-05 -2.9640896882614316e-05 0.0012309838645819659" />
                  <body name="Leg3_Tibia_Tibia-Partial" pos="3.552713678800501e-17 3.552713678800501e-17 7.105427357601002e-17" euler="2.4651903288156624e-32 -2.1629170918652414e-46 2.4797514612865137e-25">
                    <geom name="Leg3_Tibia_Tibia-Partial_geom" type="mesh" mesh="Leg3_Tibia_Tibia-Partial" pos="0 0 0" euler="0 0 0" />
                    <inertial mass="0.04268806780866727" pos="0.04302588971407915 0.09756567365453613 0.08371692150453562" fullinertia="3.765972186276829e-05 1.95706128526108e-05 1.8372073814613018e-05 3.1775203293452257e-07 -3.010977470481648e-07 1.513713371521342e-05" />
                  </body>
                  <site name="Leg3_Tibia_bad_touch1_site" pos="0.04 0.048 0.148" size="0.005" type="sphere" rgba="1 0 0 1" />
                  <geom name="Leg3_Tibia_bad_touch1_site" pos="0.04 0.048 0.148" size="0.005" type="sphere" rgba="1 0 0 1" />
                  <site name="Leg3_Tibia_bad_touch2_site" pos="0.04 -0.05 0.195" size="0.005" type="sphere" rgba="1 0 0 1" />
                  <geom name="Leg3_Tibia_bad_touch2_site" pos="0.04 -0.05 0.195" size="0.005" type="sphere" rgba="1 0 0 1" />
                  <site name="Leg3_Tibia_foot_site" pos="0.04 -0.1195 0.2018" size="0.007 0.005" type="cylinder" rgba="0 1 0 1" euler="0 1.5708 0" />
                  <geom name="Leg3_Tibia_foot_site" pos="0.04 -0.1195 0.2018" size="0.007 0.005" type="cylinder" rgba="0 1 0 1" euler="0 1.5708 0" friction="2.0 0.1 0.01" />
                </body>
                <body name="Leg3_Knee-actuator-assembly_Motor" pos="0.07650000000000368 -3.552713678800501e-17 0.0" euler="-0.0820304748437336 -1.3034353007344026e-16 3.141592653589792">
                  <geom name="Leg3_Knee-actuator-assembly_Motor_geom" type="mesh" mesh="Leg3_Knee-actuator-assembly_Motor" pos="0 0 0" euler="0 0 0" />
                  <inertial mass="0.3028214126901055" pos="0.013799107411403451 0.0002445449923600579 0.00016650114042775625" fullinertia="0.00023174021267842666 0.0001381522821278811 0.00014141746037829662 1.799485937688981e-07 1.0525676781267144e-06 5.36152601046616e-08" />
                  <body name="Leg3_Knee-actuator-assembly_Knee-motor-bearings" pos="0.11894493236997261 -0.013337526072353889 -0.04049972533770621" euler="-1.5707963267948981 1.178097245096173 -1.5707963267948972">
                    <geom name="Leg3_Knee-actuator-assembly_Knee-motor-bearings_geom" type="mesh" mesh="Leg3_Knee-actuator-assembly_Knee-motor-bearings" pos="0 0 0" euler="0 0 0" />
                    <inertial mass="0.009270686219329867" pos="-0.042575332613045816 -0.0031217780936082136 -0.12080177571379896" fullinertia="6.408471849585371e-06 6.40847184965495e-06 1.275054794519867e-05 -3.7294860667606844e-18 6.356766841980093e-20 2.243729009899024e-19" />
                  </body>
                  <body name="Leg3_Knee-actuator-assembly_KneeMotorPulley" pos="0.041000000000002375 -0.033041575943744336 -0.019714907448651717" euler="1.5707963267948966 5.3805566485503884e-20 -3.141592653589793">
                    <geom name="Leg3_Knee-actuator-assembly_KneeMotorPulley_geom" type="mesh" mesh="Leg3_Knee-actuator-assembly_KneeMotorPulley" pos="0 0 0" euler="0 0 0" />
                    <inertial mass="0.08135375942547957" pos="0.005405704726782288 0.019714907448618885 0.033041575943703556" fullinertia="1.2462648308958631e-05 7.261200035422796e-06 7.261200035850198e-06 -2.5339105424993496e-18 -4.368326944481532e-18 -2.673301626587984e-16" />
                  </body>
                </body>
              </body>
            </body>
            <body name="Leg3_Knee-actuator-assembly_End-Bearing-Holder" pos="-0.04244493236996938 -0.0031217780935925135 -0.04257533261304136" euler="3.141592653589793 1.5707963267948966 0">
              <geom name="Leg3_Knee-actuator-assembly_End-Bearing-Holder_geom" type="mesh" mesh="Leg3_Knee-actuator-assembly_End-Bearing-Holder" pos="0 0 0" euler="0 0 0" />
              <inertial mass="0.057169625310268736" pos="-0.04109062630262349 -0.001108467278132863 -0.12254015277022076" fullinertia="5.196194176609736e-05 5.134763459656069e-05 0.00010281021554763234 -9.985502905468548e-07 -1.0829253630546917e-08 -1.1711751146854755e-08" />
            </body>
          </body>
        </body>
      </body>
      <body name="Leg4_Hip-actuator-assembly_Body-Bracket" pos="0.1172789975772281 0.10561612341601537 -0.02862177809359275" euler="-1.5707963267948966 -2.078232164254877e-46 -1.5707963267948968">
        <geom name="Leg4_Hip-actuator-assembly_Body-Bracket_geom" type="mesh" mesh="Leg4_Hip-actuator-assembly_Body-Bracket" pos="0 0 0" euler="0 0 0" />
        <inertial mass="0.2737560132535958" pos="0.046780909281849185 -0.03304651659344973 -0.08247897457912827" fullinertia="0.00020548953826174518 0.0003078575243544105 0.00011826659575640263 9.18527627607933e-08 -3.8625346873688066e-10 -6.214987801741575e-11" />
        <body name="Leg4_Hip-actuator-assembly_Motor" pos="0.05236612341601523 -0.013371778093595157 -0.08247899241251178" euler="5.669937756276022e-31 -1.061584664946281e-30 1.5707963267948966">
          <geom name="Leg4_Hip-actuator-assembly_Motor_geom" type="mesh" mesh="Leg4_Hip-actuator-assembly_Motor" pos="0 0 0" euler="0 0 0" />
          <inertial mass="0.3028214126901055" pos="0.013799107411403501 0.0002445449923600619 0.0001665011404277553" fullinertia="0.00023174021267842942 0.00013815228212788388 0.00014141746037829735 1.799485937690842e-07 1.0525676781244903e-06 5.3615260104539586e-08" />
          <body name="Leg4_Hip-actuator-assembly_Hip-Bracket" pos="0.012250000000002446 0.09499999999999953 0.04000000000000241" euler="-1.5707963267948966 1.5707963267948966 0">
            <joint name="Leg4_Hip" type="hinge" axis="1.044698303301379e-30 -1.0000000000000029 2.0382828214422557e-16" pos="0.04000000516471871 -0.017249999999999977 -0.09500000000000068" range="-1.570796 0.3" limited="true" />
            <geom name="Leg4_Hip-actuator-assembly_Hip-Bracket_geom" type="mesh" mesh="Leg4_Hip-actuator-assembly_Hip-Bracket" pos="0 0 0" euler="0 0 0" />
            <inertial mass="0.05792781115933178" pos="0.0412437881617826 -0.009686640073078253 -0.05405434309768331" fullinertia="9.85838062971938e-05 0.00010067920230328245 5.2647464656368e-05 4.054417809776125e-06 -1.4243321119434844e-06 1.531754993366378e-05" />
            <body name="Leg4_Femur-actuator-assembly_Motor" pos="0.0 -2.886579864025407e-16 -1.9539925233402755e-16" euler="-1.4835298641951802 1.2301127401794757e-16 -2.848511181556418e-20">
              <geom name="Leg4_Femur-actuator-assembly_Motor_geom" type="mesh" mesh="Leg4_Femur-actuator-assembly_Motor" pos="0 0 0" euler="0 0 0" />
              <inertial mass="0.3028214126901055" pos="0.013799107411403387 0.0002445449923600398 0.00016650114042775498" fullinertia="0.00023174021267842563 0.00013815228212788217 0.00014141746037829703 1.7994859376949216e-07 1.0525676781245504e-06 5.361526010436344e-08" />
              <body name="Leg4_Femur-actuator-assembly_Femur" pos="0.0 1.5987211554602254e-16 2.220446049250313e-18" euler="1.4835298641951802 -9.213561862185276e-18 -1.0465783018494714e-16">
                <joint name="Leg4_Femur" type="hinge" axis="1.0000000000000022 -2.848544170504046e-20 -5.3875665748200195e-17" pos="0.029500005164718696 3.6429108963445334e-16 1.0943297004469161e-16" range="-0.785398 1.832596" limited="true" />
                <geom name="Leg4_Femur-actuator-assembly_Femur_geom" type="mesh" mesh="Leg4_Femur-actuator-assembly_Femur" pos="0 0 0" euler="0 0 0" />
                <inertial mass="0.06743801039317165" pos="0.03916107786857746 0.03222905940208431 0.02039616263196659" fullinertia="0.0002477420639114133 9.247070534669862e-05 0.00016401711823831806 -1.816841486932311e-06 -1.1512909002667814e-06 -8.763800429865387e-05" />
                <body name="Leg4_Tibia_Tibia-Full" pos="0.0 0.01965999558828654 0.018992913719242638" euler="4.930380657631325e-32 4.9303806524363403e-32 -2.848568968151033e-20">
                  <joint name="Leg4_Tibia" type="hinge" axis="-1.0000000000000022 -2.4799724658473147e-25 5.3875665748200146e-17" pos="0.03300000516471872 0.10761700441171412 0.07292908628075771" range="-1.047198 1.570796" limited="true" />
                  <geom name="Leg4_Tibia_Tibia-Full_geom" type="mesh" mesh="Leg4_Tibia_Tibia-Full" pos="0 0 0" euler="0 0 0" />
                  <inertial mass="0.5325920058039666" pos="0.03903387077261377 0.0025357289803729006 0.157455047889404" fullinertia="0.003029413276509664 0.0008274226390222379 0.002218887888180391 4.0867539756694594e-05 -2.964089688262299e-05 0.0012309838645819656" />
                  <body name="Leg4_Tibia_Tibia-Partial" pos="3.552713678800501e-17 3.552713678800501e-17 7.105427357601002e-17" euler="2.4651903288156624e-32 -2.1629170918652414e-46 2.4797514612865137e-25">
                    <geom name="Leg4_Tibia_Tibia-Partial_geom" type="mesh" mesh="Leg4_Tibia_Tibia-Partial" pos="0 0 0" euler="0 0 0" />
                    <inertial mass="0.04268806780866727" pos="0.04302588971407916 0.09756567365453613 0.08371692150453562" fullinertia="3.765972186276742e-05 1.9570612852609932e-05 1.837207381461318e-05 3.177520329344548e-07 -3.0109774704805636e-07 1.5137133715213636e-05" />
                  </body>
                  <site name="Leg4_Tibia_bad_touch1_site" pos="0.04 0.048 0.148" size="0.005" type="sphere" rgba="1 0 0 1" />
                  <geom name="Leg4_Tibia_bad_touch1_site" pos="0.04 0.048 0.148" size="0.005" type="sphere" rgba="1 0 0 1" />
                  <site name="Leg4_Tibia_bad_touch2_site" pos="0.04 -0.05 0.195" size="0.005" type="sphere" rgba="1 0 0 1" />
                  <geom name="Leg4_Tibia_bad_touch2_site" pos="0.04 -0.05 0.195" size="0.005" type="sphere" rgba="1 0 0 1" />
                  <site name="Leg4_Tibia_foot_site" pos="0.04 -0.1195 0.2018" size="0.007 0.005" type="cylinder" rgba="0 1 0 1" euler="0 1.5708 0" />
                  <geom name="Leg4_Tibia_foot_site" pos="0.04 -0.1195 0.2018" size="0.007 0.005" type="cylinder" rgba="0 1 0 1" euler="0 1.5708 0" friction="2.0 0.1 0.01" />
                </body>
                <body name="Leg4_Knee-actuator-assembly_Motor" pos="0.07650000000000366 -3.552713678800501e-17 0.0" euler="-0.0820304748437336 -1.3034353007344026e-16 3.141592653589792">
                  <geom name="Leg4_Knee-actuator-assembly_Motor_geom" type="mesh" mesh="Leg4_Knee-actuator-assembly_Motor" pos="0 0 0" euler="0 0 0" />
                  <inertial mass="0.3028214126901055" pos="0.013799107411403454 0.0002445449923600579 0.00016650114042775625" fullinertia="0.00023174021267842666 0.0001381522821278802 0.00014141746037829998 1.7994859376907119e-07 1.0525676781244441e-06 5.361526010453285e-08" />
                  <body name="Leg4_Knee-actuator-assembly_Knee-motor-bearings" pos="0.11894493236997265 -0.01333752607235389 -0.040499725337706176" euler="-1.5707963267948981 1.178097245096173 -1.5707963267948972">
                    <geom name="Leg4_Knee-actuator-assembly_Knee-motor-bearings_geom" type="mesh" mesh="Leg4_Knee-actuator-assembly_Knee-motor-bearings" pos="0 0 0" euler="0 0 0" />
                    <inertial mass="0.009270686219329867" pos="-0.042575332613045816 -0.0031217780936082136 -0.12080177571379896" fullinertia="6.408471849585417e-06 6.408471849655069e-06 1.275054794519867e-05 -3.73456826444421e-18 7.390020048902752e-20 2.3206396848502075e-19" />
                  </body>
                  <body name="Leg4_Knee-actuator-assembly_KneeMotorPulley" pos="0.041000000000002375 -0.033041575943744336 -0.01971490744865175" euler="1.5707963267948966 5.3805566485503884e-20 -3.141592653589793">
                    <geom name="Leg4_Knee-actuator-assembly_KneeMotorPulley_geom" type="mesh" mesh="Leg4_Knee-actuator-assembly_KneeMotorPulley" pos="0 0 0" euler="0 0 0" />
                    <inertial mass="0.08135375942547957" pos="0.005405704726782275 0.019714907448618903 0.033041575943703556" fullinertia="1.2462648308958848e-05 7.261200035422016e-06 7.261200035850193e-06 -2.4876560385442844e-18 -4.467317526682112e-18 -2.672659999130439e-16" />
                  </body>
                </body>
              </body>
            </body>
            <body name="Leg4_Knee-actuator-assembly_End-Bearing-Holder" pos="-0.042444932369969365 -0.0031217780935925135 -0.04257533261304135" euler="3.141592653589793 1.5707963267948966 0">
              <geom name="Leg4_Knee-actuator-assembly_End-Bearing-Holder_geom" type="mesh" mesh="Leg4_Knee-actuator-assembly_End-Bearing-Holder" pos="0 0 0" euler="0 0 0" />
              <inertial mass="0.057169625310268736" pos="-0.04109062630262349 -0.001108467278132863 -0.12254015277022079" fullinertia="5.1961941766097425e-05 5.1347634596561126e-05 0.00010281021554763191 -9.985502905468006e-07 -1.082925363048593e-08 -1.1711751146880166e-08" />
            </body>
          </body>
        </body>
      </body>
      <body name="Leg5_Hip-actuator-assembly_Body-Bracket" pos="0.36512101275220393 -0.1056161234160153 -0.028621778093592735" euler="-1.5707963267948966 9.43244057203782e-32 1.570796326794896">
        <geom name="Leg5_Hip-actuator-assembly_Body-Bracket_geom" type="mesh" mesh="Leg5_Hip-actuator-assembly_Body-Bracket" pos="0 0 0" euler="0 0 0" />
        <inertial mass="0.2737560132535958" pos="0.04678090928184924 -0.03304651659344973 -0.08247897457912842" fullinertia="0.0002054895382617321 0.00030785752435440357 0.00011826659575640198 9.185276276080686e-08 -3.8625346758814315e-10 -6.214987814904336e-11" />
        <body name="Leg5_Hip-actuator-assembly_Motor" pos="0.05236612341601519 -0.01337177809359516 -0.08247899241251183" euler="6.782073943008956e-31 1.2246467991473623e-16 1.5707963267948966">
          <geom name="Leg5_Hip-actuator-assembly_Motor_geom" type="mesh" mesh="Leg5_Hip-actuator-assembly_Motor" pos="0 0 0" euler="0 0 0" />
          <inertial mass="0.3028214126901055" pos="0.013799107411403501 0.000244544992360062 0.00016650114042775533" fullinertia="0.0002317402126784136 0.00013815228212788144 0.00014141746037829746 1.7994859376913905e-07 1.0525676781255207e-06 5.36152601057974e-08" />
          <body name="Leg5_Hip-actuator-assembly_Hip-Bracket" pos="0.012250000000002448 0.0949999999999995 0.040000000000002346" euler="-1.5707963267948966 1.5707963267948966 0">
            <joint name="Leg5_Hip" type="hinge" axis="-8.91468563294666e-31 -1.0000000000000029 2.0382828214422552e-16" pos="0.03999999483528662 -0.017249999999999988 -0.09500000000000071" range="-1.570796 0.3" limited="true" />
            <geom name="Leg5_Hip-actuator-assembly_Hip-Bracket_geom" type="mesh" mesh="Leg5_Hip-actuator-assembly_Hip-Bracket" pos="0 0 0" euler="0 0 0" />
            <inertial mass="0.05792781115933178" pos="0.041243788161782674 -0.009686640073078257 -0.05405434309768335" fullinertia="9.858380629719388e-05 0.00010067920230327995 5.2647464656365426e-05 4.054417809775925e-06 -1.42433211194378e-06 1.5317549933663727e-05" />
            <body name="Leg5_Femur-actuator-assembly_Motor" pos="0.0 -2.886579864025407e-16 -1.7763568394002506e-16" euler="-1.4835298641951802 1.2301127401794762e-16 -2.848511181556418e-20">
              <geom name="Leg5_Femur-actuator-assembly_Motor_geom" type="mesh" mesh="Leg5_Femur-actuator-assembly_Motor" pos="0 0 0" euler="0 0 0" />
              <inertial mass="0.3028214126901055" pos="0.013799107411403392 0.0002445449923600835 0.0001665011404277556" fullinertia="0.00023174021267842844 0.00013815228212790177 0.00014141746037830323 1.7994859377655925e-07 1.0525676781243679e-06 5.361526010274561e-08" />
              <body name="Leg5_Femur-actuator-assembly_Femur" pos="7.105427357601002e-17 1.4210854715202004e-16 4.440892098500626e-18" euler="1.4835298641951802 -9.213561862185284e-18 -1.0465783018494719e-16">
                <joint name="Leg5_Femur" type="hinge" axis="1.0000000000000027 -2.848544170722868e-20 -6.298038597725004e-16" pos="0.029499994835286616 3.573521957308402e-16 1.2019866746761297e-16" range="-0.785398 1.832596" limited="true" />
                <geom name="Leg5_Femur-actuator-assembly_Femur_geom" type="mesh" mesh="Leg5_Femur-actuator-assembly_Femur" pos="0 0 0" euler="0 0 0" />
                <inertial mass="0.06743801039317165" pos="0.039161077868577476 0.03222905940208431 0.020396162631966537" fullinertia="0.0002477420639114148 9.247070534670079e-05 0.0001640171182383158 -1.8168414869322494e-06 -1.1512909002688569e-06 -8.76380042986539e-05" />
                <body name="Leg5_Tibia_Tibia-Full" pos="0.0 0.019659995588286544 0.018992913719242638" euler="4.930380657631325e-32 -5.194942857457227e-41 -2.848568968151033e-20">
                  <joint name="Leg5_Tibia" type="hinge" axis="-1.0000000000000027 -2.479950583743499e-25 6.298038597725004e-16" pos="0.03299999483528665 0.10761700441171411 0.07292908628075774" range="-1.047198 1.570796" limited="true" />
                  <geom name="Leg5_Tibia_Tibia-Full_geom" type="mesh" mesh="Leg5_Tibia_Tibia-Full" pos="0 0 0" euler="0 0 0" />
                  <inertial mass="0.5325920058039666" pos="0.039033870772613714 0.0025357289803729006 0.15745504788940404" fullinertia="0.0030294132765096874 0.000827422639022224 0.00221888788818036 4.0867539756693646e-05 -2.9640896882650515e-05 0.0012309838645819663" />
                  <body name="Leg5_Tibia_Tibia-Partial" pos="7.105427357601002e-17 2.2204460492503132e-17 7.105427357601002e-17" euler="-7.395570986446988e-32 1.479114197289399e-31 2.479751461286513e-25">
                    <geom name="Leg5_Tibia_Tibia-Partial_geom" type="mesh" mesh="Leg5_Tibia_Tibia-Partial" pos="0 0 0" euler="0 0 0" />
                    <inertial mass="0.04268806780866727" pos="0.04302588971407921 0.09756567365453614 0.08371692150453565" fullinertia="3.76597218627679e-05 1.95706128526108e-05 1.8372073814613465e-05 3.177520329343077e-07 -3.010977470477508e-07 1.5137133715213748e-05" />
                  </body>
                  <site name="Leg5_Tibia_bad_touch1_site" pos="0.04 0.048 0.148" size="0.005" type="sphere" rgba="1 0 0 1" />
                  <geom name="Leg5_Tibia_bad_touch1_site" pos="0.04 0.048 0.148" size="0.005" type="sphere" rgba="1 0 0 1" />
                  <site name="Leg5_Tibia_bad_touch2_site" pos="0.04 -0.05 0.195" size="0.005" type="sphere" rgba="1 0 0 1" />
                  <geom name="Leg5_Tibia_bad_touch2_site" pos="0.04 -0.05 0.195" size="0.005" type="sphere" rgba="1 0 0 1" />
                  <site name="Leg5_Tibia_foot_site" pos="0.04 -0.1195 0.2018" size="0.007 0.005" type="cylinder" rgba="0 1 0 1" euler="0 1.5708 0" />
                  <geom name="Leg5_Tibia_foot_site" pos="0.04 -0.1195 0.2018" size="0.007 0.005" type="cylinder" rgba="0 1 0 1" euler="0 1.5708 0" friction="2.0 0.1 0.01" />
                </body>
                <body name="Leg5_Knee-actuator-assembly_Motor" pos="0.07650000000000368 -3.9968028886505634e-17 0.0" euler="-0.08203047484373362 -1.303435300734403e-16 3.141592653589792">
                  <geom name="Leg5_Knee-actuator-assembly_Motor_geom" type="mesh" mesh="Leg5_Knee-actuator-assembly_Motor" pos="0 0 0" euler="0 0 0" />
                  <inertial mass="0.3028214126901055" pos="0.013799107411403565 0.0002445449923600587 0.00016650114042774647" fullinertia="0.00023174021267842947 0.00013815228212791226 0.00014141746037832096 1.7994859376773984e-07 1.0525676781302181e-06 5.3615260105010576e-08" />
                  <body name="Leg5_Knee-actuator-assembly_Knee-motor-bearings" pos="0.11894493236997278 -0.01333752607235389 -0.04049972533770621" euler="-1.5707963267948981 1.1780972450961729 -1.5707963267948972">
                    <geom name="Leg5_Knee-actuator-assembly_Knee-motor-bearings_geom" type="mesh" mesh="Leg5_Knee-actuator-assembly_Knee-motor-bearings" pos="0 0 0" euler="0 0 0" />
                    <inertial mass="0.009270686219329867" pos="-0.04257533261304578 -0.0031217780936081962 -0.12080177571379905" fullinertia="6.408471849584994e-06 6.408471849654219e-06 1.2750547945198788e-05 -3.471141017848123e-18 1.2141112176321959e-19 2.1600652108457227e-19" />
                  </body>
                  <body name="Leg5_Knee-actuator-assembly_KneeMotorPulley" pos="0.04100000000000243 -0.033041575943744336 -0.01971490744865177" euler="1.5707963267948966 5.380556648545458e-20 -3.141592653589793">
                    <geom name="Leg5_Knee-actuator-assembly_KneeMotorPulley_geom" type="mesh" mesh="Leg5_Knee-actuator-assembly_KneeMotorPulley" pos="0 0 0" euler="0 0 0" />
                    <inertial mass="0.08135375942547957" pos="0.0054057047267822575 0.019714907448618903 0.03304157594370355" fullinertia="1.2462648308959079e-05 7.261200035418941e-06 7.261200035851884e-06 -3.836878041903159e-18 -4.2612035161347484e-18 -2.668166489345255e-16" />
                  </body>
                </body>
              </body>
            </body>
            <body name="Leg5_Knee-actuator-assembly_End-Bearing-Holder" pos="-0.04244493236996938 -0.0031217780935925135 -0.04257533261304135" euler="3.141592653589793 1.5707963267948966 0">
              <geom name="Leg5_Knee-actuator-assembly_End-Bearing-Holder_geom" type="mesh" mesh="Leg5_Knee-actuator-assembly_End-Bearing-Holder" pos="0 0 0" euler="0 0 0" />
              <inertial mass="0.057169625310268736" pos="-0.04109062630262346 -0.001108467278132863 -0.12254015277022091" fullinertia="5.19619417660976e-05 5.134763459656156e-05 0.00010281021554763199 -9.98550290546855e-07 -1.0829253631033684e-08 -1.1711751147017508e-08" />
            </body>
          </body>
        </body>
      </body>
      <body name="Leg6_Hip-actuator-assembly_Body-Bracket" pos="0.22752101275220393 -0.1700161234160153 -0.028621778093592735" euler="-1.5707963267948966 9.43244057203782e-32 1.570796326794896">
        <geom name="Leg6_Hip-actuator-assembly_Body-Bracket_geom" type="mesh" mesh="Leg6_Hip-actuator-assembly_Body-Bracket" pos="0 0 0" euler="0 0 0" />
        <inertial mass="0.2737560132535958" pos="0.046780909281849234 -0.03304651659344973 -0.08247897457912831" fullinertia="0.00020548953826174946 0.0003078575243544105 0.00011826659575640112 9.185276276079331e-08 -3.862534667207814e-10 -6.214987814904336e-11" />
        <body name="Leg6_Hip-actuator-assembly_Motor" pos="0.05236612341601516 -0.01337177809359516 -0.08247899241251179" euler="6.782073943008956e-31 1.2246467991473623e-16 1.5707963267948966">
          <geom name="Leg6_Hip-actuator-assembly_Motor_geom" type="mesh" mesh="Leg6_Hip-actuator-assembly_Motor" pos="0 0 0" euler="0 0 0" />
          <inertial mass="0.3028214126901055" pos="0.013799107411403501 0.000244544992360062 0.00016650114042775533" fullinertia="0.00023174021267842747 0.00013815228212787797 0.0001414174603782966 1.7994859376897642e-07 1.0525676781246533e-06 5.361526010319531e-08" />
          <body name="Leg6_Hip-actuator-assembly_Hip-Bracket" pos="0.012250000000002446 0.09499999999999949 0.040000000000002416" euler="-1.5707963267948966 1.5707963267948966 0">
            <joint name="Leg6_Hip" type="hinge" axis="-8.91468563294666e-31 -1.0000000000000029 2.0382828214422552e-16" pos="0.03999999483528668 -0.017249999999999988 -0.09500000000000071" range="-1.2 0.7" limited="true" />
            <geom name="Leg6_Hip-actuator-assembly_Hip-Bracket_geom" type="mesh" mesh="Leg6_Hip-actuator-assembly_Hip-Bracket" pos="0 0 0" euler="0 0 0" />
            <inertial mass="0.05792781115933178" pos="0.041243788161782674 -0.009686640073078257 -0.05405434309768337" fullinertia="9.858380629719377e-05 0.00010067920230328169 5.264746465636716e-05 4.054417809776033e-06 -1.4243321119433463e-06 1.5317549933663755e-05" />
            <body name="Leg6_Femur-actuator-assembly_Motor" pos="0.0 -2.886579864025407e-16 -1.7763568394002506e-16" euler="-1.4835298641951802 1.2301127401794762e-16 -2.848511181556418e-20">
              <geom name="Leg6_Femur-actuator-assembly_Motor_geom" type="mesh" mesh="Leg6_Femur-actuator-assembly_Motor" pos="0 0 0" euler="0 0 0" />
              <inertial mass="0.3028214126901055" pos="0.013799107411403392 0.00024454499236006583 0.00016650114042775715" fullinertia="0.0002317402126784293 0.0001381522821278845 0.00014141746037829624 1.7994859377652145e-07 1.052567678123936e-06 5.361526010365024e-08" />
              <body name="Leg6_Femur-actuator-assembly_Femur" pos="0.0 1.0658141036401502e-16 1.1102230246251566e-18" euler="1.4835298641951802 -9.213561862185284e-18 -1.0465783018494719e-16">
                <joint name="Leg6_Femur" type="hinge" axis="1.0000000000000027 -2.848544170722868e-20 -6.298038597725004e-16" pos="0.02949999483528667 3.573521957308402e-16 1.2019866746761293e-16" range="-0.785398 1.832596" limited="true" />
                <geom name="Leg6_Femur-actuator-assembly_Femur_geom" type="mesh" mesh="Leg6_Femur-actuator-assembly_Femur" pos="0 0 0" euler="0 0 0" />
                <inertial mass="0.06743801039317165" pos="0.03916107786857744 0.03222905940208431 0.020396162631966575" fullinertia="0.0002477420639114148 9.247070534670079e-05 0.00016401711823832015 -1.81684148693229e-06 -1.1512909002679895e-06 -8.763800429865388e-05" />
                <body name="Leg6_Tibia_Tibia-Full" pos="0.0 0.019659995588286544 0.018992913719242603" euler="4.930380657631325e-32 -5.194942857457227e-41 -2.848568968151033e-20">
                  <joint name="Leg6_Tibia" type="hinge" axis="-1.0000000000000027 -2.479950583743499e-25 6.298038597725004e-16" pos="0.032999994835286706 0.10761700441171411 0.07292908628075777" range="-1.047198 1.570796" limited="true" />
                  <geom name="Leg6_Tibia_Tibia-Full_geom" type="mesh" mesh="Leg6_Tibia_Tibia-Full" pos="0 0 0" euler="0 0 0" />
                  <inertial mass="0.5325920058039666" pos="0.03903387077261368 0.0025357289803729006 0.15745504788940404" fullinertia="0.0030294132765097013 0.000827422639022224 0.0022188878881804087 4.0867539756693754e-05 -2.9640896882650515e-05 0.0012309838645819663" />
                  <body name="Leg6_Tibia_Tibia-Partial" pos="3.552713678800501e-17 2.2204460492503132e-17 7.105427357601002e-17" euler="-7.395570986446988e-32 1.479114197289399e-31 2.479751461286513e-25">
                    <geom name="Leg6_Tibia_Tibia-Partial_geom" type="mesh" mesh="Leg6_Tibia_Tibia-Partial" pos="0 0 0" euler="0 0 0" />
                    <inertial mass="0.04268806780866727" pos="0.04302588971407921 0.09756567365453614 0.08371692150453569" fullinertia="3.7659721862767464e-05 1.9570612852609065e-05 1.8372073814613465e-05 3.1775203293474137e-07 -3.010977470477508e-07 1.5137133715213856e-05" />
                  </body>
                  <site name="Leg6_Tibia_bad_touch1_site" pos="0.04 0.048 0.148" size="0.005" type="sphere" rgba="1 0 0 1" />
                  <geom name="Leg6_Tibia_bad_touch1_site" pos="0.04 0.048 0.148" size="0.005" type="sphere" rgba="1 0 0 1" />
                  <site name="Leg6_Tibia_bad_touch2_site" pos="0.04 -0.05 0.195" size="0.005" type="sphere" rgba="1 0 0 1" />
                  <geom name="Leg6_Tibia_bad_touch2_site" pos="0.04 -0.05 0.195" size="0.005" type="sphere" rgba="1 0 0 1" />
                  <site name="Leg6_Tibia_foot_site" pos="0.04 -0.1195 0.2018" size="0.007 0.005" type="cylinder" rgba="0 1 0 1" euler="0 1.5708 0" />
                  <geom name="Leg6_Tibia_foot_site" pos="0.04 -0.1195 0.2018" size="0.007 0.005" type="cylinder" rgba="0 1 0 1" euler="0 1.5708 0" friction="2.0 0.1 0.01" />
                </body>
                <body name="Leg6_Knee-actuator-assembly_Motor" pos="0.07650000000000368 -3.9968028886505634e-17 0.0" euler="-0.08203047484373362 -1.303435300734403e-16 3.141592653589792">
                  <geom name="Leg6_Knee-actuator-assembly_Motor_geom" type="mesh" mesh="Leg6_Knee-actuator-assembly_Motor" pos="0 0 0" euler="0 0 0" />
                  <inertial mass="0.3028214126901055" pos="0.013799107411403565 0.0002445449923600572 0.0001665011404277642" fullinertia="0.00023174021267842687 0.00013815228212789833 0.0001414174603783071 1.7994859376975297e-07 1.0525676781269024e-06 5.3615260105222335e-08" />
                  <body name="Leg6_Knee-actuator-assembly_Knee-motor-bearings" pos="0.11894493236997278 -0.01333752607235389 -0.040499725337706245" euler="-1.5707963267948981 1.1780972450961729 -1.5707963267948972">
                    <geom name="Leg6_Knee-actuator-assembly_Knee-motor-bearings_geom" type="mesh" mesh="Leg6_Knee-actuator-assembly_Knee-motor-bearings" pos="0 0 0" euler="0 0 0" />
                    <inertial mass="0.009270686219329867" pos="-0.04257533261304573 -0.003121778093608172 -0.12080177571379905" fullinertia="6.40847184958512e-06 6.408471849654744e-06 1.2750547945199005e-05 -3.7269449679189215e-18 -7.764514313954851e-20 1.2894304752552253e-19" />
                  </body>
                  <body name="Leg6_Knee-actuator-assembly_KneeMotorPulley" pos="0.0410000000000025 -0.033041575943744336 -0.019714907448651717" euler="1.5707963267948966 5.380556648545458e-20 -3.141592653589793">
                    <geom name="Leg6_Knee-actuator-assembly_KneeMotorPulley_geom" type="mesh" mesh="Leg6_Knee-actuator-assembly_KneeMotorPulley" pos="0 0 0" euler="0 0 0" />
                    <inertial mass="0.08135375942547957" pos="0.005405704726782222 0.019714907448618885 0.03304157594370355" fullinertia="1.2462648308958645e-05 7.261200035425824e-06 7.26120003585194e-06 -4.7102069687845685e-18 -4.298188830878057e-18 -2.6743667705191564e-16" />
                  </body>
                </body>
              </body>
            </body>
            <body name="Leg6_Knee-actuator-assembly_End-Bearing-Holder" pos="-0.04244493236996938 -0.0031217780935925135 -0.042575332613041326" euler="3.141592653589793 1.5707963267948966 0">
              <geom name="Leg6_Knee-actuator-assembly_End-Bearing-Holder_geom" type="mesh" mesh="Leg6_Knee-actuator-assembly_End-Bearing-Holder" pos="0 0 0" euler="0 0 0" />
              <inertial mass="0.057169625310268736" pos="-0.04109062630262346 -0.001108467278132863 -0.12254015277022091" fullinertia="5.19619417661002e-05 5.1347634596559825e-05 0.00010281021554763156 -9.985502905469092e-07 -1.0829253631033684e-08 -1.1711751146800667e-08" />
            </body>
          </body>
        </body>
      </body>
      <body name="Leg7_Hip-actuator-assembly_Body-Bracket" pos="0.08992101275220396 -0.1700161234160153 -0.028621778093592735" euler="-1.5707963267948966 9.43244057203782e-32 1.570796326794896">
        <geom name="Leg7_Hip-actuator-assembly_Body-Bracket_geom" type="mesh" mesh="Leg7_Hip-actuator-assembly_Body-Bracket" pos="0 0 0" euler="0 0 0" />
        <inertial mass="0.2737560132535958" pos="0.046780909281849234 -0.03304651659344973 -0.08247897457912838" fullinertia="0.00020548953826174252 0.00030785752435440704 0.00011826659575640112 9.185276276079331e-08 -3.862534684555049e-10 -6.214987812193831e-11" />
        <body name="Leg7_Hip-actuator-assembly_Motor" pos="0.05236612341601518 -0.013371778093595162 -0.08247899241251182" euler="6.782073943008956e-31 1.2246467991473623e-16 1.5707963267948966">
          <geom name="Leg7_Hip-actuator-assembly_Motor_geom" type="mesh" mesh="Leg7_Hip-actuator-assembly_Motor" pos="0 0 0" euler="0 0 0" />
          <inertial mass="0.3028214126901055" pos="0.013799107411403501 0.000244544992360062 0.00016650114042779084" fullinertia="0.00023174021267843267 0.0001381522821278849 0.0001414174603782966 1.7994859376897642e-07 1.0525676781253039e-06 5.36152601057974e-08" />
          <body name="Leg7_Hip-actuator-assembly_Hip-Bracket" pos="0.012250000000002446 0.0949999999999995 0.040000000000002436" euler="-1.5707963267948966 1.5707963267948966 0">
            <joint name="Leg7_Hip" type="hinge" axis="-8.91468563294666e-31 -1.0000000000000029 2.0382828214422552e-16" pos="0.03999999483528668 -0.017249999999999988 -0.09500000000000071" range="-0.6 1.2" limited="true" />
            <geom name="Leg7_Hip-actuator-assembly_Hip-Bracket_geom" type="mesh" mesh="Leg7_Hip-actuator-assembly_Hip-Bracket" pos="0 0 0" euler="0 0 0" />
            <inertial mass="0.05792781115933178" pos="0.04124378816178264 -0.009686640073078257 -0.05405434309768337" fullinertia="9.858380629719377e-05 0.00010067920230328342 5.264746465636781e-05 4.054417809776087e-06 -1.42433211194378e-06 1.5317549933663755e-05" />
            <body name="Leg7_Femur-actuator-assembly_Motor" pos="-1.7763568394002505e-17 -2.886579864025407e-16 -1.7763568394002506e-16" euler="-1.4835298641951802 1.2301127401794762e-16 -2.848511181556418e-20">
              <geom name="Leg7_Femur-actuator-assembly_Motor_geom" type="mesh" mesh="Leg7_Femur-actuator-assembly_Motor" pos="0 0 0" euler="0 0 0" />
              <inertial mass="0.3028214126901055" pos="0.013799107411403392 0.00024454499236006583 0.00016650114042775715" fullinertia="0.0002317402126784293 0.00013815228212788456 0.00014141746037830313 1.7994859377135598e-07 1.0525676781246055e-06 5.361526010425333e-08" />
              <body name="Leg7_Femur-actuator-assembly_Femur" pos="0.0 1.0658141036401502e-16 1.1102230246251566e-18" euler="1.4835298641951802 -9.213561862185284e-18 -1.0465783018494719e-16">
                <joint name="Leg7_Femur" type="hinge" axis="1.0000000000000027 -2.848544170722868e-20 -6.298038597725004e-16" pos="0.02949999483528667 3.573521957308402e-16 1.2019866746761293e-16" range="-0.785398 1.832596" limited="true" />
                <geom name="Leg7_Femur-actuator-assembly_Femur_geom" type="mesh" mesh="Leg7_Femur-actuator-assembly_Femur" pos="0 0 0" euler="0 0 0" />
                <inertial mass="0.06743801039317165" pos="0.03916107786857751 0.03222905940208431 0.020396162631966575" fullinertia="0.0002477420639114148 9.247070534669819e-05 0.0001640171182383171 -1.8168414869322426e-06 -1.1512909002666884e-06 -8.763800429865388e-05" />
                <body name="Leg7_Tibia_Tibia-Full" pos="-1.7763568394002505e-17 0.019659995588286544 0.018992913719242603" euler="4.930380657631325e-32 -5.194942857457227e-41 -2.848568968151033e-20">
                  <joint name="Leg7_Tibia" type="hinge" axis="-1.0000000000000027 -2.479950583743499e-25 6.298038597725004e-16" pos="0.032999994835286706 0.10761700441171411 0.07292908628075777" range="-1.047198 1.570796" limited="true" />
                  <geom name="Leg7_Tibia_Tibia-Full_geom" type="mesh" mesh="Leg7_Tibia_Tibia-Full" pos="0 0 0" euler="0 0 0" />
                  <inertial mass="0.5325920058039666" pos="0.039033870772613735 0.0025357289803729006 0.15745504788940404" fullinertia="0.0030294132765097013 0.0008274226390222379 0.002218887888180395 4.086753975669397e-05 -2.9640896882650515e-05 0.0012309838645819663" />
                  <body name="Leg7_Tibia_Tibia-Partial" pos="3.552713678800501e-17 2.2204460492503132e-17 7.105427357601002e-17" euler="-7.395570986446988e-32 1.479114197289399e-31 2.479751461286513e-25">
                    <geom name="Leg7_Tibia_Tibia-Partial_geom" type="mesh" mesh="Leg7_Tibia_Tibia-Partial" pos="0 0 0" euler="0 0 0" />
                    <inertial mass="0.04268806780866727" pos="0.04302588971407919 0.09756567365453614 0.08371692150453569" fullinertia="3.7659721862767464e-05 1.9570612852609932e-05 1.8372073814613465e-05 3.1775203293463294e-07 -3.0109774704818447e-07 1.5137133715213856e-05" />
                  </body>
                  <site name="Leg7_Tibia_bad_touch1_site" pos="0.04 0.048 0.148" size="0.005" type="sphere" rgba="1 0 0 1" />
                  <geom name="Leg7_Tibia_bad_touch1_site" pos="0.04 0.048 0.148" size="0.005" type="sphere" rgba="1 0 0 1" />
                  <site name="Leg7_Tibia_bad_touch2_site" pos="0.04 -0.05 0.195" size="0.005" type="sphere" rgba="1 0 0 1" />
                  <geom name="Leg7_Tibia_bad_touch2_site" pos="0.04 -0.05 0.195" size="0.005" type="sphere" rgba="1 0 0 1" />
                  <site name="Leg7_Tibia_foot_site" pos="0.04 -0.1195 0.2018" size="0.007 0.005" type="cylinder" rgba="0 1 0 1" euler="0 1.5708 0" />
                  <geom name="Leg7_Tibia_foot_site" pos="0.04 -0.1195 0.2018" size="0.007 0.005" type="cylinder" rgba="0 1 0 1" euler="0 1.5708 0" friction="2.0 0.1 0.01" />
                </body>
                <body name="Leg7_Knee-actuator-assembly_Motor" pos="0.07650000000000365 -3.9968028886505634e-17 -3.552713678800501e-17" euler="-0.08203047484373362 -1.303435300734403e-16 3.141592653589792">
                  <geom name="Leg7_Knee-actuator-assembly_Motor_geom" type="mesh" mesh="Leg7_Knee-actuator-assembly_Motor" pos="0 0 0" euler="0 0 0" />
                  <inertial mass="0.3028214126901055" pos="0.013799107411403458 0.0002445449923600572 0.0001665011404277642" fullinertia="0.00023174021267842687 0.00013815228212788104 0.00014141746037829667 1.799485937687406e-07 1.052567678123338e-06 5.361526010465821e-08" />
                  <body name="Leg7_Knee-actuator-assembly_Knee-motor-bearings" pos="0.11894493236997261 -0.013337526072353894 -0.040499725337706245" euler="-1.5707963267948981 1.1780972450961729 -1.5707963267948972">
                    <geom name="Leg7_Knee-actuator-assembly_Knee-motor-bearings_geom" type="mesh" mesh="Leg7_Knee-actuator-assembly_Knee-motor-bearings" pos="0 0 0" euler="0 0 0" />
                    <inertial mass="0.009270686219329867" pos="-0.04257533261304573 -0.003121778093608172 -0.12080177571379905" fullinertia="6.408471849585404e-06 6.4084718496552185e-06 1.2750547945199005e-05 -3.859929140637847e-18 1.568815724238989e-20 1.8452862385712994e-19" />
                  </body>
                  <body name="Leg7_Knee-actuator-assembly_KneeMotorPulley" pos="0.04100000000000236 -0.033041575943744336 -0.019714907448651717" euler="1.5707963267948966 5.380556648545458e-20 -3.141592653589793">
                    <geom name="Leg7_Knee-actuator-assembly_KneeMotorPulley_geom" type="mesh" mesh="Leg7_Knee-actuator-assembly_KneeMotorPulley" pos="0 0 0" euler="0 0 0" />
                    <inertial mass="0.08135375942547957" pos="0.0054057047267822575 0.019714907448618885 0.03304157594370355" fullinertia="1.2462648308958645e-05 7.261200035421494e-06 7.261200035848465e-06 -3.409097369369144e-18 -4.350766500759938e-18 -2.673658439217015e-16" />
                  </body>
                </body>
              </body>
            </body>
            <body name="Leg7_Knee-actuator-assembly_End-Bearing-Holder" pos="-0.04244493236996938 -0.0031217780935925135 -0.042575332613041326" euler="3.141592653589793 1.5707963267948966 0">
              <geom name="Leg7_Knee-actuator-assembly_End-Bearing-Holder_geom" type="mesh" mesh="Leg7_Knee-actuator-assembly_End-Bearing-Holder" pos="0 0 0" euler="0 0 0" />
              <inertial mass="0.057169625310268736" pos="-0.04109062630262346 -0.001108467278132863 -0.12254015277022091" fullinertia="5.196194176609717e-05 5.134763459655896e-05 0.00010281021554763156 -9.985502905469092e-07 -1.0829253630600004e-08 -1.1711751146963298e-08" />
            </body>
          </body>
        </body>
      </body>
      <body name="Leg8_Hip-actuator-assembly_Body-Bracket" pos="-0.04767898724779603 -0.10561612341601528 -0.028621778093592735" euler="-1.5707963267948966 9.43244057203782e-32 1.570796326794896">
        <geom name="Leg8_Hip-actuator-assembly_Body-Bracket_geom" type="mesh" mesh="Leg8_Hip-actuator-assembly_Body-Bracket" pos="0 0 0" euler="0 0 0" />
        <inertial mass="0.2737560132535958" pos="0.046780909281849234 -0.03304651659344973 -0.08247897457912838" fullinertia="0.00020548953826174398 0.0003078575243544079 0.00011826659575640209 9.185276276086107e-08 -3.862534696481273e-10 -6.214987812871457e-11" />
        <body name="Leg8_Hip-actuator-assembly_Motor" pos="0.05236612341601521 -0.013371778093595157 -0.08247899241251179" euler="6.782073943008956e-31 1.2246467991473623e-16 1.5707963267948966">
          <geom name="Leg8_Hip-actuator-assembly_Motor_geom" type="mesh" mesh="Leg8_Hip-actuator-assembly_Motor" pos="0 0 0" euler="0 0 0" />
          <inertial mass="0.3028214126901055" pos="0.013799107411403501 0.000244544992360062 0.00016650114042775533" fullinertia="0.00023174021267842964 0.00013815228212788404 0.00014141746037829768 1.7994859376903063e-07 1.0525676781246533e-06 5.3615260104604775e-08" />
          <body name="Leg8_Hip-actuator-assembly_Hip-Bracket" pos="0.012250000000002448 0.0949999999999995 0.04000000000000241" euler="-1.5707963267948966 1.5707963267948966 0">
            <joint name="Leg8_Hip" type="hinge" axis="-8.91468563294666e-31 -1.0000000000000029 2.0382828214422552e-16" pos="0.03999999483528665 -0.017249999999999988 -0.09500000000000065" range="-0.3 1.570796" limited="true" />
            <geom name="Leg8_Hip-actuator-assembly_Hip-Bracket_geom" type="mesh" mesh="Leg8_Hip-actuator-assembly_Hip-Bracket" pos="0 0 0" euler="0 0 0" />
            <inertial mass="0.05792781115933178" pos="0.04124378816178265 -0.009686640073078257 -0.05405434309768335" fullinertia="9.858380629719409e-05 0.00010067920230328212 5.264746465636784e-05 4.054417809776155e-06 -1.4243321119437258e-06 1.531754993366378e-05" />
            <body name="Leg8_Femur-actuator-assembly_Motor" pos="-1.1102230246251566e-18 -2.886579864025407e-16 -1.7763568394002506e-16" euler="-1.4835298641951802 1.2301127401794762e-16 -2.848511181556418e-20">
              <geom name="Leg8_Femur-actuator-assembly_Motor_geom" type="mesh" mesh="Leg8_Femur-actuator-assembly_Motor" pos="0 0 0" euler="0 0 0" />
              <inertial mass="0.3028214126901055" pos="0.013799107411403406 0.00024454499236006583 0.00016650114042775715" fullinertia="0.0002317402126784267 0.0001381522821278823 0.00014141746037829703 1.799485937692814e-07 1.0525676781245286e-06 5.3615260104134744e-08" />
              <body name="Leg8_Femur-actuator-assembly_Femur" pos="0.0 1.4210854715202004e-16 2.220446049250313e-18" euler="1.4835298641951802 -9.213561862185284e-18 -1.0465783018494719e-16">
                <joint name="Leg8_Femur" type="hinge" axis="1.0000000000000027 -2.848544170722868e-20 -6.298038597725004e-16" pos="0.029499994835286654 3.573521957308402e-16 1.4795424308324204e-16" range="-0.785398 1.832596" limited="true" />
                <geom name="Leg8_Femur-actuator-assembly_Femur_geom" type="mesh" mesh="Leg8_Femur-actuator-assembly_Femur" pos="0 0 0" euler="0 0 0" />
                <inertial mass="0.06743801039317165" pos="0.03916107786857749 0.03222905940208431 0.020396162631966575" fullinertia="0.00024774206391141437 9.247070534669949e-05 0.0001640171182383182 -1.8168414869322612e-06 -1.1512909002671763e-06 -8.763800429865384e-05" />
                <body name="Leg8_Tibia_Tibia-Full" pos="2.220446049250313e-18 0.019659995588286544 0.018992913719242638" euler="4.930380657631325e-32 -5.194942857457227e-41 -2.848568968151033e-20">
                  <joint name="Leg8_Tibia" type="hinge" axis="-1.0000000000000027 -2.479950583743499e-25 6.298038597725004e-16" pos="0.03299999483528669 0.10761700441171411 0.07292908628075777" range="-1.047198 1.570796" limited="true" />
                  <geom name="Leg8_Tibia_Tibia-Full_geom" type="mesh" mesh="Leg8_Tibia_Tibia-Full" pos="0 0 0" euler="0 0 0" />
                  <inertial mass="0.5325920058039666" pos="0.039033870772613735 0.0025357289803729006 0.15745504788940407" fullinertia="0.0030294132765096874 0.0008274226390222309 0.002218887888180396 4.0867539756694066e-05 -2.9640896882634903e-05 0.0012309838645819667" />
                  <body name="Leg8_Tibia_Tibia-Partial" pos="3.1086244689504386e-17 2.2204460492503132e-17 7.105427357601002e-17" euler="-7.395570986446988e-32 1.479114197289399e-31 2.479751461286513e-25">
                    <geom name="Leg8_Tibia_Tibia-Partial_geom" type="mesh" mesh="Leg8_Tibia_Tibia-Partial" pos="0 0 0" euler="0 0 0" />
                    <inertial mass="0.04268806780866727" pos="0.043025889714079175 0.09756567365453614 0.08371692150453565" fullinertia="3.7659721862768765e-05 1.9570612852610366e-05 1.837207381461341e-05 3.177520329345245e-07 -3.010977470482387e-07 1.5137133715213423e-05" />
                  </body>
                  <site name="Leg8_Tibia_bad_touch1_site" pos="0.04 0.048 0.148" size="0.005" type="sphere" rgba="1 0 0 1" />
                  <geom name="Leg8_Tibia_bad_touch1_site" pos="0.04 0.048 0.148" size="0.005" type="sphere" rgba="1 0 0 1" />
                  <site name="Leg8_Tibia_bad_touch2_site" pos="0.04 -0.05 0.195" size="0.005" type="sphere" rgba="1 0 0 1" />
                  <geom name="Leg8_Tibia_bad_touch2_site" pos="0.04 -0.05 0.195" size="0.005" type="sphere" rgba="1 0 0 1" />
                  <site name="Leg8_Tibia_foot_site" pos="0.04 -0.1195 0.2018" size="0.007 0.005" type="cylinder" rgba="0 1 0 1" euler="0 1.5708 0" />
                  <geom name="Leg8_Tibia_foot_site" pos="0.04 -0.1195 0.2018" size="0.007 0.005" type="cylinder" rgba="0 1 0 1" euler="0 1.5708 0" friction="2.0 0.1 0.01" />
                </body>
                <body name="Leg8_Knee-actuator-assembly_Motor" pos="0.07650000000000368 -3.9968028886505634e-17 0.0" euler="-0.08203047484373362 -1.303435300734403e-16 3.141592653589792">
                  <geom name="Leg8_Knee-actuator-assembly_Motor_geom" type="mesh" mesh="Leg8_Knee-actuator-assembly_Motor" pos="0 0 0" euler="0 0 0" />
                  <inertial mass="0.3028214126901055" pos="0.013799107411403468 0.0002445449923600587 0.00016650114042774647" fullinertia="0.00023174021267842947 0.0001381522821278845 0.00014141746037829993 1.799485937690662e-07 1.0525676781246703e-06 5.3615260104676845e-08" />
                  <body name="Leg8_Knee-actuator-assembly_Knee-motor-bearings" pos="0.11894493236997264 -0.013337526072353889 -0.04049972533770621" euler="-1.5707963267948981 1.1780972450961729 -1.5707963267948972">
                    <geom name="Leg8_Knee-actuator-assembly_Knee-motor-bearings_geom" type="mesh" mesh="Leg8_Knee-actuator-assembly_Knee-motor-bearings" pos="0 0 0" euler="0 0 0" />
                    <inertial mass="0.009270686219329867" pos="-0.04257533261304576 -0.003121778093608186 -0.12080177571379905" fullinertia="6.408471849585391e-06 6.408471849655062e-06 1.2750547945198843e-05 -3.748544308073906e-18 -2.5605143791382897e-21 1.9038763133976689e-19" />
                  </body>
                  <body name="Leg8_Knee-actuator-assembly_KneeMotorPulley" pos="0.04100000000000239 -0.03304157594374433 -0.01971490744865177" euler="1.5707963267948966 5.380556648545458e-20 -3.141592653589793">
                    <geom name="Leg8_Knee-actuator-assembly_KneeMotorPulley_geom" type="mesh" mesh="Leg8_Knee-actuator-assembly_KneeMotorPulley" pos="0 0 0" euler="0 0 0" />
                    <inertial mass="0.08135375942547957" pos="0.005405704726782271 0.01971490744861892 0.03304157594370355" fullinertia="1.2462648308958211e-05 7.261200035422076e-06 7.261200035849536e-06 -2.6571497708446097e-18 -4.466980858105195e-18 -2.6727034095689857e-16" />
                  </body>
                </body>
              </body>
            </body>
            <body name="Leg8_Knee-actuator-assembly_End-Bearing-Holder" pos="-0.04244493236996935 -0.0031217780935925135 -0.042575332613041326" euler="3.141592653589793 1.5707963267948966 0">
              <geom name="Leg8_Knee-actuator-assembly_End-Bearing-Holder_geom" type="mesh" mesh="Leg8_Knee-actuator-assembly_End-Bearing-Holder" pos="0 0 0" euler="0 0 0" />
              <inertial mass="0.057169625310268736" pos="-0.04109062630262346 -0.001108467278132863 -0.12254015277022091" fullinertia="5.1961941766097276e-05 5.134763459656069e-05 0.00010281021554763264 -9.985502905468008e-07 -1.0829253631033684e-08 -1.1711751146854878e-08" />
            </body>
          </body>
        </body>
      </body>
    </body>
  </worldbody>
  <actuator>
    <motor name="Leg1_Hip_Actuator" joint="Leg1_Hip" ctrlrange="-10 10" gear="1" />
    <motor name="Leg1_Femur_Actuator" joint="Leg1_Femur" ctrlrange="-10 10" gear="1" />
    <motor name="Leg1_Tibia_Actuator" joint="Leg1_Tibia" ctrlrange="-10 10" gear="1" />
    <motor name="Leg2_Hip_Actuator" joint="Leg2_Hip" ctrlrange="-10 10" gear="1" />
    <motor name="Leg2_Femur_Actuator" joint="Leg2_Femur" ctrlrange="-10 10" gear="1" />
    <motor name="Leg2_Tibia_Actuator" joint="Leg2_Tibia" ctrlrange="-10 10" gear="1" />
    <motor name="Leg3_Hip_Actuator" joint="Leg3_Hip" ctrlrange="-10 10" gear="1" />
    <motor name="Leg3_Femur_Actuator" joint="Leg3_Femur" ctrlrange="-10 10" gear="1" />
    <motor name="Leg3_Tibia_Actuator" joint="Leg3_Tibia" ctrlrange="-10 10" gear="1" />
    <motor name="Leg4_Hip_Actuator" joint="Leg4_Hip" ctrlrange="-10 10" gear="1" />
    <motor name="Leg4_Femur_Actuator" joint="Leg4_Femur" ctrlrange="-10 10" gear="1" />
    <motor name="Leg4_Tibia_Actuator" joint="Leg4_Tibia" ctrlrange="-10 10" gear="1" />
    <motor name="Leg5_Hip_Actuator" joint="Leg5_Hip" ctrlrange="-10 10" gear="1" />
    <motor name="Leg5_Femur_Actuator" joint="Leg5_Femur" ctrlrange="-10 10" gear="1" />
    <motor name="Leg5_Tibia_Actuator" joint="Leg5_Tibia" ctrlrange="-10 10" gear="1" />
    <motor name="Leg6_Hip_Actuator" joint="Leg6_Hip" ctrlrange="-10 10" gear="1" />
    <motor name="Leg6_Femur_Actuator" joint="Leg6_Femur" ctrlrange="-10 10" gear="1" />
    <motor name="Leg6_Tibia_Actuator" joint="Leg6_Tibia" ctrlrange="-10 10" gear="1" />
    <motor name="Leg7_Hip_Actuator" joint="Leg7_Hip" ctrlrange="-10 10" gear="1" />
    <motor name="Leg7_Femur_Actuator" joint="Leg7_Femur" ctrlrange="-10 10" gear="1" />
    <motor name="Leg7_Tibia_Actuator" joint="Leg7_Tibia" ctrlrange="-10 10" gear="1" />
    <motor name="Leg8_Hip_Actuator" joint="Leg8_Hip" ctrlrange="-10 10" gear="1" />
    <motor name="Leg8_Femur_Actuator" joint="Leg8_Femur" ctrlrange="-10 10" gear="1" />
    <motor name="Leg8_Tibia_Actuator" joint="Leg8_Tibia" ctrlrange="-10 10" gear="1" />
  </actuator>
  <sensor>
    <gyro name="gyro_sensor" site="imu_site" />
    <accelerometer name="accelerometer_sensor" site="imu_site" />
    <touch name="Leg1_Tibia_bad_touch1" site="Leg1_Tibia_bad_touch1_site" />
    <touch name="Leg1_Tibia_bad_touch2" site="Leg1_Tibia_bad_touch2_site" />
    <touch name="Leg1_Tibia_foot" site="Leg1_Tibia_foot_site" />
    <touch name="Leg2_Tibia_bad_touch1" site="Leg2_Tibia_bad_touch1_site" />
    <touch name="Leg2_Tibia_bad_touch2" site="Leg2_Tibia_bad_touch2_site" />
    <touch name="Leg2_Tibia_foot" site="Leg2_Tibia_foot_site" />
    <touch name="Leg3_Tibia_bad_touch1" site="Leg3_Tibia_bad_touch1_site" />
    <touch name="Leg3_Tibia_bad_touch2" site="Leg3_Tibia_bad_touch2_site" />
    <touch name="Leg3_Tibia_foot" site="Leg3_Tibia_foot_site" />
    <touch name="Leg4_Tibia_bad_touch1" site="Leg4_Tibia_bad_touch1_site" />
    <touch name="Leg4_Tibia_bad_touch2" site="Leg4_Tibia_bad_touch2_site" />
    <touch name="Leg4_Tibia_foot" site="Leg4_Tibia_foot_site" />
    <touch name="Leg5_Tibia_bad_touch1" site="Leg5_Tibia_bad_touch1_site" />
    <touch name="Leg5_Tibia_bad_touch2" site="Leg5_Tibia_bad_touch2_site" />
    <touch name="Leg5_Tibia_foot" site="Leg5_Tibia_foot_site" />
    <touch name="Leg6_Tibia_bad_touch1" site="Leg6_Tibia_bad_touch1_site" />
    <touch name="Leg6_Tibia_bad_touch2" site="Leg6_Tibia_bad_touch2_site" />
    <touch name="Leg6_Tibia_foot" site="Leg6_Tibia_foot_site" />
    <touch name="Leg7_Tibia_bad_touch1" site="Leg7_Tibia_bad_touch1_site" />
    <touch name="Leg7_Tibia_bad_touch2" site="Leg7_Tibia_bad_touch2_site" />
    <touch name="Leg7_Tibia_foot" site="Leg7_Tibia_foot_site" />
    <touch name="Leg8_Tibia_bad_touch1" site="Leg8_Tibia_bad_touch1_site" />
    <touch name="Leg8_Tibia_bad_touch2" site="Leg8_Tibia_bad_touch2_site" />
    <touch name="Leg8_Tibia_foot" site="Leg8_Tibia_foot_site" />
  </sensor>
</mujoco>
