<mujoco model="SpiderBot">
  <compiler angle="radian" />
  <default>
    <mesh scale="0.001 0.001 0.001" />
    <geom contype="0" conaffinity="0" group="2" />
    <default class="collision">
      <geom contype="1" conaffinity="1" group="3" pos="0 0 0" mass="0.0" />
    </default>
  </default>
  <asset>
    <mesh name="Body_visual" file="meshes/Body/visual.stl" />
    <mesh name="Femur_visual" file="meshes/Femur/visual.stl" />
    <mesh name="Femur_collision00" file="meshes/Femur/collision00.stl" />
    <mesh name="Motor_visual" file="meshes/Motor/visual.stl" />
    <mesh name="Motor_collision00" file="meshes/Motor/collision00.stl" />
    <mesh name="Motor_collision01" file="meshes/Motor/collision01.stl" />
    <mesh name="Motor_collision02" file="meshes/Motor/collision02.stl" />
    <mesh name="Motor_collision03" file="meshes/Motor/collision03.stl" />
    <mesh name="Tibia_visual" file="meshes/Tibia/visual.stl" />
    <mesh name="Tibia_collision00" file="meshes/Tibia/collision00.stl" />
    <mesh name="Tibia_collision01" file="meshes/Tibia/collision01.stl" />
    <mesh name="Tibia_collision02" file="meshes/Tibia/collision02.stl" />
    <mesh name="Tibia_collision03" file="meshes/Tibia/collision03.stl" />
    <mesh name="Knee_visual" file="meshes/Knee/visual.stl" />
    <mesh name="Foot_visual" file="meshes/Foot/visual.stl" />
    <mesh name="Foot_collision00" file="meshes/Foot/collision00.stl" />
    <mesh name="TibiaBearingTrack_visual" file="meshes/TibiaBearingTrack/visual.stl" />
    <mesh name="TibiaMotorSpacer_visual" file="meshes/TibiaMotorSpacer/visual.stl" />
    <mesh name="Hip_visual" file="meshes/Hip/visual.stl" />
    <mesh name="HipBearingTrack_visual" file="meshes/HipBearingTrack/visual.stl" />
    <mesh name="MainClamp_visual" file="meshes/MainClamp/visual.stl" />
    <mesh name="CrossClamp_visual" file="meshes/CrossClamp/visual.stl" />
    <material name="Body_mat" rgba="0.0980 0.0980 0.0980 1.0000" roughness="0.0775" />
    <material name="Femur_mat" rgba="0.5373 0.5373 0.5373 1.0000" roughness="0.1225" />
    <material name="Motor_mat" rgba="0.0980 0.0980 0.0980 1.0000" roughness="0.0775" />
    <material name="Tibia_mat" rgba="0.5373 0.5373 0.5373 1.0000" roughness="0.1225" />
    <material name="Knee_mat" rgba="0.2471 0.2471 0.2471 1.0000" roughness="0.2600" />
    <material name="Foot_mat" rgba="0.0980 0.0980 0.0980 1.0000" roughness="0.7071" />
    <material name="TibiaBearingTrack_mat" rgba="0.2471 0.2471 0.2471 1.0000" roughness="0.2600" />
    <material name="TibiaMotorSpacer_mat" rgba="0.0980 0.0980 0.0980 1.0000" roughness="0.7071" />
    <material name="Hip_mat" rgba="0.2471 0.2471 0.2471 1.0000" roughness="0.2600" />
    <material name="HipBearingTrack_mat" rgba="0.2471 0.2471 0.2471 1.0000" roughness="0.2600" />
    <material name="MainClamp_mat" rgba="0.2471 0.2471 0.2471 1.0000" roughness="0.2600" />
    <material name="CrossClamp_mat" rgba="0.2471 0.2471 0.2471 1.0000" roughness="0.2600" />
  </asset>
  <worldbody>
    <body name="Body" pos="0.0 0.0 0.0" quat="1.0 0.0 0.0 0.0">
      <freejoint />
      <geom mesh="Body_visual" name="Body_Body_visual_geom" type="mesh" pos="0 0 0" quat="1 0 0 0" material="Body_mat" />
      <inertial mass="0.18464093644287463" pos="0.0002043264181948041 6.163197729409591e-17 0.007241278293340654" fullinertia="0.0012170529417377895 0.0032623722956095 0.004463635442019566 2.7068691264730745e-19 8.019621781711088e-07 1.3791534859335566e-19" />
      <body name="R1_MainClamp" pos="0.21768105157175574 -0.1646239541111095 -0.06824959828188881" quat="0.9999979914074321 -0.002004290672836025 -1.0166845459493043e-15 -2.0377354456429908e-18">
        <geom mesh="MainClamp_visual" name="R1_MainClamp_MainClamp_visual_geom" type="mesh" pos="0 0 0" quat="1 0 0 0" material="MainClamp_mat" />
        <inertial mass="0.04277320346680061" pos="-0.011078641677823025 0.10936584632552594 0.07185120146554273" fullinertia="2.5569324435957536e-05 4.9554608103231195e-05 7.410198303042189e-05 -6.176818167937542e-08 -4.803365145461677e-10 -1.0852179663378192e-07" />
        <body name="R1_CrossClamp" pos="0.0 0.0 0.0" quat="1.0 2.168404344971009e-19 9.860682090334649e-32 1.0089855797698544e-35">
          <geom mesh="CrossClamp_visual" name="R1_CrossClamp_CrossClamp_visual_geom" type="mesh" pos="0 0 0" quat="1 0 0 0" material="CrossClamp_mat" />
          <inertial mass="0.0060873366326105825" pos="-0.011076095384506187 0.10937852181993969 0.08220436514827456" fullinertia="3.569640975298418e-07 8.628331172516547e-06 8.861345261438887e-06 -2.3998371452427588e-08 -9.439137922450537e-11 -1.065146252730935e-09" />
        </body>
        <body name="R1_Hip-assembly_Motor" pos="-0.011076386363475165 0.10966822722227194 0.01505997107270793" quat="-0.0014172475262309893 0.707105360897122 0.001417247526231073 -0.7071053608971223">
          <geom mesh="Motor_visual" name="R1_Hip-assembly_Motor_Motor_visual_geom" type="mesh" pos="0 0 0" quat="1 0 0 0" material="Motor_mat" />
          <geom mesh="Motor_collision00" name="R1_Hip-assembly_Motor_Motor_collision00_geom" type="mesh" pos="0 0 0" quat="1 0 0 0" class="collision" />
          <geom mesh="Motor_collision01" name="R1_Hip-assembly_Motor_Motor_collision01_geom" type="mesh" pos="0 0 0" quat="1 0 0 0" class="collision" />
          <geom mesh="Motor_collision02" name="R1_Hip-assembly_Motor_Motor_collision02_geom" type="mesh" pos="0 0 0" quat="1 0 0 0" class="collision" />
          <geom mesh="Motor_collision03" name="R1_Hip-assembly_Motor_Motor_collision03_geom" type="mesh" pos="0 0 0" quat="1 0 0 0" class="collision" />
          <inertial mass="0.4096463210987154" pos="-0.03569820729651781 0.00047016950890322614 -5.891982746499138e-06" fullinertia="0.0004025220023127328 0.00022651206716561785 0.00023297814211205656 1.5369569971653381e-06 -5.181750872317603e-08 -2.6262635187278443e-08" />
          <body name="R1_Hip" pos="0.014620638666750292 0.10750000000000089 -0.010029361333295093" quat="1.2699325361584729e-15 -0.7071067811865472 1.102379038134243e-15 0.7071067811865478">
            <joint type="hinge" name="R1_Hip" axis="2.04862431470163e-15 2.5916768731093498e-15 1.0" pos="-0.01002902654157561 0.10750023900524659 0.035250000000043864" range="-0.3 1.4" limited="true" />
            <geom mesh="Hip_visual" name="R1_Hip_Hip_visual_geom" type="mesh" pos="0 0 0" quat="1 0 0 0" material="Hip_mat" />
            <inertial mass="0.052580342819792604" pos="-0.012181480181525596 0.04674400290943464 0.02883739744027624" fullinertia="0.0001103630858238173 3.7076315879304005e-05 8.929956210807904e-05 -2.9193347098829655e-06 4.020625400927333e-06 -1.4395949292889949e-05" />
            <body name="R1_HipBearingTrack" pos="0.0010470250301800378 -0.0022277151058630196 4.0171815532730195e-07" quat="0.9999979914074321 -0.0020042906728373207 7.502826567872053e-18 6.124750082395104e-17">
              <geom mesh="HipBearingTrack_visual" name="R1_HipBearingTrack_HipBearingTrack_visual_geom" type="mesh" pos="0 0 0" quat="1 0 0 0" material="HipBearingTrack_mat" />
              <inertial mass="0.011609757728843081" pos="-0.010935890023697522 0.10786068092028847 0.06071584524702324" fullinertia="1.7484945833483858e-05 1.5363892724198782e-05 3.26918707448008e-05 8.956505581893472e-08 2.868177647897336e-09 1.1403857006668036e-07" />
            </body>
            <body name="R1_Femur-assembly_Motor" pos="3.552713678800501e-17 -3.1974423109204507e-16 0.0500000000000013" quat="-6.114900252818196e-17 1.0 6.126241564798603e-17 -2.2907194013402957e-29">
              <geom mesh="Motor_visual" name="R1_Femur-assembly_Motor_Motor_visual_geom" type="mesh" pos="0 0 0" quat="1 0 0 0" material="Motor_mat" />
              <geom mesh="Motor_collision00" name="R1_Femur-assembly_Motor_Motor_collision00_geom" type="mesh" pos="0 0 0" quat="1 0 0 0" class="collision" />
              <geom mesh="Motor_collision01" name="R1_Femur-assembly_Motor_Motor_collision01_geom" type="mesh" pos="0 0 0" quat="1 0 0 0" class="collision" />
              <geom mesh="Motor_collision02" name="R1_Femur-assembly_Motor_Motor_collision02_geom" type="mesh" pos="0 0 0" quat="1 0 0 0" class="collision" />
              <geom mesh="Motor_collision03" name="R1_Femur-assembly_Motor_Motor_collision03_geom" type="mesh" pos="0 0 0" quat="1 0 0 0" class="collision" />
              <inertial mass="0.4096463210987154" pos="-0.03569820729651777 0.0004701695089032045 -5.891982746489858e-06" fullinertia="0.0004025220023127305 0.00022651206716561866 0.0002329781421120602 1.5369569971619705e-06 -5.181750872274396e-08 -2.626263518699081e-08" />
              <body name="R1_Femur" pos="0.0 -2.1316282072803005e-16 0.04999999999999993" quat="-2.609024107869118e-15 0.9999999999999999 -3.5582322627219784e-34 3.022776199361025e-32">
                <joint type="hinge" name="R1_Femur" axis="-1.0 6.015138125580519e-20 2.048624314701585e-15" pos="-0.02062902654157562 2.390052469905287e-07 0.050000000000042816" range="-1.570796 0.0" limited="true" />
                <geom mesh="Femur_visual" name="R1_Femur_Femur_visual_geom" type="mesh" pos="0 0 0" quat="1 0 0 0" material="Femur_mat" />
                <geom mesh="Femur_collision00" name="R1_Femur_Femur_collision00_geom" type="mesh" pos="0 0 0" quat="1 0 0 0" class="collision" />
                <inertial mass="0.230842936042845" pos="-0.01038368677116484 0.0008485718996991484 0.051461139330156426" fullinertia="0.0008028766514152899 0.0005773602804628149 0.0002491128346876067 -6.940768618269669e-08 2.303269615935221e-08 -1.470243222718049e-05" />
                <body name="R1_TibiaMotorSpacer" pos="0.0 0.0 0.0" quat="1.0 0.0 0.0 -7.821578647613801e-46">
                  <geom mesh="TibiaMotorSpacer_visual" name="R1_TibiaMotorSpacer_TibiaMotorSpacer_visual_geom" type="mesh" pos="0 0 0" quat="1 0 0 0" material="TibiaMotorSpacer_mat" />
                  <inertial mass="0.01707263849756077" pos="0.0013206386667055162 -6.945183746737574e-06 0.029478113737471095" fullinertia="2.921102534848174e-05 7.473002877028613e-06 2.174442471088991e-05 1.084265940943542e-19 3.891384923556604e-20 3.751013704944496e-09" />
                  <body name="R1_Tibia-assembly_Motor" pos="-0.02405872266658843 4.618527782440651e-16 0.05000000206997374" quat="-2.312169521622237e-16 7.20464942823445e-16 0.38268343236509045 0.9238795325112871">
                    <geom mesh="Motor_visual" name="R1_Tibia-assembly_Motor_Motor_visual_geom" type="mesh" pos="0 0 0" quat="1 0 0 0" material="Motor_mat" />
                    <geom mesh="Motor_collision00" name="R1_Tibia-assembly_Motor_Motor_collision00_geom" type="mesh" pos="0 0 0" quat="1 0 0 0" class="collision" />
                    <geom mesh="Motor_collision01" name="R1_Tibia-assembly_Motor_Motor_collision01_geom" type="mesh" pos="0 0 0" quat="1 0 0 0" class="collision" />
                    <geom mesh="Motor_collision02" name="R1_Tibia-assembly_Motor_Motor_collision02_geom" type="mesh" pos="0 0 0" quat="1 0 0 0" class="collision" />
                    <geom mesh="Motor_collision03" name="R1_Tibia-assembly_Motor_Motor_collision03_geom" type="mesh" pos="0 0 0" quat="1 0 0 0" class="collision" />
                    <inertial mass="0.4096463210987154" pos="-0.03569820729651784 0.0004701695089032443 -5.891982746497786e-06" fullinertia="0.0004025220023127278 0.00022651206716562043 0.00023297814211205932 1.536956997165948e-06 -5.181750872329104e-08 -2.6262635188140438e-08" />
                  </body>
                </body>
                <body name="R1_Knee" pos="-0.015029361333294489 -0.019714907448651217 0.1739584240562563" quat="1.0 0.0 8.048094238931602e-20 -2.0619978725023343e-37">
                  <joint type="hinge" name="R1_Knee" axis="-1.0 6.015138125580519e-20 2.0484633528168065e-15" pos="0.014000334791719178 0.01971514645389945 0.03304157594378652" range="-0.20944 2.268928" limited="true" />
                  <geom mesh="Knee_visual" name="R1_Knee_Knee_visual_geom" type="mesh" pos="0 0 0" quat="1 0 0 0" material="Knee_mat" />
                  <inertial mass="0.008812389430275673" pos="0.004999999999999997 0.019714907448508803 0.03304157594374378" fullinertia="1.4471797213984772e-06 8.008801325288346e-07 8.008801268246301e-07 5.421006974838949e-20 5.2886187589849905e-20 -3.5724461583442614e-17" />
                  <body name="R1_Tibia" pos="0.015029361333294489 0.019714907448651255 -0.17395842405625622" quat="1.0 0.0 -8.048094238931602e-20 1.6959068022287468e-22">
                    <geom mesh="Tibia_visual" name="R1_Tibia_Tibia_visual_geom" type="mesh" pos="0 0 0" quat="1 0 0 0" material="Tibia_mat" />
                    <geom mesh="Tibia_collision00" name="R1_Tibia_Tibia_collision00_geom" type="mesh" pos="0 0 0" quat="1 0 0 0" class="collision" />
                    <geom mesh="Tibia_collision01" name="R1_Tibia_Tibia_collision01_geom" type="mesh" pos="0 0 0" quat="1 0 0 0" class="collision" />
                    <geom mesh="Tibia_collision02" name="R1_Tibia_Tibia_collision02_geom" type="mesh" pos="0 0 0" quat="1 0 0 0" class="collision" />
                    <geom mesh="Tibia_collision03" name="R1_Tibia_Tibia_collision03_geom" type="mesh" pos="0 0 0" quat="1 0 0 0" class="collision" />
                    <inertial mass="0.07297107048801112" pos="-0.010029361333294318 -0.047571361468123095 0.11810916584738512" fullinertia="0.0005482843792552132 0.0004624716132690046 9.111533044167097e-05 4.94367590455011e-19 7.981448332518909e-19 -0.0001820680121749135" />
                    <body name="R1_Foot" pos="0.0 0.0 0.0" quat="1.0 0.0 0.0 -7.821578647613801e-46">
                      <geom mesh="Foot_visual" name="R1_Foot_Foot_visual_geom" type="mesh" pos="0 0 0" quat="1 0 0 0" material="Foot_mat" />
                      <geom mesh="Foot_collision00" name="R1_Foot_Foot_collision00_geom" type="mesh" pos="0 0 0" quat="1 0 0 0" class="collision" friction="2.0 0.1 0.01" />
                      <inertial mass="0.004818206956885" pos="-0.010029361333294169 -0.08392600723875258 -0.03482830039342609" fullinertia="4.0355141511756254e-07 3.266830345812974e-07 1.4993157143529563e-07 -5.4208725990490147e-20 -5.195717374949909e-22 6.771781369145493e-10" />
                    </body>
                  </body>
                </body>
              </body>
            </body>
            <body name="R1_TibiaBearingTrack" pos="3.552713678800501e-17 -1.0658141036401502e-16 1.3500311979441904e-15" quat="1.0 2.6701731103973003e-15 2.297557386456197e-29 6.126241564798602e-17">
              <geom mesh="TibiaBearingTrack_visual" name="R1_TibiaBearingTrack_TibiaBearingTrack_visual_geom" type="mesh" pos="0 0 0" quat="1 0 0 0" material="TibiaBearingTrack_mat" />
              <inertial mass="0.015140027390716102" pos="0.012936002208848415 0.008673353142335503 0.03817888888858537" fullinertia="4.130276155873871e-05 2.106701364111607e-05 2.040326746851044e-05 2.923768935302156e-10 -2.5812677988877467e-09 4.898672945159864e-07" />
            </body>
          </body>
        </body>
      </body>
      <body name="L1_MainClamp" pos="0.19552827884480486 0.16462395411110975 -0.06824959828188862" quat="3.304566878248689e-18 1.648743011932669e-15 -0.0020042906728360193 0.9999979914074331">
        <geom mesh="MainClamp_visual" name="L1_MainClamp_MainClamp_visual_geom" type="mesh" pos="0 0 0" quat="1 0 0 0" material="MainClamp_mat" />
        <inertial mass="0.04277320346680061" pos="-0.011078641677823117 0.1093658463255267 0.07185120146554273" fullinertia="2.556932443595948e-05 4.95546081032322e-05 7.410198303041624e-05 -6.176818167937585e-08 -4.803365145559676e-10 -1.0852179663383203e-07" />
        <body name="L1_CrossClamp" pos="0.0 3.552713678800501e-17 0.0" quat="1.0 2.1689618408400908e-19 9.865514810942556e-32 -1.6059710305357113e-33">
          <geom mesh="CrossClamp_visual" name="L1_CrossClamp_CrossClamp_visual_geom" type="mesh" pos="0 0 0" quat="1 0 0 0" material="CrossClamp_mat" />
          <inertial mass="0.0060873366326105825" pos="-0.01107609538450623 0.10937852181994046 0.08220436514827456" fullinertia="3.56964097530173e-07 8.628331172516879e-06 8.86134526143829e-06 -2.399837145244132e-08 -9.439137922397355e-11 -1.0651462527308158e-09" />
        </body>
        <body name="L1_Hip-assembly_Motor" pos="-0.011076386363475165 0.109668227222272 0.015059971072707939" quat="-0.0014172475262309893 0.707105360897122 0.001417247526231073 -0.7071053608971223">
          <geom mesh="Motor_visual" name="L1_Hip-assembly_Motor_Motor_visual_geom" type="mesh" pos="0 0 0" quat="1 0 0 0" material="Motor_mat" />
          <geom mesh="Motor_collision00" name="L1_Hip-assembly_Motor_Motor_collision00_geom" type="mesh" pos="0 0 0" quat="1 0 0 0" class="collision" />
          <geom mesh="Motor_collision01" name="L1_Hip-assembly_Motor_Motor_collision01_geom" type="mesh" pos="0 0 0" quat="1 0 0 0" class="collision" />
          <geom mesh="Motor_collision02" name="L1_Hip-assembly_Motor_Motor_collision02_geom" type="mesh" pos="0 0 0" quat="1 0 0 0" class="collision" />
          <geom mesh="Motor_collision03" name="L1_Hip-assembly_Motor_Motor_collision03_geom" type="mesh" pos="0 0 0" quat="1 0 0 0" class="collision" />
          <inertial mass="0.4096463210987154" pos="-0.03569820729651781 0.00047016950890323665 -5.891982746508759e-06" fullinertia="0.0004025220023127293 0.00022651206716561948 0.0002329781421120636 1.5369569971652288e-06 -5.181750872296188e-08 -2.6262635187276683e-08" />
          <body name="L1_Hip" pos="0.014620638666750292 0.10750000000000093 -0.010029361333295128" quat="1.2699325361584729e-15 -0.7071067811865472 1.1023790381342386e-15 0.7071067811865478">
            <joint type="hinge" name="L1_Hip" axis="3.312743785769343e-15 2.5916768731093498e-15 1.0" pos="-0.010029696125015048 0.10750023900524722 0.03525000000004368" range="-1.4 0.3" limited="true" />
            <geom mesh="Hip_visual" name="L1_Hip_Hip_visual_geom" type="mesh" pos="0 0 0" quat="1 0 0 0" material="Hip_mat" />
            <inertial mass="0.052580342819792604" pos="-0.012181480181525711 0.046744002909434965 0.028837397440276236" fullinertia="0.00011036308582381896 3.707631587930513e-05 8.92995621080786e-05 -2.919334709882571e-06 4.020625400927158e-06 -1.4395949292889998e-05" />
            <body name="L1_HipBearingTrack" pos="0.0010470250301800378 -0.002227715105862984 4.017181553184202e-07" quat="0.9999979914074321 -0.0020042906728373207 7.502826567872045e-18 6.124750082395104e-17">
              <geom mesh="HipBearingTrack_visual" name="L1_HipBearingTrack_HipBearingTrack_visual_geom" type="mesh" pos="0 0 0" quat="1 0 0 0" material="HipBearingTrack_mat" />
              <inertial mass="0.011609757728843081" pos="-0.010935890023697591 0.1078606809202892 0.06071584524702323" fullinertia="1.74849458334844e-05 1.5363892724199433e-05 3.269187074479983e-05 8.956505581896264e-08 2.868177647906512e-09 1.1403857006666158e-07" />
            </body>
            <body name="L1_Femur-assembly_Motor" pos="0.0 -2.486899575160351e-16 0.0500000000000013" quat="-6.114900252818186e-17 1.0 6.126241564798603e-17 -2.2948931854515965e-29">
              <geom mesh="Motor_visual" name="L1_Femur-assembly_Motor_Motor_visual_geom" type="mesh" pos="0 0 0" quat="1 0 0 0" material="Motor_mat" />
              <geom mesh="Motor_collision00" name="L1_Femur-assembly_Motor_Motor_collision00_geom" type="mesh" pos="0 0 0" quat="1 0 0 0" class="collision" />
              <geom mesh="Motor_collision01" name="L1_Femur-assembly_Motor_Motor_collision01_geom" type="mesh" pos="0 0 0" quat="1 0 0 0" class="collision" />
              <geom mesh="Motor_collision02" name="L1_Femur-assembly_Motor_Motor_collision02_geom" type="mesh" pos="0 0 0" quat="1 0 0 0" class="collision" />
              <geom mesh="Motor_collision03" name="L1_Femur-assembly_Motor_Motor_collision03_geom" type="mesh" pos="0 0 0" quat="1 0 0 0" class="collision" />
              <inertial mass="0.4096463210987154" pos="-0.03569820729651801 0.00047016950890324175 -5.891982746488369e-06" fullinertia="0.0004025220023127316 0.00022651206716562717 0.0002329781421120602 1.536956997165451e-06 -5.1817508723180395e-08 -2.6262635186561565e-08" />
              <body name="L1_Femur" pos="0.0 -1.7763568394002506e-16 0.04999999999999993" quat="-2.6090241078691135e-15 0.9999999999999999 1.0675054281976233e-34 -2.238572363512608e-31">
                <joint type="hinge" name="L1_Femur" axis="-1.0000000000000036 6.015138126582773e-20 3.312743785769286e-15" pos="-0.02062969612501502 2.390052472403297e-07 0.05000000000004265" range="-1.570796 0.0" limited="true" />
                <geom mesh="Femur_visual" name="L1_Femur_Femur_visual_geom" type="mesh" pos="0 0 0" quat="1 0 0 0" material="Femur_mat" />
                <geom mesh="Femur_collision00" name="L1_Femur_Femur_collision00_geom" type="mesh" pos="0 0 0" quat="1 0 0 0" class="collision" />
                <inertial mass="0.230842936042845" pos="-0.010383686771164883 0.0008485718996991514 0.05146113933015643" fullinertia="0.0008028766514153051 0.0005773602804628295 0.0002491128346876067 -6.94076861818484e-08 2.3032696159194377e-08 -1.4702432227180776e-05" />
                <body name="L1_TibiaMotorSpacer" pos="0.0 0.0 0.0" quat="1.0 0.0 0.0 3.490722164698665e-36">
                  <geom mesh="TibiaMotorSpacer_visual" name="L1_TibiaMotorSpacer_TibiaMotorSpacer_visual_geom" type="mesh" pos="0 0 0" quat="1 0 0 0" material="TibiaMotorSpacer_mat" />
                  <inertial mass="0.01707263849756077" pos="0.0013206386667055229 -6.945183746737599e-06 0.029478113737471095" fullinertia="2.9211025348482328e-05 7.473002877029099e-06 2.1744424710889694e-05 1.1118575264176248e-23 2.947517398689867e-20 3.751013704944302e-09" />
                  <body name="L1_Tibia-assembly_Motor" pos="-0.024058722666588466 4.618527782440651e-16 0.05000000206997373" quat="-2.3121695216222366e-16 7.20464942823445e-16 0.38268343236509034 0.9238795325112871">
                    <geom mesh="Motor_visual" name="L1_Tibia-assembly_Motor_Motor_visual_geom" type="mesh" pos="0 0 0" quat="1 0 0 0" material="Motor_mat" />
                    <geom mesh="Motor_collision00" name="L1_Tibia-assembly_Motor_Motor_collision00_geom" type="mesh" pos="0 0 0" quat="1 0 0 0" class="collision" />
                    <geom mesh="Motor_collision01" name="L1_Tibia-assembly_Motor_Motor_collision01_geom" type="mesh" pos="0 0 0" quat="1 0 0 0" class="collision" />
                    <geom mesh="Motor_collision02" name="L1_Tibia-assembly_Motor_Motor_collision02_geom" type="mesh" pos="0 0 0" quat="1 0 0 0" class="collision" />
                    <geom mesh="Motor_collision03" name="L1_Tibia-assembly_Motor_Motor_collision03_geom" type="mesh" pos="0 0 0" quat="1 0 0 0" class="collision" />
                    <inertial mass="0.4096463210987154" pos="-0.03569820729651808 0.0004701695089032431 -5.891982746500614e-06" fullinertia="0.0004025220023127341 0.00022651206716561823 0.00023297814211205794 1.5369569971656538e-06 -5.1817508723602356e-08 -2.626263519325691e-08" />
                  </body>
                </body>
                <body name="L1_Knee" pos="-0.015029361333294489 -0.019714907448651217 0.17395842405625625" quat="1.0 0.0 8.048094238941462e-20 2.3232483703915257e-35">
                  <joint type="hinge" name="L1_Knee" axis="-1.0000000000000036 6.015138126582773e-20 3.312582823884507e-15" pos="0.013999665208280158 0.01971514645389985 0.03304157594378634" range="-0.20944 2.268928" limited="true" />
                  <geom mesh="Knee_visual" name="L1_Knee_Knee_visual_geom" type="mesh" pos="0 0 0" quat="1 0 0 0" material="Knee_mat" />
                  <inertial mass="0.008812389430275673" pos="0.00500000000000002 0.01971490744850891 0.033041575943743774" fullinertia="1.4471797213984332e-06 8.008801325287319e-07 8.008801268246301e-07 -5.421014750020702e-20 -2.1409209360682444e-21 -3.575158886664396e-17" />
                  <body name="L1_Tibia" pos="0.015029361333294489 0.019714907448651255 -0.17395842405625622" quat="1.0 0.0 -8.048094238941462e-20 1.6959068022356698e-22">
                    <geom mesh="Tibia_visual" name="L1_Tibia_Tibia_visual_geom" type="mesh" pos="0 0 0" quat="1 0 0 0" material="Tibia_mat" />
                    <geom mesh="Tibia_collision00" name="L1_Tibia_Tibia_collision00_geom" type="mesh" pos="0 0 0" quat="1 0 0 0" class="collision" />
                    <geom mesh="Tibia_collision01" name="L1_Tibia_Tibia_collision01_geom" type="mesh" pos="0 0 0" quat="1 0 0 0" class="collision" />
                    <geom mesh="Tibia_collision02" name="L1_Tibia_Tibia_collision02_geom" type="mesh" pos="0 0 0" quat="1 0 0 0" class="collision" />
                    <geom mesh="Tibia_collision03" name="L1_Tibia_Tibia_collision03_geom" type="mesh" pos="0 0 0" quat="1 0 0 0" class="collision" />
                    <inertial mass="0.07297107048801112" pos="-0.010029361333294382 -0.04757136146812344 0.11810916584738514" fullinertia="0.0005482843792552279 0.0004624716132690174 9.111533044167097e-05 2.6421187120611406e-19 7.62329623319909e-19 -0.00018206801217491504" />
                    <body name="L1_Foot" pos="0.0 0.0 0.0" quat="1.0 0.0 0.0 2.8882150354913727e-36">
                      <geom mesh="Foot_visual" name="L1_Foot_Foot_visual_geom" type="mesh" pos="0 0 0" quat="1 0 0 0" material="Foot_mat" />
                      <geom mesh="Foot_collision00" name="L1_Foot_Foot_collision00_geom" type="mesh" pos="0 0 0" quat="1 0 0 0" class="collision" friction="2.0 0.1 0.01" />
                      <inertial mass="0.004818206956885" pos="-0.01002936133329425 -0.08392600723875315 -0.034828300393426076" fullinertia="4.035514151175112e-07 3.266830345813539e-07 1.4993157143486195e-07 5.421234729212894e-20 -8.401775201450125e-22 6.771781369145426e-10" />
                    </body>
                  </body>
                </body>
              </body>
            </body>
            <body name="L1_TibiaBearingTrack" pos="0.0 -7.105427357601002e-17 1.3500311979441904e-15" quat="1.0 2.6701731103972956e-15 2.2876966251409342e-29 6.126241564798602e-17">
              <geom mesh="TibiaBearingTrack_visual" name="L1_TibiaBearingTrack_TibiaBearingTrack_visual_geom" type="mesh" pos="0 0 0" quat="1 0 0 0" material="TibiaBearingTrack_mat" />
              <inertial mass="0.015140027390716102" pos="0.012936002208848508 0.008673353142335551 0.03817888888858537" fullinertia="4.1302761558739334e-05 2.1067013641116543e-05 2.040326746851044e-05 2.923768935308369e-10 -2.58126779888707e-09 4.898672945160146e-07" />
            </body>
          </body>
        </body>
      </body>
      <body name="R2_MainClamp" pos="0.07968105157175574 -0.2326239541111095 -0.06824959828188881" quat="0.9999979914074321 -0.002004290672836025 -1.0166845459493043e-15 -2.0377354456429908e-18">
        <geom mesh="MainClamp_visual" name="R2_MainClamp_MainClamp_visual_geom" type="mesh" pos="0 0 0" quat="1 0 0 0" material="MainClamp_mat" />
        <inertial mass="0.04277320346680061" pos="-0.01107864167782299 0.10936584632552593 0.07185120146554273" fullinertia="2.556932443595751e-05 4.955460810323087e-05 7.410198303042091e-05 -6.176818167959228e-08 -4.803365145436487e-10 -1.0852179663377845e-07" />
        <body name="R2_CrossClamp" pos="0.0 0.0 0.0" quat="1.0 2.168404344971009e-19 9.860682090334649e-32 1.0089855797698544e-35">
          <geom mesh="CrossClamp_visual" name="R2_CrossClamp_CrossClamp_visual_geom" type="mesh" pos="0 0 0" quat="1 0 0 0" material="CrossClamp_mat" />
          <inertial mass="0.0060873366326105825" pos="-0.011076095384506142 0.10937852181993966 0.08220436514827456" fullinertia="3.569640975298452e-07 8.628331172516486e-06 8.861345261438792e-06 -2.399837145244114e-08 -9.43913792245597e-11 -1.0651462527299556e-09" />
        </body>
        <body name="R2_Hip-assembly_Motor" pos="-0.011076386363475165 0.10966822722227194 0.01505997107270793" quat="-0.0014172475262309893 0.707105360897122 0.001417247526231073 -0.7071053608971223">
          <geom mesh="Motor_visual" name="R2_Hip-assembly_Motor_Motor_visual_geom" type="mesh" pos="0 0 0" quat="1 0 0 0" material="Motor_mat" />
          <geom mesh="Motor_collision00" name="R2_Hip-assembly_Motor_Motor_collision00_geom" type="mesh" pos="0 0 0" quat="1 0 0 0" class="collision" />
          <geom mesh="Motor_collision01" name="R2_Hip-assembly_Motor_Motor_collision01_geom" type="mesh" pos="0 0 0" quat="1 0 0 0" class="collision" />
          <geom mesh="Motor_collision02" name="R2_Hip-assembly_Motor_Motor_collision02_geom" type="mesh" pos="0 0 0" quat="1 0 0 0" class="collision" />
          <geom mesh="Motor_collision03" name="R2_Hip-assembly_Motor_Motor_collision03_geom" type="mesh" pos="0 0 0" quat="1 0 0 0" class="collision" />
          <inertial mass="0.4096463210987154" pos="-0.03569820729651781 0.00047016950890323497 -5.891982746481375e-06" fullinertia="0.0004025220023127328 0.00022651206716561525 0.00023297814211205526 1.536956997165284e-06 -5.181750872285077e-08 -2.6262635187278443e-08" />
          <body name="R2_Hip" pos="0.014620638666750283 0.10750000000000093 -0.010029361333295128" quat="1.2699325361584729e-15 -0.7071067811865472 1.102379038134243e-15 0.7071067811865478">
            <joint type="hinge" name="R2_Hip" axis="2.04862431470163e-15 2.5916768731093498e-15 1.0" pos="-0.010029026541575652 0.10750023900524659 0.035250000000043864" range="-0.4 0.9" limited="true" />
            <geom mesh="Hip_visual" name="R2_Hip_Hip_visual_geom" type="mesh" pos="0 0 0" quat="1 0 0 0" material="Hip_mat" />
            <inertial mass="0.052580342819792604" pos="-0.012181480181525614 0.04674400290943464 0.02883739744027624" fullinertia="0.00011036308582381687 3.707631587930449e-05 8.92995621080799e-05 -2.9193347098829655e-06 4.020625400927225e-06 -1.439594929288976e-05" />
            <body name="R2_HipBearingTrack" pos="0.00104702503018002 -0.0022277151058630196 4.0171815532730195e-07" quat="0.9999979914074321 -0.0020042906728373207 7.502826567872053e-18 6.124750082395104e-17">
              <geom mesh="HipBearingTrack_visual" name="R2_HipBearingTrack_HipBearingTrack_visual_geom" type="mesh" pos="0 0 0" quat="1 0 0 0" material="HipBearingTrack_mat" />
              <inertial mass="0.011609757728843081" pos="-0.010935890023697513 0.10786068092028847 0.06071584524702324" fullinertia="1.7484945833483838e-05 1.536389272419887e-05 3.269187074480083e-05 8.956505581896181e-08 2.8681776479008327e-09 1.140385700666823e-07" />
            </body>
            <body name="R2_Femur-assembly_Motor" pos="8.881784197001253e-18 -3.1974423109204507e-16 0.0500000000000013" quat="-6.114900252818196e-17 1.0 6.126241564798603e-17 -2.2907194013402957e-29">
              <geom mesh="Motor_visual" name="R2_Femur-assembly_Motor_Motor_visual_geom" type="mesh" pos="0 0 0" quat="1 0 0 0" material="Motor_mat" />
              <geom mesh="Motor_collision00" name="R2_Femur-assembly_Motor_Motor_collision00_geom" type="mesh" pos="0 0 0" quat="1 0 0 0" class="collision" />
              <geom mesh="Motor_collision01" name="R2_Femur-assembly_Motor_Motor_collision01_geom" type="mesh" pos="0 0 0" quat="1 0 0 0" class="collision" />
              <geom mesh="Motor_collision02" name="R2_Femur-assembly_Motor_Motor_collision02_geom" type="mesh" pos="0 0 0" quat="1 0 0 0" class="collision" />
              <geom mesh="Motor_collision03" name="R2_Femur-assembly_Motor_Motor_collision03_geom" type="mesh" pos="0 0 0" quat="1 0 0 0" class="collision" />
              <inertial mass="0.4096463210987154" pos="-0.035698207296517785 0.0004701695089032045 -5.891982746489858e-06" fullinertia="0.0004025220023127357 0.00022651206716561888 0.0002329781421120602 1.5369569971637052e-06 -5.181750872290659e-08 -2.626263518699081e-08" />
              <body name="R2_Femur" pos="-8.881784197001253e-18 -2.1316282072803005e-16 0.04999999999999992" quat="-2.609024107869118e-15 0.9999999999999999 -3.5582322627219784e-34 3.022776199361025e-32">
                <joint type="hinge" name="R2_Femur" axis="-1.0 6.015138125580519e-20 2.048624314701585e-15" pos="-0.020629026541575606 2.3900524701828425e-07 0.050000000000042816" range="-1.570796 0.0" limited="true" />
                <geom mesh="Femur_visual" name="R2_Femur_Femur_visual_geom" type="mesh" pos="0 0 0" quat="1 0 0 0" material="Femur_mat" />
                <geom mesh="Femur_collision00" name="R2_Femur_Femur_collision00_geom" type="mesh" pos="0 0 0" quat="1 0 0 0" class="collision" />
                <inertial mass="0.230842936042845" pos="-0.010383686771164849 0.0008485718996991484 0.051461139330156426" fullinertia="0.000802876651415289 0.0005773602804628145 0.0002491128346876032 -6.940768618269669e-08 2.303269615935221e-08 -1.4702432227180056e-05" />
                <body name="R2_TibiaMotorSpacer" pos="0.0 0.0 0.0" quat="1.0 0.0 0.0 -7.821578647613801e-46">
                  <geom mesh="TibiaMotorSpacer_visual" name="R2_TibiaMotorSpacer_TibiaMotorSpacer_visual_geom" type="mesh" pos="0 0 0" quat="1 0 0 0" material="TibiaMotorSpacer_mat" />
                  <inertial mass="0.01707263849756077" pos="0.001320638666705525 -6.945183746737574e-06 0.029478113737471095" fullinertia="2.92110253484819e-05 7.473002877028749e-06 2.1744424710889694e-05 1.6263670271862948e-19 4.5690112813599224e-20 3.751013704944496e-09" />
                  <body name="R2_Tibia-assembly_Motor" pos="-0.02405872266658843 4.618527782440651e-16 0.05000000206997373" quat="-2.312169521622237e-16 7.20464942823445e-16 0.38268343236509045 0.9238795325112871">
                    <geom mesh="Motor_visual" name="R2_Tibia-assembly_Motor_Motor_visual_geom" type="mesh" pos="0 0 0" quat="1 0 0 0" material="Motor_mat" />
                    <geom mesh="Motor_collision00" name="R2_Tibia-assembly_Motor_Motor_collision00_geom" type="mesh" pos="0 0 0" quat="1 0 0 0" class="collision" />
                    <geom mesh="Motor_collision01" name="R2_Tibia-assembly_Motor_Motor_collision01_geom" type="mesh" pos="0 0 0" quat="1 0 0 0" class="collision" />
                    <geom mesh="Motor_collision02" name="R2_Tibia-assembly_Motor_Motor_collision02_geom" type="mesh" pos="0 0 0" quat="1 0 0 0" class="collision" />
                    <geom mesh="Motor_collision03" name="R2_Tibia-assembly_Motor_Motor_collision03_geom" type="mesh" pos="0 0 0" quat="1 0 0 0" class="collision" />
                    <inertial mass="0.4096463210987154" pos="-0.03569820729651784 0.0004701695089032192 -5.89198274647266e-06" fullinertia="0.0004025220023127365 0.00022651206716562083 0.0002329781421120602 1.5369569971645682e-06 -5.181750872221765e-08 -2.6262635185305138e-08" />
                  </body>
                </body>
                <body name="R2_Knee" pos="-0.015029361333294472 -0.019714907448651217 0.17395842405625625" quat="1.0 0.0 8.048094238931602e-20 -2.0619978725023343e-37">
                  <joint type="hinge" name="R2_Knee" axis="-1.0 6.015138125580519e-20 2.0484633528168065e-15" pos="0.014000334791719178 0.019715146453899476 0.03304157594378652" range="-0.20944 2.268928" limited="true" />
                  <geom mesh="Knee_visual" name="R2_Knee_Knee_visual_geom" type="mesh" pos="0 0 0" quat="1 0 0 0" material="Knee_mat" />
                  <inertial mass="0.008812389430275673" pos="0.004999999999999988 0.0197149074485087 0.03304157594374378" fullinertia="1.447179721398152e-06 8.008801325287804e-07 8.008801268241965e-07 -3.887588670379834e-26 -2.8428975346562717e-20 -3.5887091909315445e-17" />
                  <body name="R2_Tibia" pos="0.015029361333294472 0.019714907448651255 -0.17395842405625622" quat="1.0 0.0 -8.048094238931602e-20 1.6959068022287468e-22">
                    <geom mesh="Tibia_visual" name="R2_Tibia_Tibia_visual_geom" type="mesh" pos="0 0 0" quat="1 0 0 0" material="Tibia_mat" />
                    <geom mesh="Tibia_collision00" name="R2_Tibia_Tibia_collision00_geom" type="mesh" pos="0 0 0" quat="1 0 0 0" class="collision" />
                    <geom mesh="Tibia_collision01" name="R2_Tibia_Tibia_collision01_geom" type="mesh" pos="0 0 0" quat="1 0 0 0" class="collision" />
                    <geom mesh="Tibia_collision02" name="R2_Tibia_Tibia_collision02_geom" type="mesh" pos="0 0 0" quat="1 0 0 0" class="collision" />
                    <geom mesh="Tibia_collision03" name="R2_Tibia_Tibia_collision03_geom" type="mesh" pos="0 0 0" quat="1 0 0 0" class="collision" />
                    <inertial mass="0.07297107048801112" pos="-0.01002936133329431 -0.04757136146812306 0.11810916584738512" fullinertia="0.0005482843792552154 0.0004624716132690036 9.111533044167531e-05 4.94367590455012e-19 8.523549418761706e-19 -0.00018206801217491328" />
                    <body name="R2_Foot" pos="0.0 0.0 0.0" quat="1.0 0.0 0.0 -7.821578647613801e-46">
                      <geom mesh="Foot_visual" name="R2_Foot_Foot_visual_geom" type="mesh" pos="0 0 0" quat="1 0 0 0" material="Foot_mat" />
                      <geom mesh="Foot_collision00" name="R2_Foot_Foot_collision00_geom" type="mesh" pos="0 0 0" quat="1 0 0 0" class="collision" friction="2.0 0.1 0.01" />
                      <inertial mass="0.004818206956885" pos="-0.010029361333294178 -0.08392600723875258 -0.03482830039342609" fullinertia="4.0355141511761675e-07 3.2668303458133804e-07 1.499315714351872e-07 -1.3551144522283672e-20 1.303295541857316e-20 6.771781368874443e-10" />
                    </body>
                  </body>
                </body>
              </body>
            </body>
            <body name="R2_TibiaBearingTrack" pos="0.0 -1.0658141036401502e-16 1.3500311979441904e-15" quat="1.0 2.6701731103973003e-15 2.297557386456197e-29 6.126241564798602e-17">
              <geom mesh="TibiaBearingTrack_visual" name="R2_TibiaBearingTrack_TibiaBearingTrack_visual_geom" type="mesh" pos="0 0 0" quat="1 0 0 0" material="TibiaBearingTrack_mat" />
              <inertial mass="0.015140027390716102" pos="0.012936002208848432 0.008673353142335484 0.03817888888858537" fullinertia="4.13027615587386e-05 2.1067013641116015e-05 2.040326746851044e-05 2.923768934760055e-10 -2.581267798894523e-09 4.89867294516e-07" />
            </body>
          </body>
        </body>
      </body>
      <body name="L2_MainClamp" pos="0.05752827884480499 0.23262395411110956 -0.06824959828188862" quat="3.3045668782487136e-18 1.6487430119326716e-15 -0.002004290672836023 0.9999979914074324">
        <geom mesh="MainClamp_visual" name="L2_MainClamp_MainClamp_visual_geom" type="mesh" pos="0 0 0" quat="1 0 0 0" material="MainClamp_mat" />
        <inertial mass="0.04277320346680061" pos="-0.011078641677823008 0.10936584632552614 0.07185120146554273" fullinertia="2.55693244359581e-05 4.95546081032314e-05 7.410198303042014e-05 -6.176818167948398e-08 -4.803365145479312e-10 -1.0852179663382104e-07" />
        <body name="L2_CrossClamp" pos="8.881784197001253e-18 3.552713678800501e-17 0.0" quat="1.0 2.1685437189382793e-19 9.86218736396662e-32 5.312026471665938e-34">
          <geom mesh="CrossClamp_visual" name="L2_CrossClamp_CrossClamp_visual_geom" type="mesh" pos="0 0 0" quat="1 0 0 0" material="CrossClamp_mat" />
          <inertial mass="0.0060873366326105825" pos="-0.011076095384506175 0.10937852181993987 0.08220436514827456" fullinertia="3.5696409752995424e-07 8.628331172516596e-06 8.86134526143871e-06 -2.399837145244796e-08 -9.439137922484772e-11 -1.0651462527342966e-09" />
        </body>
        <body name="L2_Hip-assembly_Motor" pos="-0.011076386363475157 0.10966822722227196 0.01505997107270793" quat="-0.0014172475262309893 0.707105360897122 0.001417247526231073 -0.7071053608971223">
          <geom mesh="Motor_visual" name="L2_Hip-assembly_Motor_Motor_visual_geom" type="mesh" pos="0 0 0" quat="1 0 0 0" material="Motor_mat" />
          <geom mesh="Motor_collision00" name="L2_Hip-assembly_Motor_Motor_collision00_geom" type="mesh" pos="0 0 0" quat="1 0 0 0" class="collision" />
          <geom mesh="Motor_collision01" name="L2_Hip-assembly_Motor_Motor_collision01_geom" type="mesh" pos="0 0 0" quat="1 0 0 0" class="collision" />
          <geom mesh="Motor_collision02" name="L2_Hip-assembly_Motor_Motor_collision02_geom" type="mesh" pos="0 0 0" quat="1 0 0 0" class="collision" />
          <geom mesh="Motor_collision03" name="L2_Hip-assembly_Motor_Motor_collision03_geom" type="mesh" pos="0 0 0" quat="1 0 0 0" class="collision" />
          <inertial mass="0.4096463210987154" pos="-0.03569820729651781 0.0004701695089032354 -5.89198274649098e-06" fullinertia="0.00040252200231273105 0.0002265120671656165 0.00023297814211205824 1.5369569971653923e-06 -5.181750872285332e-08 -2.6262635187710225e-08" />
          <body name="L2_Hip" pos="0.014620638666750283 0.10750000000000091 -0.01002936133329512" quat="1.2699325361584725e-15 -0.7071067811865472 1.1023790381342418e-15 0.7071067811865478">
            <joint type="hinge" name="L2_Hip" axis="3.3127437857693425e-15 2.5916768731093498e-15 1.0" pos="-0.010029696125014882 0.10750023900524672 0.035250000000043684" range="-0.9 0.4" limited="true" />
            <geom mesh="Hip_visual" name="L2_Hip_Hip_visual_geom" type="mesh" pos="0 0 0" quat="1 0 0 0" material="Hip_mat" />
            <inertial mass="0.052580342819792604" pos="-0.012181480181525633 0.046744002909434715 0.02883739744027624" fullinertia="0.00011036308582381728 3.7076315879304615e-05 8.92995621080799e-05 -2.919334709882989e-06 4.020625400927228e-06 -1.4395949292890039e-05" />
            <body name="L2_HipBearingTrack" pos="0.0010470250301800289 -0.0022277151058630196 4.017181553184202e-07" quat="0.9999979914074321 -0.0020042906728373207 7.502826567872045e-18 6.124750082395102e-17">
              <geom mesh="HipBearingTrack_visual" name="L2_HipBearingTrack_HipBearingTrack_visual_geom" type="mesh" pos="0 0 0" quat="1 0 0 0" material="HipBearingTrack_mat" />
              <inertial mass="0.011609757728843081" pos="-0.010935890023697527 0.10786068092028865 0.06071584524702323" fullinertia="1.748494583348406e-05 1.5363892724199e-05 3.2691870744800694e-05 8.956505581893509e-08 2.868177647902161e-09 1.1403857006667652e-07" />
            </body>
            <body name="L2_Femur-assembly_Motor" pos="0.0 -3.1974423109204507e-16 0.0500000000000013" quat="-6.114900252818196e-17 1.0 6.126241564798602e-17 -2.2948931854515965e-29">
              <geom mesh="Motor_visual" name="L2_Femur-assembly_Motor_Motor_visual_geom" type="mesh" pos="0 0 0" quat="1 0 0 0" material="Motor_mat" />
              <geom mesh="Motor_collision00" name="L2_Femur-assembly_Motor_Motor_collision00_geom" type="mesh" pos="0 0 0" quat="1 0 0 0" class="collision" />
              <geom mesh="Motor_collision01" name="L2_Femur-assembly_Motor_Motor_collision01_geom" type="mesh" pos="0 0 0" quat="1 0 0 0" class="collision" />
              <geom mesh="Motor_collision02" name="L2_Femur-assembly_Motor_Motor_collision02_geom" type="mesh" pos="0 0 0" quat="1 0 0 0" class="collision" />
              <geom mesh="Motor_collision03" name="L2_Femur-assembly_Motor_Motor_collision03_geom" type="mesh" pos="0 0 0" quat="1 0 0 0" class="collision" />
              <inertial mass="0.4096463210987154" pos="-0.035698207296517834 0.0004701695089032405 -5.891982746488359e-06" fullinertia="0.00040252200231272954 0.0002265120671656199 0.00023297814211205325 1.5369569971619733e-06 -5.181750872318022e-08 -2.626263518677362e-08" />
              <body name="L2_Femur" pos="8.881784197001253e-18 -2.1316282072803005e-16 0.04999999999999992" quat="-2.6090241078691167e-15 0.9999999999999999 -4.902563169260125e-33 -1.2524962319863433e-31">
                <joint type="hinge" name="L2_Femur" axis="-1.0000000000000009 6.015138126581694e-20 3.3127437857692928e-15" pos="-0.02062969612501483 2.3900524704604004e-07 0.05000000000004265" range="-1.570796 0.0" limited="true" />
                <geom mesh="Femur_visual" name="L2_Femur_Femur_visual_geom" type="mesh" pos="0 0 0" quat="1 0 0 0" material="Femur_mat" />
                <geom mesh="Femur_collision00" name="L2_Femur_Femur_collision00_geom" type="mesh" pos="0 0 0" quat="1 0 0 0" class="collision" />
                <inertial mass="0.230842936042845" pos="-0.010383686771164864 0.0008485718996991492 0.05146113933015643" fullinertia="0.000802876651415294 0.0005773602804628175 0.00024911283468760496 -6.940768618228171e-08 2.3032696159465362e-08 -1.4702432227180942e-05" />
                <body name="L2_TibiaMotorSpacer" pos="0.0 0.0 0.0" quat="1.0 0.0 0.0 -6.319522257341832e-37">
                  <geom mesh="TibiaMotorSpacer_visual" name="L2_TibiaMotorSpacer_TibiaMotorSpacer_visual_geom" type="mesh" pos="0 0 0" quat="1 0 0 0" material="TibiaMotorSpacer_mat" />
                  <inertial mass="0.01707263849756077" pos="0.0013206386667055279 -6.94518374673758e-06 0.029478113737471095" fullinertia="2.9211025348482172e-05 7.47300287702883e-06 2.174442471088991e-05 2.711617288740179e-20 3.6251437564933495e-20 3.7510137049173424e-09" />
                  <body name="L2_Tibia-assembly_Motor" pos="-0.02405872266658844 4.618527782440651e-16 0.05000000206997372" quat="-2.3121695216222366e-16 7.20464942823445e-16 0.38268343236509045 0.9238795325112871">
                    <geom mesh="Motor_visual" name="L2_Tibia-assembly_Motor_Motor_visual_geom" type="mesh" pos="0 0 0" quat="1 0 0 0" material="Motor_mat" />
                    <geom mesh="Motor_collision00" name="L2_Tibia-assembly_Motor_Motor_collision00_geom" type="mesh" pos="0 0 0" quat="1 0 0 0" class="collision" />
                    <geom mesh="Motor_collision01" name="L2_Tibia-assembly_Motor_Motor_collision01_geom" type="mesh" pos="0 0 0" quat="1 0 0 0" class="collision" />
                    <geom mesh="Motor_collision02" name="L2_Tibia-assembly_Motor_Motor_collision02_geom" type="mesh" pos="0 0 0" quat="1 0 0 0" class="collision" />
                    <geom mesh="Motor_collision03" name="L2_Tibia-assembly_Motor_Motor_collision03_geom" type="mesh" pos="0 0 0" quat="1 0 0 0" class="collision" />
                    <inertial mass="0.4096463210987154" pos="-0.0356982072965179 0.00047016950890324245 -5.891982746500045e-06" fullinertia="0.00040252200231273366 0.00022651206716562032 0.00023297814211205967 1.536956997166376e-06 -5.181750872409853e-08 -2.6262635188222716e-08" />
                  </body>
                </body>
                <body name="L2_Knee" pos="-0.015029361333294489 -0.019714907448651217 0.17395842405625625" quat="1.0 0.0 8.048094238931602e-20 -4.602284384135095e-33">
                  <joint type="hinge" name="L2_Knee" axis="-1.0000000000000009 6.015138126581694e-20 3.312582823884514e-15" pos="0.01399966520828021 0.01971514645389955 0.03304157594378634" range="-0.20944 2.268928" limited="true" />
                  <geom mesh="Knee_visual" name="L2_Knee_Knee_visual_geom" type="mesh" pos="0 0 0" quat="1 0 0 0" material="Knee_mat" />
                  <inertial mass="0.008812389430275673" pos="0.005000000000000016 0.01971490744850875 0.033041575943743774" fullinertia="1.447179721398263e-06 8.008801325287006e-07 8.008801268244133e-07 -3.8875931860869533e-26 -2.140920936068854e-21 -3.588709746653774e-17" />
                  <body name="L2_Tibia" pos="0.015029361333294489 0.019714907448651255 -0.17395842405625622" quat="1.0 0.0 -8.048094238931602e-20 1.6959068022433347e-22">
                    <geom mesh="Tibia_visual" name="L2_Tibia_Tibia_visual_geom" type="mesh" pos="0 0 0" quat="1 0 0 0" material="Tibia_mat" />
                    <geom mesh="Tibia_collision00" name="L2_Tibia_Tibia_collision00_geom" type="mesh" pos="0 0 0" quat="1 0 0 0" class="collision" />
                    <geom mesh="Tibia_collision01" name="L2_Tibia_Tibia_collision01_geom" type="mesh" pos="0 0 0" quat="1 0 0 0" class="collision" />
                    <geom mesh="Tibia_collision02" name="L2_Tibia_Tibia_collision02_geom" type="mesh" pos="0 0 0" quat="1 0 0 0" class="collision" />
                    <geom mesh="Tibia_collision03" name="L2_Tibia_Tibia_collision03_geom" type="mesh" pos="0 0 0" quat="1 0 0 0" class="collision" />
                    <inertial mass="0.07297107048801112" pos="-0.010029361333294318 -0.047571361468123206 0.11810916584738514" fullinertia="0.0005482843792552154 0.0004624716132690072 9.111533044166924e-05 4.810523057032143e-19 8.165397319442035e-19 -0.0001820680121749141" />
                    <body name="L2_Foot" pos="0.0 0.0 0.0" quat="1.0 0.0 0.0 -7.825790083863309e-37">
                      <geom mesh="Foot_visual" name="L2_Foot_Foot_visual_geom" type="mesh" pos="0 0 0" quat="1 0 0 0" material="Foot_mat" />
                      <geom mesh="Foot_collision00" name="L2_Foot_Foot_collision00_geom" type="mesh" pos="0 0 0" quat="1 0 0 0" class="collision" friction="2.0 0.1 0.01" />
                      <inertial mass="0.004818206956885" pos="-0.010029361333294197 -0.08392600723875272 -0.034828300393426076" fullinertia="4.035514151175091e-07 3.26683034581325e-07 1.499315714350788e-07 -1.355028848821562e-20 5.936086057890654e-21 6.771781368603376e-10" />
                    </body>
                  </body>
                </body>
              </body>
            </body>
            <body name="L2_TibiaBearingTrack" pos="8.881784197001253e-18 -1.0658141036401502e-16 1.3500311979441904e-15" quat="1.0 2.670173110397299e-15 2.297557386456197e-29 6.126241564798602e-17">
              <geom mesh="TibiaBearingTrack_visual" name="L2_TibiaBearingTrack_TibiaBearingTrack_visual_geom" type="mesh" pos="0 0 0" quat="1 0 0 0" material="TibiaBearingTrack_mat" />
              <inertial mass="0.015140027390716102" pos="0.012936002208848458 0.008673353142335527 0.03817888888858537" fullinertia="4.130276155873889e-05 2.106701364111617e-05 2.040326746851066e-05 2.9237689347662526e-10 -2.5812677988938397e-09 4.898672945160002e-07" />
            </body>
          </body>
        </body>
      </body>
      <body name="R3_MainClamp" pos="-0.05831894842824429 -0.2326239541111095 -0.06824959828188881" quat="0.9999979914074321 -0.002004290672836025 -1.0166845459493043e-15 -2.0377354456429908e-18">
        <geom mesh="MainClamp_visual" name="R3_MainClamp_MainClamp_visual_geom" type="mesh" pos="0 0 0" quat="1 0 0 0" material="MainClamp_mat" />
        <inertial mass="0.04277320346680061" pos="-0.01107864167782299 0.10936584632552593 0.07185120146554273" fullinertia="2.556932443595751e-05 4.9554608103230924e-05 7.410198303042102e-05 -6.176818167953807e-08 -4.803365145451255e-10 -1.0852179663377866e-07" />
        <body name="R3_CrossClamp" pos="0.0 0.0 0.0" quat="1.0 2.168404344971009e-19 9.860682090334649e-32 1.0089855797698544e-35">
          <geom mesh="CrossClamp_visual" name="R3_CrossClamp_CrossClamp_visual_geom" type="mesh" pos="0 0 0" quat="1 0 0 0" material="CrossClamp_mat" />
          <inertial mass="0.0060873366326105825" pos="-0.01107609538450615 0.10937852181993966 0.08220436514827456" fullinertia="3.569640975298452e-07 8.628331172516496e-06 8.861345261438805e-06 -2.3998371452447913e-08 -9.439137922543388e-11 -1.0651462527299688e-09" />
        </body>
        <body name="R3_Hip-assembly_Motor" pos="-0.011076386363475165 0.10966822722227193 0.01505997107270793" quat="-0.0014172475262309893 0.707105360897122 0.001417247526231073 -0.7071053608971223">
          <geom mesh="Motor_visual" name="R3_Hip-assembly_Motor_Motor_visual_geom" type="mesh" pos="0 0 0" quat="1 0 0 0" material="Motor_mat" />
          <geom mesh="Motor_collision00" name="R3_Hip-assembly_Motor_Motor_collision00_geom" type="mesh" pos="0 0 0" quat="1 0 0 0" class="collision" />
          <geom mesh="Motor_collision01" name="R3_Hip-assembly_Motor_Motor_collision01_geom" type="mesh" pos="0 0 0" quat="1 0 0 0" class="collision" />
          <geom mesh="Motor_collision02" name="R3_Hip-assembly_Motor_Motor_collision02_geom" type="mesh" pos="0 0 0" quat="1 0 0 0" class="collision" />
          <geom mesh="Motor_collision03" name="R3_Hip-assembly_Motor_Motor_collision03_geom" type="mesh" pos="0 0 0" quat="1 0 0 0" class="collision" />
          <inertial mass="0.4096463210987154" pos="-0.03569820729651781 0.00047016950890323497 -5.891982746490257e-06" fullinertia="0.0004025220023127293 0.00022651206716561525 0.00023297814211205526 1.536956997165284e-06 -5.181750872285077e-08 -2.6262635187712124e-08" />
          <body name="R3_Hip" pos="0.014620638666750283 0.10750000000000093 -0.010029361333295128" quat="1.2699325361584729e-15 -0.7071067811865472 1.102379038134243e-15 0.7071067811865478">
            <joint type="hinge" name="R3_Hip" axis="2.04862431470163e-15 2.5916768731093498e-15 1.0" pos="-0.010029026541575625 0.10750023900524659 0.035250000000043864" range="-0.9 0.4" limited="true" />
            <geom mesh="Hip_visual" name="R3_Hip_Hip_visual_geom" type="mesh" pos="0 0 0" quat="1 0 0 0" material="Hip_mat" />
            <inertial mass="0.052580342819792604" pos="-0.012181480181525614 0.04674400290943464 0.02883739744027624" fullinertia="0.00011036308582381687 3.707631587930449e-05 8.929956210807947e-05 -2.919334709882857e-06 4.020625400927225e-06 -1.439594929288976e-05" />
            <body name="R3_HipBearingTrack" pos="0.00104702503018002 -0.0022277151058630196 4.017181553184202e-07" quat="0.9999979914074321 -0.0020042906728373207 7.502826567872053e-18 6.124750082395104e-17">
              <geom mesh="HipBearingTrack_visual" name="R3_HipBearingTrack_HipBearingTrack_visual_geom" type="mesh" pos="0 0 0" quat="1 0 0 0" material="HipBearingTrack_mat" />
              <inertial mass="0.011609757728843081" pos="-0.010935890023697513 0.10786068092028847 0.06071584524702324" fullinertia="1.7484945833483838e-05 1.5363892724198877e-05 3.269187074480083e-05 8.956505581894826e-08 2.868177647899084e-09 1.1403857006668233e-07" />
            </body>
            <body name="R3_Femur-assembly_Motor" pos="8.881784197001253e-18 -3.1974423109204507e-16 0.0500000000000013" quat="-6.114900252818196e-17 1.0 6.126241564798603e-17 -2.2907194013402957e-29">
              <geom mesh="Motor_visual" name="R3_Femur-assembly_Motor_Motor_visual_geom" type="mesh" pos="0 0 0" quat="1 0 0 0" material="Motor_mat" />
              <geom mesh="Motor_collision00" name="R3_Femur-assembly_Motor_Motor_collision00_geom" type="mesh" pos="0 0 0" quat="1 0 0 0" class="collision" />
              <geom mesh="Motor_collision01" name="R3_Femur-assembly_Motor_Motor_collision01_geom" type="mesh" pos="0 0 0" quat="1 0 0 0" class="collision" />
              <geom mesh="Motor_collision02" name="R3_Femur-assembly_Motor_Motor_collision02_geom" type="mesh" pos="0 0 0" quat="1 0 0 0" class="collision" />
              <geom mesh="Motor_collision03" name="R3_Femur-assembly_Motor_Motor_collision03_geom" type="mesh" pos="0 0 0" quat="1 0 0 0" class="collision" />
              <inertial mass="0.4096463210987154" pos="-0.035698207296517785 0.0004701695089032045 -5.891982746489858e-06" fullinertia="0.0004025220023127357 0.0002265120671656178 0.0002329781421120602 1.53695699716544e-06 -5.181750872306922e-08 -2.626263518699081e-08" />
              <body name="R3_Femur" pos="-8.881784197001253e-18 -2.1316282072803005e-16 0.04999999999999992" quat="-2.609024107869118e-15 0.9999999999999999 -3.5582322627219784e-34 3.022776199361025e-32">
                <joint type="hinge" name="R3_Femur" axis="-1.0 6.015138125580519e-20 2.048624314701585e-15" pos="-0.020629026541575578 2.3900524701828425e-07 0.050000000000042816" range="-1.570796 0.0" limited="true" />
                <geom mesh="Femur_visual" name="R3_Femur_Femur_visual_geom" type="mesh" pos="0 0 0" quat="1 0 0 0" material="Femur_mat" />
                <geom mesh="Femur_collision00" name="R3_Femur_Femur_collision00_geom" type="mesh" pos="0 0 0" quat="1 0 0 0" class="collision" />
                <inertial mass="0.230842936042845" pos="-0.010383686771164849 0.0008485718996991484 0.051461139330156426" fullinertia="0.000802876651415289 0.0005773602804628143 0.00024911283468760496 -6.940768618313037e-08 2.303269615962326e-08 -1.4702432227180056e-05" />
                <body name="R3_TibiaMotorSpacer" pos="0.0 0.0 0.0" quat="1.0 0.0 0.0 -7.821578647613801e-46">
                  <geom mesh="TibiaMotorSpacer_visual" name="R3_TibiaMotorSpacer_TibiaMotorSpacer_visual_geom" type="mesh" pos="0 0 0" quat="1 0 0 0" material="TibiaMotorSpacer_mat" />
                  <inertial mass="0.01707263849756077" pos="0.001320638666705525 -6.945183746737574e-06 0.029478113737471095" fullinertia="2.92110253484819e-05 7.473002877028776e-06 2.1744424710889803e-05 1.3553164840649182e-19 3.8913849235565267e-20 3.751013704944496e-09" />
                  <body name="R3_Tibia-assembly_Motor" pos="-0.02405872266658843 4.618527782440651e-16 0.05000000206997374" quat="-2.312169521622237e-16 7.20464942823445e-16 0.38268343236509045 0.9238795325112871">
                    <geom mesh="Motor_visual" name="R3_Tibia-assembly_Motor_Motor_visual_geom" type="mesh" pos="0 0 0" quat="1 0 0 0" material="Motor_mat" />
                    <geom mesh="Motor_collision00" name="R3_Tibia-assembly_Motor_Motor_collision00_geom" type="mesh" pos="0 0 0" quat="1 0 0 0" class="collision" />
                    <geom mesh="Motor_collision01" name="R3_Tibia-assembly_Motor_Motor_collision01_geom" type="mesh" pos="0 0 0" quat="1 0 0 0" class="collision" />
                    <geom mesh="Motor_collision02" name="R3_Tibia-assembly_Motor_Motor_collision02_geom" type="mesh" pos="0 0 0" quat="1 0 0 0" class="collision" />
                    <geom mesh="Motor_collision03" name="R3_Tibia-assembly_Motor_Motor_collision03_geom" type="mesh" pos="0 0 0" quat="1 0 0 0" class="collision" />
                    <inertial mass="0.4096463210987154" pos="-0.03569820729651784 0.0004701695089032192 -5.89198274647266e-06" fullinertia="0.0004025220023127365 0.00022651206716562162 0.00023297814211206095 1.5369569971646065e-06 -5.181750872217932e-08 -2.626263518606408e-08" />
                  </body>
                </body>
                <body name="R3_Knee" pos="-0.015029361333294472 -0.019714907448651217 0.1739584240562563" quat="1.0 0.0 8.048094238931602e-20 -2.0619978725023343e-37">
                  <joint type="hinge" name="R3_Knee" axis="-1.0 6.015138125580519e-20 2.0484633528168065e-15" pos="0.014000334791719212 0.019715146453899476 0.03304157594378652" range="-0.20944 2.268928" limited="true" />
                  <geom mesh="Knee_visual" name="R3_Knee_Knee_visual_geom" type="mesh" pos="0 0 0" quat="1 0 0 0" material="Knee_mat" />
                  <inertial mass="0.008812389430275673" pos="0.005000000000000015 0.0197149074485087 0.03304157594374378" fullinertia="1.447179721398152e-06 8.008801325287262e-07 8.008801268244133e-07 2.7105015436251223e-20 1.2228606121643925e-20 -3.588709190931544e-17" />
                  <body name="R3_Tibia" pos="0.015029361333294472 0.019714907448651255 -0.17395842405625622" quat="1.0 0.0 -8.048094238931602e-20 1.6959068022287468e-22">
                    <geom mesh="Tibia_visual" name="R3_Tibia_Tibia_visual_geom" type="mesh" pos="0 0 0" quat="1 0 0 0" material="Tibia_mat" />
                    <geom mesh="Tibia_collision00" name="R3_Tibia_Tibia_collision00_geom" type="mesh" pos="0 0 0" quat="1 0 0 0" class="collision" />
                    <geom mesh="Tibia_collision01" name="R3_Tibia_Tibia_collision01_geom" type="mesh" pos="0 0 0" quat="1 0 0 0" class="collision" />
                    <geom mesh="Tibia_collision02" name="R3_Tibia_Tibia_collision02_geom" type="mesh" pos="0 0 0" quat="1 0 0 0" class="collision" />
                    <geom mesh="Tibia_collision03" name="R3_Tibia_Tibia_collision03_geom" type="mesh" pos="0 0 0" quat="1 0 0 0" class="collision" />
                    <inertial mass="0.07297107048801112" pos="-0.010029361333294328 -0.04757136146812306 0.11810916584738512" fullinertia="0.0005482843792552154 0.0004624716132690037 9.111533044167531e-05 2.775271559579107e-19 7.981448332518971e-19 -0.00018206801217491328" />
                    <body name="R3_Foot" pos="0.0 0.0 0.0" quat="1.0 0.0 0.0 -7.821578647613801e-46">
                      <geom mesh="Foot_visual" name="R3_Foot_Foot_visual_geom" type="mesh" pos="0 0 0" quat="1 0 0 0" material="Foot_mat" />
                      <geom mesh="Foot_collision00" name="R3_Foot_Foot_collision00_geom" type="mesh" pos="0 0 0" quat="1 0 0 0" class="collision" friction="2.0 0.1 0.01" />
                      <inertial mass="0.004818206956885" pos="-0.010029361333294178 -0.08392600723875258 -0.03482830039342609" fullinertia="4.0355141511761675e-07 3.2668303458133804e-07 1.499315714350788e-07 -2.710367167835253e-20 6.256691840538642e-21 6.771781368874443e-10" />
                    </body>
                  </body>
                </body>
              </body>
            </body>
            <body name="R3_TibiaBearingTrack" pos="0.0 -1.0658141036401502e-16 1.3500311979441904e-15" quat="1.0 2.6701731103973003e-15 2.297557386456197e-29 6.126241564798602e-17">
              <geom mesh="TibiaBearingTrack_visual" name="R3_TibiaBearingTrack_TibiaBearingTrack_visual_geom" type="mesh" pos="0 0 0" quat="1 0 0 0" material="TibiaBearingTrack_mat" />
              <inertial mass="0.015140027390716102" pos="0.012936002208848432 0.008673353142335484 0.03817888888858537" fullinertia="4.13027615587386e-05 2.1067013641116062e-05 2.040326746851055e-05 2.9237689350311054e-10 -2.581267798894523e-09 4.89867294516e-07" />
            </body>
          </body>
        </body>
      </body>
      <body name="L3_MainClamp" pos="-0.08047172115519509 0.23262395411110967 -0.06824959828188862" quat="3.3045668782487656e-18 1.648743011932665e-15 -0.0020042906728360214 0.9999979914074326">
        <geom mesh="MainClamp_visual" name="L3_MainClamp_MainClamp_visual_geom" type="mesh" pos="0 0 0" quat="1 0 0 0" material="MainClamp_mat" />
        <inertial mass="0.04277320346680061" pos="-0.011078641677823057 0.10936584632552641 0.07185120146554273" fullinertia="2.5569324435958708e-05 4.9554608103232286e-05 7.410198303041884e-05 -6.176818167937577e-08 -4.803365145339445e-10 -1.0852179663382631e-07" />
        <body name="L3_CrossClamp" pos="0.0 3.552713678800501e-17 0.0" quat="1.0 2.168752779889185e-19 9.868287683422503e-32 -9.09823121916955e-34">
          <geom mesh="CrossClamp_visual" name="L3_CrossClamp_CrossClamp_visual_geom" type="mesh" pos="0 0 0" quat="1 0 0 0" material="CrossClamp_mat" />
          <inertial mass="0.0060873366326105825" pos="-0.011076095384506206 0.10937852181994015 0.08220436514827456" fullinertia="3.569640975300636e-07 8.628331172516752e-06 8.861345261438494e-06 -2.3998371452434476e-08 -9.439137922394638e-11 -1.0651462527295056e-09" />
        </body>
        <body name="L3_Hip-assembly_Motor" pos="-0.011076386363475157 0.10966822722227196 0.01505997107270793" quat="-0.0014172475262309893 0.707105360897122 0.001417247526231073 -0.7071053608971223">
          <geom mesh="Motor_visual" name="L3_Hip-assembly_Motor_Motor_visual_geom" type="mesh" pos="0 0 0" quat="1 0 0 0" material="Motor_mat" />
          <geom mesh="Motor_collision00" name="L3_Hip-assembly_Motor_Motor_collision00_geom" type="mesh" pos="0 0 0" quat="1 0 0 0" class="collision" />
          <geom mesh="Motor_collision01" name="L3_Hip-assembly_Motor_Motor_collision01_geom" type="mesh" pos="0 0 0" quat="1 0 0 0" class="collision" />
          <geom mesh="Motor_collision02" name="L3_Hip-assembly_Motor_Motor_collision02_geom" type="mesh" pos="0 0 0" quat="1 0 0 0" class="collision" />
          <geom mesh="Motor_collision03" name="L3_Hip-assembly_Motor_Motor_collision03_geom" type="mesh" pos="0 0 0" quat="1 0 0 0" class="collision" />
          <inertial mass="0.4096463210987154" pos="-0.03569820729651781 0.00047016950890323606 -5.891982746473223e-06" fullinertia="0.0004025220023127328 0.00022651206716561926 0.00023297814211206057 1.5369569971653921e-06 -5.181750872274497e-08 -2.6262635187276617e-08" />
          <body name="L3_Hip" pos="0.014620638666750283 0.10750000000000091 -0.01002936133329512" quat="1.2699325361584729e-15 -0.7071067811865472 1.1023790381342402e-15 0.7071067811865478">
            <joint type="hinge" name="L3_Hip" axis="3.3127437857693425e-15 2.5916768731093498e-15 1.0" pos="-0.010029696125014979 0.10750023900524697 0.03525000000004368" range="-0.4 0.9" limited="true" />
            <geom mesh="Hip_visual" name="L3_Hip_Hip_visual_geom" type="mesh" pos="0 0 0" quat="1 0 0 0" material="Hip_mat" />
            <inertial mass="0.052580342819792604" pos="-0.012181480181525659 0.046744002909434854 0.028837397440276236" fullinertia="0.00011036308582381801 3.707631587930493e-05 8.929956210807904e-05 -2.9193347098829964e-06 4.020625400927207e-06 -1.4395949292890059e-05" />
            <body name="L3_HipBearingTrack" pos="0.0010470250301800289 -0.002227715105862984 4.017181553184202e-07" quat="0.9999979914074321 -0.0020042906728373207 7.502826567872045e-18 6.124750082395107e-17">
              <geom mesh="HipBearingTrack_visual" name="L3_HipBearingTrack_HipBearingTrack_visual_geom" type="mesh" pos="0 0 0" quat="1 0 0 0" material="HipBearingTrack_mat" />
              <inertial mass="0.011609757728843081" pos="-0.01093589002369756 0.10786068092028893 0.06071584524702323" fullinertia="1.748494583348421e-05 1.5363892724199203e-05 3.2691870744800207e-05 8.956505581896243e-08 2.868177647900579e-09 1.1403857006666582e-07" />
            </body>
            <body name="L3_Femur-assembly_Motor" pos="0.0 -2.842170943040401e-16 0.0500000000000013" quat="-6.114900252818196e-17 1.0 6.126241564798604e-17 -2.2948931854515962e-29">
              <geom mesh="Motor_visual" name="L3_Femur-assembly_Motor_Motor_visual_geom" type="mesh" pos="0 0 0" quat="1 0 0 0" material="Motor_mat" />
              <geom mesh="Motor_collision00" name="L3_Femur-assembly_Motor_Motor_collision00_geom" type="mesh" pos="0 0 0" quat="1 0 0 0" class="collision" />
              <geom mesh="Motor_collision01" name="L3_Femur-assembly_Motor_Motor_collision01_geom" type="mesh" pos="0 0 0" quat="1 0 0 0" class="collision" />
              <geom mesh="Motor_collision02" name="L3_Femur-assembly_Motor_Motor_collision02_geom" type="mesh" pos="0 0 0" quat="1 0 0 0" class="collision" />
              <geom mesh="Motor_collision03" name="L3_Femur-assembly_Motor_Motor_collision03_geom" type="mesh" pos="0 0 0" quat="1 0 0 0" class="collision" />
              <inertial mass="0.4096463210987154" pos="-0.03569820729651792 0.00047016950890320554 -5.891982746488364e-06" fullinertia="0.0004025220023127409 0.00022651206716562062 0.00023297814211205672 1.5369569971645794e-06 -5.181750872269241e-08 -2.626263518699285e-08" />
              <body name="L3_Femur" pos="8.881784197001253e-18 -2.1316282072803005e-16 0.04999999999999993" quat="-2.609024107869115e-15 0.9999999999999999 1.975179267995699e-32 -1.2524962319863433e-31">
                <joint type="hinge" name="L3_Femur" axis="-1.0000000000000022 6.015138126542868e-20 3.312743785769267e-15" pos="-0.02062969612501495 2.3900524715706266e-07 0.05000000000004265" range="-1.570796 0.0" limited="true" />
                <geom mesh="Femur_visual" name="L3_Femur_Femur_visual_geom" type="mesh" pos="0 0 0" quat="1 0 0 0" material="Femur_mat" />
                <geom mesh="Femur_collision00" name="L3_Femur_Femur_collision00_geom" type="mesh" pos="0 0 0" quat="1 0 0 0" class="collision" />
                <inertial mass="0.230842936042845" pos="-0.010383686771164897 0.0008485718996991857 0.05146113933015643" fullinertia="0.0008028766514153029 0.0005773602804628223 0.00024911283468760843 -6.94076861822819e-08 2.303269615946539e-08 -1.4702432227180858e-05" />
                <body name="L3_TibiaMotorSpacer" pos="0.0 0.0 0.0" quat="1.0 0.0 0.0 -7.524775467908684e-38">
                  <geom mesh="TibiaMotorSpacer_visual" name="L3_TibiaMotorSpacer_TibiaMotorSpacer_visual_geom" type="mesh" pos="0 0 0" quat="1 0 0 0" material="TibiaMotorSpacer_mat" />
                  <inertial mass="0.01707263849756077" pos="0.0013206386667055387 -6.94518374673759e-06 0.029478113737471095" fullinertia="2.921102534848214e-05 7.473002877028891e-06 2.1744424710889694e-05 1.0843133582381504e-19 2.947517398689878e-20 3.75101370491727e-09" />
                  <body name="L3_Tibia-assembly_Motor" pos="-0.02405872266658844 4.618527782440651e-16 0.05000000206997373" quat="-2.312169521622237e-16 7.204649428234448e-16 0.3826834323650904 0.9238795325112871">
                    <geom mesh="Motor_visual" name="L3_Tibia-assembly_Motor_Motor_visual_geom" type="mesh" pos="0 0 0" quat="1 0 0 0" material="Motor_mat" />
                    <geom mesh="Motor_collision00" name="L3_Tibia-assembly_Motor_Motor_collision00_geom" type="mesh" pos="0 0 0" quat="1 0 0 0" class="collision" />
                    <geom mesh="Motor_collision01" name="L3_Tibia-assembly_Motor_Motor_collision01_geom" type="mesh" pos="0 0 0" quat="1 0 0 0" class="collision" />
                    <geom mesh="Motor_collision02" name="L3_Tibia-assembly_Motor_Motor_collision02_geom" type="mesh" pos="0 0 0" quat="1 0 0 0" class="collision" />
                    <geom mesh="Motor_collision03" name="L3_Tibia-assembly_Motor_Motor_collision03_geom" type="mesh" pos="0 0 0" quat="1 0 0 0" class="collision" />
                    <inertial mass="0.4096463210987154" pos="-0.03569820729651798 0.0004701695089032177 -5.891982746475216e-06" fullinertia="0.0004025220023127382 0.00022651206716562221 0.00023297814211206065 1.5369569971669538e-06 -5.181750872475123e-08 -2.62626351896924e-08" />
                  </body>
                </body>
                <body name="L3_Knee" pos="-0.01502936133329448 -0.019714907448651182 0.17395842405625625" quat="1.0 0.0 8.048094238931602e-20 1.56082930583472e-33">
                  <joint type="hinge" name="L3_Knee" axis="-1.0000000000000022 6.015138126542868e-20 3.3125828238844885e-15" pos="0.013999665208280167 0.019715146453899688 0.03304157594378634" range="-0.20944 2.268928" limited="true" />
                  <geom mesh="Knee_visual" name="L3_Knee_Knee_visual_geom" type="mesh" pos="0 0 0" quat="1 0 0 0" material="Knee_mat" />
                  <inertial mass="0.008812389430275673" pos="0.005000000000000023 0.01971490744850885 0.033041575943743774" fullinertia="1.4471797213983752e-06 8.008801325286756e-07 8.008801268246301e-07 -2.710509318806924e-20 -2.1409209360682485e-21 -3.5778685585122645e-17" />
                  <body name="L3_Tibia" pos="0.01502936133329448 0.019714907448651217 -0.17395842405625622" quat="1.0 0.0 -8.048094238931602e-20 1.695906802551488e-22">
                    <geom mesh="Tibia_visual" name="L3_Tibia_Tibia_visual_geom" type="mesh" pos="0 0 0" quat="1 0 0 0" material="Tibia_mat" />
                    <geom mesh="Tibia_collision00" name="L3_Tibia_Tibia_collision00_geom" type="mesh" pos="0 0 0" quat="1 0 0 0" class="collision" />
                    <geom mesh="Tibia_collision01" name="L3_Tibia_Tibia_collision01_geom" type="mesh" pos="0 0 0" quat="1 0 0 0" class="collision" />
                    <geom mesh="Tibia_collision02" name="L3_Tibia_Tibia_collision02_geom" type="mesh" pos="0 0 0" quat="1 0 0 0" class="collision" />
                    <geom mesh="Tibia_collision03" name="L3_Tibia_Tibia_collision03_geom" type="mesh" pos="0 0 0" quat="1 0 0 0" class="collision" />
                    <inertial mass="0.07297107048801112" pos="-0.01002936133329436 -0.04757136146812327 0.11810916584738514" fullinertia="0.0005482843792552238 0.0004624716132690124 9.111533044167184e-05 9.147331746974199e-19 8.165397319442004e-19 -0.00018206801217491447" />
                    <body name="L3_Foot" pos="0.0 0.0 0.0" quat="1.0 0.0 0.0 -4.5181470990815775e-37">
                      <geom mesh="Foot_visual" name="L3_Foot_Foot_visual_geom" type="mesh" pos="0 0 0" quat="1 0 0 0" material="Foot_mat" />
                      <geom mesh="Foot_collision00" name="L3_Foot_Foot_collision00_geom" type="mesh" pos="0 0 0" quat="1 0 0 0" class="collision" friction="2.0 0.1 0.01" />
                      <inertial mass="0.004818206956885" pos="-0.01002936133329422 -0.0839260072387529 -0.034828300393426076" fullinertia="4.0355141511772697e-07 3.266830345813531e-07 1.499315714351872e-07 2.7107292979991e-20 1.2712349635924407e-20 6.771781368603351e-10" />
                    </body>
                  </body>
                </body>
              </body>
            </body>
            <body name="L3_TibiaBearingTrack" pos="8.881784197001253e-18 -7.105427357601002e-17 1.3500311979441904e-15" quat="1.0 2.670173110397297e-15 2.297557386456197e-29 6.126241564798602e-17">
              <geom mesh="TibiaBearingTrack_visual" name="L3_TibiaBearingTrack_TibiaBearingTrack_visual_geom" type="mesh" pos="0 0 0" quat="1 0 0 0" material="TibiaBearingTrack_mat" />
              <inertial mass="0.015140027390716102" pos="0.012936002208848493 0.00867335314233554 0.03817888888858537" fullinertia="4.130276155873912e-05 2.1067013641116326e-05 2.040326746851055e-05 2.923768934766261e-10 -2.581267798893843e-09 4.898672945160006e-07" />
            </body>
          </body>
        </body>
      </body>
      <body name="R4_MainClamp" pos="-0.19631894842824435 -0.1646239541111095 -0.06824959828188881" quat="0.9999979914074321 -0.002004290672836025 -1.0166845459493043e-15 -2.0377354456429908e-18">
        <geom mesh="MainClamp_visual" name="R4_MainClamp_MainClamp_visual_geom" type="mesh" pos="0 0 0" quat="1 0 0 0" material="MainClamp_mat" />
        <inertial mass="0.04277320346680061" pos="-0.01107864167782299 0.10936584632552594 0.07185120146554273" fullinertia="2.5569324435957536e-05 4.955460810323098e-05 7.410198303042146e-05 -6.176818167964649e-08 -4.80336514543866e-10 -1.0852179663378102e-07" />
        <body name="R4_CrossClamp" pos="0.0 3.552713678800501e-17 8.881784197001253e-18" quat="1.0 2.168404344971009e-19 9.860682090334649e-32 1.0089855797698544e-35">
          <geom mesh="CrossClamp_visual" name="R4_CrossClamp_CrossClamp_visual_geom" type="mesh" pos="0 0 0" quat="1 0 0 0" material="CrossClamp_mat" />
          <inertial mass="0.0060873366326105825" pos="-0.01107609538450615 0.10937852181993969 0.08220436514827456" fullinertia="3.569640975298418e-07 8.628331172516493e-06 8.861345261438832e-06 -2.399837145244114e-08 -9.43913792245597e-11 -1.065146252730935e-09" />
        </body>
        <body name="R4_Hip-assembly_Motor" pos="-0.011076386363475165 0.10966822722227196 0.01505997107270793" quat="-0.0014172475262309893 0.707105360897122 0.001417247526231073 -0.7071053608971223">
          <geom mesh="Motor_visual" name="R4_Hip-assembly_Motor_Motor_visual_geom" type="mesh" pos="0 0 0" quat="1 0 0 0" material="Motor_mat" />
          <geom mesh="Motor_collision00" name="R4_Hip-assembly_Motor_Motor_collision00_geom" type="mesh" pos="0 0 0" quat="1 0 0 0" class="collision" />
          <geom mesh="Motor_collision01" name="R4_Hip-assembly_Motor_Motor_collision01_geom" type="mesh" pos="0 0 0" quat="1 0 0 0" class="collision" />
          <geom mesh="Motor_collision02" name="R4_Hip-assembly_Motor_Motor_collision02_geom" type="mesh" pos="0 0 0" quat="1 0 0 0" class="collision" />
          <geom mesh="Motor_collision03" name="R4_Hip-assembly_Motor_Motor_collision03_geom" type="mesh" pos="0 0 0" quat="1 0 0 0" class="collision" />
          <inertial mass="0.4096463210987154" pos="-0.03569820729651781 0.00047016950890322614 -5.891982746499138e-06" fullinertia="0.0004025220023127293 0.00022651206716562132 0.00023297814211205656 1.5369569971653381e-06 -5.181750872295919e-08 -2.6262635188145805e-08" />
          <body name="R4_Hip" pos="0.014620638666750283 0.10750000000000089 -0.010029361333295093" quat="1.2699325361584729e-15 -0.7071067811865472 1.102379038134243e-15 0.7071067811865478">
            <joint type="hinge" name="R4_Hip" axis="2.04862431470163e-15 2.5916768731093498e-15 1.0" pos="-0.010029026541575555 0.10750023900524659 0.035250000000043864" range="-1.4 0.3" limited="true" />
            <geom mesh="Hip_visual" name="R4_Hip_Hip_visual_geom" type="mesh" pos="0 0 0" quat="1 0 0 0" material="Hip_mat" />
            <inertial mass="0.052580342819792604" pos="-0.012181480181525596 0.04674400290943464 0.02883739744027624" fullinertia="0.0001103630858238173 3.7076315879304005e-05 8.929956210807947e-05 -2.9193347098827487e-06 4.020625400927333e-06 -1.4395949292889949e-05" />
            <body name="R4_HipBearingTrack" pos="0.0010470250301800378 -0.0022277151058630196 4.017181553184202e-07" quat="0.9999979914074321 -0.0020042906728373207 7.502826567872053e-18 6.124750082395104e-17">
              <geom mesh="HipBearingTrack_visual" name="R4_HipBearingTrack_HipBearingTrack_visual_geom" type="mesh" pos="0 0 0" quat="1 0 0 0" material="HipBearingTrack_mat" />
              <inertial mass="0.011609757728843081" pos="-0.010935890023697522 0.10786068092028847 0.06071584524702324" fullinertia="1.7484945833483858e-05 1.536389272419889e-05 3.26918707448008e-05 8.956505581893472e-08 2.868177647897336e-09 1.140385700666808e-07" />
            </body>
            <body name="R4_Femur-assembly_Motor" pos="3.552713678800501e-17 -3.1974423109204507e-16 0.0500000000000013" quat="-6.114900252818196e-17 1.0 6.126241564798603e-17 -2.2907194013402957e-29">
              <geom mesh="Motor_visual" name="R4_Femur-assembly_Motor_Motor_visual_geom" type="mesh" pos="0 0 0" quat="1 0 0 0" material="Motor_mat" />
              <geom mesh="Motor_collision00" name="R4_Femur-assembly_Motor_Motor_collision00_geom" type="mesh" pos="0 0 0" quat="1 0 0 0" class="collision" />
              <geom mesh="Motor_collision01" name="R4_Femur-assembly_Motor_Motor_collision01_geom" type="mesh" pos="0 0 0" quat="1 0 0 0" class="collision" />
              <geom mesh="Motor_collision02" name="R4_Femur-assembly_Motor_Motor_collision02_geom" type="mesh" pos="0 0 0" quat="1 0 0 0" class="collision" />
              <geom mesh="Motor_collision03" name="R4_Femur-assembly_Motor_Motor_collision03_geom" type="mesh" pos="0 0 0" quat="1 0 0 0" class="collision" />
              <inertial mass="0.4096463210987154" pos="-0.03569820729651777 0.0004701695089032045 -5.891982746489858e-06" fullinertia="0.0004025220023127305 0.00022651206716561172 0.0002329781421120602 1.5369569971671747e-06 -5.181750872361132e-08 -2.626263518699081e-08" />
              <body name="R4_Femur" pos="0.0 -2.1316282072803005e-16 0.04999999999999992" quat="-2.609024107869118e-15 0.9999999999999999 -3.5582322627219784e-34 3.022776199361025e-32">
                <joint type="hinge" name="R4_Femur" axis="-1.0 6.015138125580519e-20 2.048624314701585e-15" pos="-0.020629026541575564 2.390052469905287e-07 0.050000000000042816" range="-1.570796 0.0" limited="true" />
                <geom mesh="Femur_visual" name="R4_Femur_Femur_visual_geom" type="mesh" pos="0 0 0" quat="1 0 0 0" material="Femur_mat" />
                <geom mesh="Femur_collision00" name="R4_Femur_Femur_collision00_geom" type="mesh" pos="0 0 0" quat="1 0 0 0" class="collision" />
                <inertial mass="0.230842936042845" pos="-0.010383686771164876 0.0008485718996991484 0.051461139330156426" fullinertia="0.0008028766514152899 0.0005773602804628097 0.00024911283468759975 -6.94076861800946e-08 2.3032696160219572e-08 -1.470243222718049e-05" />
                <body name="R4_TibiaMotorSpacer" pos="0.0 0.0 0.0" quat="1.0 0.0 0.0 -7.821578647613801e-46">
                  <geom mesh="TibiaMotorSpacer_visual" name="R4_TibiaMotorSpacer_TibiaMotorSpacer_visual_geom" type="mesh" pos="0 0 0" quat="1 0 0 0" material="TibiaMotorSpacer_mat" />
                  <inertial mass="0.01707263849756077" pos="0.0013206386667055162 -6.945183746737574e-06 0.029478113737471095" fullinertia="2.921102534848174e-05 7.47300287702883e-06 2.1744424710889694e-05 -1.0841384040274693e-19 1.1808794923429702e-20 3.751013704944496e-09" />
                  <body name="R4_Tibia-assembly_Motor" pos="-0.02405872266658843 4.618527782440651e-16 0.05000000206997373" quat="-2.312169521622237e-16 7.20464942823445e-16 0.38268343236509045 0.9238795325112871">
                    <geom mesh="Motor_visual" name="R4_Tibia-assembly_Motor_Motor_visual_geom" type="mesh" pos="0 0 0" quat="1 0 0 0" material="Motor_mat" />
                    <geom mesh="Motor_collision00" name="R4_Tibia-assembly_Motor_Motor_collision00_geom" type="mesh" pos="0 0 0" quat="1 0 0 0" class="collision" />
                    <geom mesh="Motor_collision01" name="R4_Tibia-assembly_Motor_Motor_collision01_geom" type="mesh" pos="0 0 0" quat="1 0 0 0" class="collision" />
                    <geom mesh="Motor_collision02" name="R4_Tibia-assembly_Motor_Motor_collision02_geom" type="mesh" pos="0 0 0" quat="1 0 0 0" class="collision" />
                    <geom mesh="Motor_collision03" name="R4_Tibia-assembly_Motor_Motor_collision03_geom" type="mesh" pos="0 0 0" quat="1 0 0 0" class="collision" />
                    <inertial mass="0.4096463210987154" pos="-0.03569820729651784 0.0004701695089032443 -5.891982746497786e-06" fullinertia="0.0004025220023127278 0.00022651206716561782 0.00023297814211205672 1.5369569971671747e-06 -5.181750872451765e-08 -2.62626351855248e-08" />
                  </body>
                </body>
                <body name="R4_Knee" pos="-0.015029361333294489 -0.019714907448651217 0.1739584240562563" quat="1.0 0.0 8.048094238931602e-20 -2.0619978725023343e-37">
                  <joint type="hinge" name="R4_Knee" axis="-1.0 6.015138125580519e-20 2.0484633528168065e-15" pos="0.014000334791719261 0.01971514645389945 0.03304157594378652" range="-0.20944 2.268928" limited="true" />
                  <geom mesh="Knee_visual" name="R4_Knee_Knee_visual_geom" type="mesh" pos="0 0 0" quat="1 0 0 0" material="Knee_mat" />
                  <inertial mass="0.008812389430275673" pos="0.005000000000000032 0.019714907448508803 0.03304157594374378" fullinertia="1.4471797213984772e-06 8.008801325287262e-07 8.008801268246301e-07 -5.421014750016051e-20 1.0709629621412598e-19 -3.5724461583442614e-17" />
                  <body name="R4_Tibia" pos="0.015029361333294489 0.019714907448651255 -0.17395842405625622" quat="1.0 0.0 -8.048094238931602e-20 1.6959068022287468e-22">
                    <geom mesh="Tibia_visual" name="R4_Tibia_Tibia_visual_geom" type="mesh" pos="0 0 0" quat="1 0 0 0" material="Tibia_mat" />
                    <geom mesh="Tibia_collision00" name="R4_Tibia_Tibia_collision00_geom" type="mesh" pos="0 0 0" quat="1 0 0 0" class="collision" />
                    <geom mesh="Tibia_collision01" name="R4_Tibia_Tibia_collision01_geom" type="mesh" pos="0 0 0" quat="1 0 0 0" class="collision" />
                    <geom mesh="Tibia_collision02" name="R4_Tibia_Tibia_collision02_geom" type="mesh" pos="0 0 0" quat="1 0 0 0" class="collision" />
                    <geom mesh="Tibia_collision03" name="R4_Tibia_Tibia_collision03_geom" type="mesh" pos="0 0 0" quat="1 0 0 0" class="collision" />
                    <inertial mass="0.07297107048801112" pos="-0.010029361333294283 -0.047571361468123095 0.11810916584738512" fullinertia="0.0005482843792552132 0.00046247161326900415 9.11153304416727e-05 9.280484594492128e-19 7.981448332518909e-19 -0.0001820680121749135" />
                    <body name="R4_Foot" pos="0.0 0.0 0.0" quat="1.0 0.0 0.0 -7.821578647613801e-46">
                      <geom mesh="Foot_visual" name="R4_Foot_Foot_visual_geom" type="mesh" pos="0 0 0" quat="1 0 0 0" material="Foot_mat" />
                      <geom mesh="Foot_collision00" name="R4_Foot_Foot_collision00_geom" type="mesh" pos="0 0 0" quat="1 0 0 0" class="collision" friction="2.0 0.1 0.01" />
                      <inertial mass="0.004818206956885" pos="-0.010029361333294169 -0.08392600723875258 -0.03482830039342609" fullinertia="4.0355141511756254e-07 3.266830345813516e-07 1.499315714351872e-07 -5.420872599049004e-20 1.3032955418573593e-20 6.771781369145493e-10" />
                    </body>
                  </body>
                </body>
              </body>
            </body>
            <body name="R4_TibiaBearingTrack" pos="3.552713678800501e-17 -1.0658141036401502e-16 1.3500311979441904e-15" quat="1.0 2.6701731103973003e-15 2.297557386456197e-29 6.126241564798602e-17">
              <geom mesh="TibiaBearingTrack_visual" name="R4_TibiaBearingTrack_TibiaBearingTrack_visual_geom" type="mesh" pos="0 0 0" quat="1 0 0 0" material="TibiaBearingTrack_mat" />
              <inertial mass="0.015140027390716102" pos="0.012936002208848415 0.008673353142335503 0.03817888888858537" fullinertia="4.130276155873871e-05 2.106701364111607e-05 2.040326746851066e-05 2.923768934217954e-10 -2.581267798874194e-09 4.898672945159864e-07" />
            </body>
          </body>
        </body>
      </body>
      <body name="L4_MainClamp" pos="-0.2184717211551951 0.16462395411110964 -0.06824959828188862" quat="3.3045668782486674e-18 1.648743011932672e-15 -0.002004290672836022 0.9999979914074326">
        <geom mesh="MainClamp_visual" name="L4_MainClamp_MainClamp_visual_geom" type="mesh" pos="0 0 0" quat="1 0 0 0" material="MainClamp_mat" />
        <inertial mass="0.04277320346680061" pos="-0.011078641677823062 0.10936584632552633 0.07185120146554273" fullinertia="2.5569324435958573e-05 4.955460810323289e-05 7.410198303041927e-05 -6.176818167942989e-08 -4.80336514542632e-10 -1.0852179663380087e-07" />
        <body name="L4_CrossClamp" pos="0.0 0.0 8.881784197001253e-18" quat="1.0 2.16868309290555e-19 9.862345813822617e-32 -3.169009684134244e-34">
          <geom mesh="CrossClamp_visual" name="L4_CrossClamp_CrossClamp_visual_geom" type="mesh" pos="0 0 0" quat="1 0 0 0" material="CrossClamp_mat" />
          <inertial mass="0.0060873366326105825" pos="-0.01107609538450621 0.10937852181994007 0.08220436514827456" fullinertia="3.5696409753001925e-07 8.628331172516794e-06 8.861345261438616e-06 -2.3998371452427637e-08 -9.439137923408353e-11 -1.0651462527314908e-09" />
        </body>
        <body name="L4_Hip-assembly_Motor" pos="-0.011076386363475165 0.10966822722227196 0.015059971072707939" quat="-0.0014172475262309893 0.707105360897122 0.001417247526231073 -0.7071053608971223">
          <geom mesh="Motor_visual" name="L4_Hip-assembly_Motor_Motor_visual_geom" type="mesh" pos="0 0 0" quat="1 0 0 0" material="Motor_mat" />
          <geom mesh="Motor_collision00" name="L4_Hip-assembly_Motor_Motor_collision00_geom" type="mesh" pos="0 0 0" quat="1 0 0 0" class="collision" />
          <geom mesh="Motor_collision01" name="L4_Hip-assembly_Motor_Motor_collision01_geom" type="mesh" pos="0 0 0" quat="1 0 0 0" class="collision" />
          <geom mesh="Motor_collision02" name="L4_Hip-assembly_Motor_Motor_collision02_geom" type="mesh" pos="0 0 0" quat="1 0 0 0" class="collision" />
          <geom mesh="Motor_collision03" name="L4_Hip-assembly_Motor_Motor_collision03_geom" type="mesh" pos="0 0 0" quat="1 0 0 0" class="collision" />
          <inertial mass="0.4096463210987154" pos="-0.03569820729651781 0.000470169508903227 -5.891982746508748e-06" fullinertia="0.00040252200231272585 0.0002265120671656152 0.00023297814211205997 1.5369569971652835e-06 -5.181750872296179e-08 -2.6262635188143952e-08" />
          <body name="L4_Hip" pos="0.014620638666750292 0.10750000000000091 -0.010029361333295128" quat="1.2699325361584729e-15 -0.7071067811865472 1.1023790381342406e-15 0.7071067811865478">
            <joint type="hinge" name="L4_Hip" axis="3.3127437857693425e-15 2.5916768731093498e-15 1.0" pos="-0.010029696125014973 0.10750023900524693 0.03525000000004368" range="-0.3 1.4" limited="true" />
            <geom mesh="Hip_visual" name="L4_Hip_Hip_visual_geom" type="mesh" pos="0 0 0" quat="1 0 0 0" material="Hip_mat" />
            <inertial mass="0.052580342819792604" pos="-0.012181480181525652 0.04674400290943481 0.02883739744027624" fullinertia="0.00011036308582381834 3.7076315879304574e-05 8.929956210807904e-05 -2.919334709882777e-06 4.020625400927259e-06 -1.4395949292889998e-05" />
            <body name="L4_HipBearingTrack" pos="0.0010470250301800378 -0.0022277151058630196 4.0171815532730195e-07" quat="0.9999979914074321 -0.0020042906728373207 7.502826567872045e-18 6.124750082395104e-17">
              <geom mesh="HipBearingTrack_visual" name="L4_HipBearingTrack_HipBearingTrack_visual_geom" type="mesh" pos="0 0 0" quat="1 0 0 0" material="HipBearingTrack_mat" />
              <inertial mass="0.011609757728843081" pos="-0.010935890023697535 0.10786068092028885 0.06071584524702323" fullinertia="1.7484945833484143e-05 1.536389272419927e-05 3.269187074480048e-05 8.956505581898946e-08 2.86817764789984e-09 1.1403857006668445e-07" />
            </body>
            <body name="L4_Femur-assembly_Motor" pos="0.0 -3.1974423109204507e-16 0.0500000000000013" quat="-6.114900252818196e-17 1.0 6.126241564798604e-17 -2.2948931854515965e-29">
              <geom mesh="Motor_visual" name="L4_Femur-assembly_Motor_Motor_visual_geom" type="mesh" pos="0 0 0" quat="1 0 0 0" material="Motor_mat" />
              <geom mesh="Motor_collision00" name="L4_Femur-assembly_Motor_Motor_collision00_geom" type="mesh" pos="0 0 0" quat="1 0 0 0" class="collision" />
              <geom mesh="Motor_collision01" name="L4_Femur-assembly_Motor_Motor_collision01_geom" type="mesh" pos="0 0 0" quat="1 0 0 0" class="collision" />
              <geom mesh="Motor_collision02" name="L4_Femur-assembly_Motor_Motor_collision02_geom" type="mesh" pos="0 0 0" quat="1 0 0 0" class="collision" />
              <geom mesh="Motor_collision03" name="L4_Femur-assembly_Motor_Motor_collision03_geom" type="mesh" pos="0 0 0" quat="1 0 0 0" class="collision" />
              <inertial mass="0.4096463210987154" pos="-0.0356982072965179 0.0004701695089032053 -5.891982746488362e-06" fullinertia="0.00040252200231273366 0.000226512067165616 0.0002329781421120602 1.5369569971637107e-06 -5.1817508722746595e-08 -2.6262635186775216e-08" />
              <body name="L4_Femur" pos="0.0 -2.1316282072803005e-16 0.04999999999999993" quat="-2.6090241078691155e-15 0.9999999999999999 7.424020427051067e-33 -1.2524962319863433e-31">
                <joint type="hinge" name="L4_Femur" axis="-1.0000000000000018 6.015138126588474e-20 3.312743785769295e-15" pos="-0.02062969612501493 2.39005247129307e-07 0.05000000000004265" range="-1.570796 0.0" limited="true" />
                <geom mesh="Femur_visual" name="L4_Femur_Femur_visual_geom" type="mesh" pos="0 0 0" quat="1 0 0 0" material="Femur_mat" />
                <geom mesh="Femur_collision00" name="L4_Femur_Femur_collision00_geom" type="mesh" pos="0 0 0" quat="1 0 0 0" class="collision" />
                <inertial mass="0.230842936042845" pos="-0.010383686771164902 0.0008485718996991499 0.05146113933015643" fullinertia="0.0008028766514152953 0.0005773602804628221 0.0002491128346876032 -6.940768618271551e-08 2.303269615941117e-08 -1.470243222718085e-05" />
                <body name="L4_TibiaMotorSpacer" pos="0.0 0.0 0.0" quat="1.0 0.0 0.0 1.7453610756181137e-36">
                  <geom mesh="TibiaMotorSpacer_visual" name="L4_TibiaMotorSpacer_TibiaMotorSpacer_visual_geom" type="mesh" pos="0 0 0" quat="1 0 0 0" material="TibiaMotorSpacer_mat" />
                  <inertial mass="0.01707263849756077" pos="0.0013206386667055205 -6.945183746737587e-06 0.029478113737471095" fullinertia="2.9211025348482165e-05 7.473002877028857e-06 2.1744424710889694e-05 1.111857526438999e-23 5.658022829903632e-20 3.751013704944399e-09" />
                  <body name="L4_Tibia-assembly_Motor" pos="-0.02405872266658843 4.618527782440651e-16 0.05000000206997373" quat="-2.312169521622238e-16 7.204649428234449e-16 0.38268343236509045 0.9238795325112871">
                    <geom mesh="Motor_visual" name="L4_Tibia-assembly_Motor_Motor_visual_geom" type="mesh" pos="0 0 0" quat="1 0 0 0" material="Motor_mat" />
                    <geom mesh="Motor_collision00" name="L4_Tibia-assembly_Motor_Motor_collision00_geom" type="mesh" pos="0 0 0" quat="1 0 0 0" class="collision" />
                    <geom mesh="Motor_collision01" name="L4_Tibia-assembly_Motor_Motor_collision01_geom" type="mesh" pos="0 0 0" quat="1 0 0 0" class="collision" />
                    <geom mesh="Motor_collision02" name="L4_Tibia-assembly_Motor_Motor_collision02_geom" type="mesh" pos="0 0 0" quat="1 0 0 0" class="collision" />
                    <geom mesh="Motor_collision03" name="L4_Tibia-assembly_Motor_Motor_collision03_geom" type="mesh" pos="0 0 0" quat="1 0 0 0" class="collision" />
                    <inertial mass="0.4096463210987154" pos="-0.03569820729651798 0.00047016950890321757 -5.891982746475135e-06" fullinertia="0.00040252200231273615 0.00022651206716561563 0.0002329781421120545 1.5369569971648828e-06 -5.181750872191435e-08 -2.6262635190267814e-08" />
                  </body>
                </body>
                <body name="L4_Knee" pos="-0.015029361333294454 -0.019714907448651217 0.17395842405625625" quat="1.0 0.0 8.048094238931602e-20 1.5627895268451488e-33">
                  <joint type="hinge" name="L4_Knee" axis="-1.0000000000000018 6.015138126588474e-20 3.3125828238845165e-15" pos="0.013999665208280132 0.01971514645389965 0.03304157594378634" range="-0.20944 2.268928" limited="true" />
                  <geom mesh="Knee_visual" name="L4_Knee_Knee_visual_geom" type="mesh" pos="0 0 0" quat="1 0 0 0" material="Knee_mat" />
                  <inertial mass="0.008812389430275673" pos="0.005000000000000011 0.019714907448508876 0.033041575943743774" fullinertia="1.4471797213984823e-06 8.008801325288374e-07 8.008801268246301e-07 1.0842017837262001e-19 5.20691876882056e-20 -3.569736764357508e-17" />
                  <body name="L4_Tibia" pos="0.015029361333294454 0.019714907448651255 -0.17395842405625622" quat="1.0 0.0 -8.048094238931602e-20 1.6959068020584685e-22">
                    <geom mesh="Tibia_visual" name="L4_Tibia_Tibia_visual_geom" type="mesh" pos="0 0 0" quat="1 0 0 0" material="Tibia_mat" />
                    <geom mesh="Tibia_collision00" name="L4_Tibia_Tibia_collision00_geom" type="mesh" pos="0 0 0" quat="1 0 0 0" class="collision" />
                    <geom mesh="Tibia_collision01" name="L4_Tibia_Tibia_collision01_geom" type="mesh" pos="0 0 0" quat="1 0 0 0" class="collision" />
                    <geom mesh="Tibia_collision02" name="L4_Tibia_Tibia_collision02_geom" type="mesh" pos="0 0 0" quat="1 0 0 0" class="collision" />
                    <geom mesh="Tibia_collision03" name="L4_Tibia_Tibia_collision03_geom" type="mesh" pos="0 0 0" quat="1 0 0 0" class="collision" />
                    <inertial mass="0.07297107048801112" pos="-0.010029361333294363 -0.04757136146812328 0.11810916584738514" fullinertia="0.0005482843792552208 0.00046247161326901055 9.111533044167097e-05 6.978927402003166e-19 7.623296233199167e-19 -0.0001820680121749144" />
                    <body name="L4_Foot" pos="0.0 0.0 0.0" quat="1.0 0.0 0.0 1.4441075103138182e-36">
                      <geom mesh="Foot_visual" name="L4_Foot_Foot_visual_geom" type="mesh" pos="0 0 0" quat="1 0 0 0" material="Foot_mat" />
                      <geom mesh="Foot_collision00" name="L4_Foot_Foot_collision00_geom" type="mesh" pos="0 0 0" quat="1 0 0 0" class="collision" friction="2.0 0.1 0.01" />
                      <inertial mass="0.004818206956885" pos="-0.010029361333294197 -0.08392600723875288 -0.034828300393426076" fullinertia="4.035514151174556e-07 3.2668303458135276e-07 1.499315714350788e-07 -5.420786995642216e-20 -8.401775201432538e-22 6.77178136887441e-10" />
                    </body>
                  </body>
                </body>
              </body>
            </body>
            <body name="L4_TibiaBearingTrack" pos="0.0 -1.0658141036401502e-16 1.3500311979441904e-15" quat="1.0 2.670173110397298e-15 2.297557386456197e-29 6.126241564798602e-17">
              <geom mesh="TibiaBearingTrack_visual" name="L4_TibiaBearingTrack_TibiaBearingTrack_visual_geom" type="mesh" pos="0 0 0" quat="1 0 0 0" material="TibiaBearingTrack_mat" />
              <inertial mass="0.015140027390716102" pos="0.012936002208848486 0.008673353142335536 0.03817888888858537" fullinertia="4.130276155873897e-05 2.106701364111636e-05 2.040326746851066e-05 2.923768935308359e-10 -2.5812677988870655e-09 4.898672945160141e-07" />
            </body>
          </body>
        </body>
      </body>
    </body>
  </worldbody>
</mujoco>